[2018-05-28 09:52:54 +0800] [23818] [INFO] Starting gunicorn 19.7.1
[2018-05-28 09:52:54 +0800] [23818] [ERROR] Invalid address: ('10.199.141.178', 9018)
[2018-05-28 09:52:54 +0800] [23818] [ERROR] Retrying in 1 second.
[2018-05-28 09:52:55 +0800] [23818] [ERROR] Invalid address: ('10.199.141.178', 9018)
[2018-05-28 09:52:55 +0800] [23818] [ERROR] Retrying in 1 second.
[2018-05-28 09:52:56 +0800] [23818] [ERROR] Invalid address: ('10.199.141.178', 9018)
[2018-05-28 09:52:56 +0800] [23818] [ERROR] Retrying in 1 second.
[2018-05-28 09:52:57 +0800] [23818] [ERROR] Invalid address: ('10.199.141.178', 9018)
[2018-05-28 09:52:57 +0800] [23818] [ERROR] Retrying in 1 second.
[2018-05-28 09:52:58 +0800] [23818] [ERROR] Invalid address: ('10.199.141.178', 9018)
[2018-05-28 09:52:58 +0800] [23818] [ERROR] Retrying in 1 second.
[2018-05-28 09:52:59 +0800] [23818] [ERROR] Can't connect to ('10.199.141.178', 9018)
[2018-05-28 09:53:12 +0800] [23825] [INFO] Starting gunicorn 19.7.1
[2018-05-28 09:53:12 +0800] [23825] [INFO] Listening at: http://127.0.0.1:9018 (23825)
[2018-05-28 09:53:12 +0800] [23825] [INFO] Using worker: sync
[2018-05-28 09:53:12 +0800] [23826] [INFO] Booting worker with pid: 23826
[2018-05-28 09:53:52 +0800] [23826] [ERROR] Error handling request /elb-healthcheck
Traceback (most recent call last):
  File "/Users/leepand/anaconda2/lib/python2.7/site-packages/gunicorn/workers/sync.py", line 135, in handle
    self.handle_request(listener, req, client, addr)
  File "/Users/leepand/anaconda2/lib/python2.7/site-packages/gunicorn/workers/sync.py", line 176, in handle_request
    respiter = self.wsgi(environ, resp.start_response)
TypeError: loader() takes no arguments (2 given)
[2018-05-28 09:54:13 +0800] [23835] [INFO] Starting gunicorn 19.7.1
[2018-05-28 09:54:13 +0800] [23835] [INFO] Listening at: http://127.0.0.1:9018 (23835)
[2018-05-28 09:54:13 +0800] [23835] [INFO] Using worker: sync
[2018-05-28 09:54:13 +0800] [23836] [INFO] Booting worker with pid: 23836
