2018-05-17 20:08:42,308 - AIaas.router.AI_worker_client - ERROR - Predict has failed.. 
Traceback (most recent call last):
  File "/Users/leepand/Downloads/BigRLab_APIs/demoday_fs/web_lab/knn_as_a_service/AIaas/AIaas/router/AI_worker_client.py", line 101, in predict
    po = client.predict(prediction_input.data)
  File "/Users/leepand/Downloads/BigRLab_APIs/demoday_fs/web_lab/knn_as_a_service/AIaas/AIaas/router/common_client.py", line 115, in wrapped
    raise FireflyError('Firefly functions only accept named arguments')
FireflyError: Firefly functions only accept named arguments
2018-05-17 20:16:33,021 - AIaas.router.AI_worker_client - ERROR - Predict has failed.. 
Traceback (most recent call last):
  File "/Users/leepand/Downloads/BigRLab_APIs/demoday_fs/web_lab/knn_as_a_service/AIaas/AIaas/router/AI_worker_client.py", line 110, in predict
    po=prediction_output()
TypeError: __init__() takes exactly 3 arguments (1 given)
2018-05-17 20:18:01,720 - AIaas.router.AI_worker_client - ERROR - Predict has failed.. 
Traceback (most recent call last):
  File "/Users/leepand/Downloads/BigRLab_APIs/demoday_fs/web_lab/knn_as_a_service/AIaas/AIaas/router/AI_worker_client.py", line 110, in predict
    po=prediction_output()
TypeError: __init__() takes exactly 3 arguments (1 given)
2018-05-17 20:20:14,726 - AIaas.router.AI_worker_client - ERROR - Predict has failed.. 
Traceback (most recent call last):
  File "/Users/leepand/Downloads/BigRLab_APIs/demoday_fs/web_lab/knn_as_a_service/AIaas/AIaas/router/AI_worker_client.py", line 112, in predict
    prediction_output.result = client.predict(prediction_input.data)
  File "/Users/leepand/Downloads/BigRLab_APIs/demoday_fs/web_lab/knn_as_a_service/AIaas/AIaas/router/common_client.py", line 115, in wrapped
    raise FireflyError('Firefly functions only accept named arguments')
FireflyError: Firefly functions only accept named arguments
2018-05-17 20:20:14,729 - AIaas.router.AI_worker_client - ERROR - Predict has failed.. 
Traceback (most recent call last):
  File "/Users/leepand/Downloads/BigRLab_APIs/demoday_fs/web_lab/knn_as_a_service/AIaas/AIaas/router/AI_worker_client.py", line 112, in predict
    prediction_output.result = client.predict(prediction_input.data)
  File "/Users/leepand/Downloads/BigRLab_APIs/demoday_fs/web_lab/knn_as_a_service/AIaas/AIaas/router/common_client.py", line 115, in wrapped
    raise FireflyError('Firefly functions only accept named arguments')
FireflyError: Firefly functions only accept named arguments
2018-05-17 20:20:14,732 - AIaas.router.AI_worker_client - ERROR - Predict has failed.. 
Traceback (most recent call last):
  File "/Users/leepand/Downloads/BigRLab_APIs/demoday_fs/web_lab/knn_as_a_service/AIaas/AIaas/router/AI_worker_client.py", line 112, in predict
    prediction_output.result = client.predict(prediction_input.data)
  File "/Users/leepand/Downloads/BigRLab_APIs/demoday_fs/web_lab/knn_as_a_service/AIaas/AIaas/router/common_client.py", line 115, in wrapped
    raise FireflyError('Firefly functions only accept named arguments')
FireflyError: Firefly functions only accept named arguments
2018-05-17 20:20:14,734 - AIaas.router.AI_worker_client - ERROR - Predict has failed.. 
Traceback (most recent call last):
  File "/Users/leepand/Downloads/BigRLab_APIs/demoday_fs/web_lab/knn_as_a_service/AIaas/AIaas/router/AI_worker_client.py", line 112, in predict
    prediction_output.result = client.predict(prediction_input.data)
  File "/Users/leepand/Downloads/BigRLab_APIs/demoday_fs/web_lab/knn_as_a_service/AIaas/AIaas/router/common_client.py", line 115, in wrapped
    raise FireflyError('Firefly functions only accept named arguments')
FireflyError: Firefly functions only accept named arguments
2018-05-17 20:20:14,736 - AIaas.router.AI_worker_client - ERROR - Predict has failed.. 
Traceback (most recent call last):
  File "/Users/leepand/Downloads/BigRLab_APIs/demoday_fs/web_lab/knn_as_a_service/AIaas/AIaas/router/AI_worker_client.py", line 112, in predict
    prediction_output.result = client.predict(prediction_input.data)
  File "/Users/leepand/Downloads/BigRLab_APIs/demoday_fs/web_lab/knn_as_a_service/AIaas/AIaas/router/common_client.py", line 115, in wrapped
    raise FireflyError('Firefly functions only accept named arguments')
FireflyError: Firefly functions only accept named arguments
2018-05-17 20:20:14,738 - AIaas.router.AI_worker_client - ERROR - Predict has failed.. 
Traceback (most recent call last):
  File "/Users/leepand/Downloads/BigRLab_APIs/demoday_fs/web_lab/knn_as_a_service/AIaas/AIaas/router/AI_worker_client.py", line 112, in predict
    prediction_output.result = client.predict(prediction_input.data)
  File "/Users/leepand/Downloads/BigRLab_APIs/demoday_fs/web_lab/knn_as_a_service/AIaas/AIaas/router/common_client.py", line 115, in wrapped
    raise FireflyError('Firefly functions only accept named arguments')
FireflyError: Firefly functions only accept named arguments
2018-05-17 20:20:32,189 - AIaas.router.AI_worker_client - ERROR - Predict has failed.. 
Traceback (most recent call last):
  File "/Users/leepand/Downloads/BigRLab_APIs/demoday_fs/web_lab/knn_as_a_service/AIaas/AIaas/router/AI_worker_client.py", line 112, in predict
    prediction_output.result = client.predict(prediction_input.data)
  File "/Users/leepand/Downloads/BigRLab_APIs/demoday_fs/web_lab/knn_as_a_service/AIaas/AIaas/router/common_client.py", line 115, in wrapped
    raise FireflyError('Firefly functions only accept named arguments')
FireflyError: Firefly functions only accept named arguments
2018-05-17 20:20:32,191 - AIaas.router.AI_worker_client - ERROR - Predict has failed.. 
Traceback (most recent call last):
  File "/Users/leepand/Downloads/BigRLab_APIs/demoday_fs/web_lab/knn_as_a_service/AIaas/AIaas/router/AI_worker_client.py", line 112, in predict
    prediction_output.result = client.predict(prediction_input.data)
  File "/Users/leepand/Downloads/BigRLab_APIs/demoday_fs/web_lab/knn_as_a_service/AIaas/AIaas/router/common_client.py", line 115, in wrapped
    raise FireflyError('Firefly functions only accept named arguments')
FireflyError: Firefly functions only accept named arguments
2018-05-17 20:20:32,192 - AIaas.router.AI_worker_client - ERROR - Predict has failed.. 
Traceback (most recent call last):
  File "/Users/leepand/Downloads/BigRLab_APIs/demoday_fs/web_lab/knn_as_a_service/AIaas/AIaas/router/AI_worker_client.py", line 112, in predict
    prediction_output.result = client.predict(prediction_input.data)
  File "/Users/leepand/Downloads/BigRLab_APIs/demoday_fs/web_lab/knn_as_a_service/AIaas/AIaas/router/common_client.py", line 115, in wrapped
    raise FireflyError('Firefly functions only accept named arguments')
FireflyError: Firefly functions only accept named arguments
2018-05-17 20:20:32,193 - AIaas.router.AI_worker_client - ERROR - Predict has failed.. 
Traceback (most recent call last):
  File "/Users/leepand/Downloads/BigRLab_APIs/demoday_fs/web_lab/knn_as_a_service/AIaas/AIaas/router/AI_worker_client.py", line 112, in predict
    prediction_output.result = client.predict(prediction_input.data)
  File "/Users/leepand/Downloads/BigRLab_APIs/demoday_fs/web_lab/knn_as_a_service/AIaas/AIaas/router/common_client.py", line 115, in wrapped
    raise FireflyError('Firefly functions only accept named arguments')
FireflyError: Firefly functions only accept named arguments
2018-05-17 20:20:32,195 - AIaas.router.AI_worker_client - ERROR - Predict has failed.. 
Traceback (most recent call last):
  File "/Users/leepand/Downloads/BigRLab_APIs/demoday_fs/web_lab/knn_as_a_service/AIaas/AIaas/router/AI_worker_client.py", line 112, in predict
    prediction_output.result = client.predict(prediction_input.data)
  File "/Users/leepand/Downloads/BigRLab_APIs/demoday_fs/web_lab/knn_as_a_service/AIaas/AIaas/router/common_client.py", line 115, in wrapped
    raise FireflyError('Firefly functions only accept named arguments')
FireflyError: Firefly functions only accept named arguments
2018-05-17 20:20:32,196 - AIaas.router.AI_worker_client - ERROR - Predict has failed.. 
Traceback (most recent call last):
  File "/Users/leepand/Downloads/BigRLab_APIs/demoday_fs/web_lab/knn_as_a_service/AIaas/AIaas/router/AI_worker_client.py", line 112, in predict
    prediction_output.result = client.predict(prediction_input.data)
  File "/Users/leepand/Downloads/BigRLab_APIs/demoday_fs/web_lab/knn_as_a_service/AIaas/AIaas/router/common_client.py", line 115, in wrapped
    raise FireflyError('Firefly functions only accept named arguments')
FireflyError: Firefly functions only accept named arguments
2018-05-17 20:21:03,812 - AIaas.router.AI_worker_client - ERROR - Predict has failed.. 
Traceback (most recent call last):
  File "/Users/leepand/Downloads/BigRLab_APIs/demoday_fs/web_lab/knn_as_a_service/AIaas/AIaas/router/AI_worker_client.py", line 112, in predict
    prediction_output.result = client.predict(prediction_input.data)
  File "/Users/leepand/Downloads/BigRLab_APIs/demoday_fs/web_lab/knn_as_a_service/AIaas/AIaas/router/common_client.py", line 115, in wrapped
    raise FireflyError('Firefly functions only accept named arguments')
FireflyError: Firefly functions only accept named arguments
2018-05-17 20:21:03,814 - AIaas.router.AI_worker_client - ERROR - Predict has failed.. 
Traceback (most recent call last):
  File "/Users/leepand/Downloads/BigRLab_APIs/demoday_fs/web_lab/knn_as_a_service/AIaas/AIaas/router/AI_worker_client.py", line 112, in predict
    prediction_output.result = client.predict(prediction_input.data)
  File "/Users/leepand/Downloads/BigRLab_APIs/demoday_fs/web_lab/knn_as_a_service/AIaas/AIaas/router/common_client.py", line 115, in wrapped
    raise FireflyError('Firefly functions only accept named arguments')
FireflyError: Firefly functions only accept named arguments
2018-05-17 20:21:03,815 - AIaas.router.AI_worker_client - ERROR - Predict has failed.. 
Traceback (most recent call last):
  File "/Users/leepand/Downloads/BigRLab_APIs/demoday_fs/web_lab/knn_as_a_service/AIaas/AIaas/router/AI_worker_client.py", line 112, in predict
    prediction_output.result = client.predict(prediction_input.data)
  File "/Users/leepand/Downloads/BigRLab_APIs/demoday_fs/web_lab/knn_as_a_service/AIaas/AIaas/router/common_client.py", line 115, in wrapped
    raise FireflyError('Firefly functions only accept named arguments')
FireflyError: Firefly functions only accept named arguments
2018-05-17 20:21:03,817 - AIaas.router.AI_worker_client - ERROR - Predict has failed.. 
Traceback (most recent call last):
  File "/Users/leepand/Downloads/BigRLab_APIs/demoday_fs/web_lab/knn_as_a_service/AIaas/AIaas/router/AI_worker_client.py", line 112, in predict
    prediction_output.result = client.predict(prediction_input.data)
  File "/Users/leepand/Downloads/BigRLab_APIs/demoday_fs/web_lab/knn_as_a_service/AIaas/AIaas/router/common_client.py", line 115, in wrapped
    raise FireflyError('Firefly functions only accept named arguments')
FireflyError: Firefly functions only accept named arguments
2018-05-17 20:21:03,818 - AIaas.router.AI_worker_client - ERROR - Predict has failed.. 
Traceback (most recent call last):
  File "/Users/leepand/Downloads/BigRLab_APIs/demoday_fs/web_lab/knn_as_a_service/AIaas/AIaas/router/AI_worker_client.py", line 112, in predict
    prediction_output.result = client.predict(prediction_input.data)
  File "/Users/leepand/Downloads/BigRLab_APIs/demoday_fs/web_lab/knn_as_a_service/AIaas/AIaas/router/common_client.py", line 115, in wrapped
    raise FireflyError('Firefly functions only accept named arguments')
FireflyError: Firefly functions only accept named arguments
2018-05-17 20:21:03,820 - AIaas.router.AI_worker_client - ERROR - Predict has failed.. 
Traceback (most recent call last):
  File "/Users/leepand/Downloads/BigRLab_APIs/demoday_fs/web_lab/knn_as_a_service/AIaas/AIaas/router/AI_worker_client.py", line 112, in predict
    prediction_output.result = client.predict(prediction_input.data)
  File "/Users/leepand/Downloads/BigRLab_APIs/demoday_fs/web_lab/knn_as_a_service/AIaas/AIaas/router/common_client.py", line 115, in wrapped
    raise FireflyError('Firefly functions only accept named arguments')
FireflyError: Firefly functions only accept named arguments
2018-05-17 20:22:40,135 - AIaas.router.AI_worker_client - ERROR - Predict has failed.. 
Traceback (most recent call last):
  File "/Users/leepand/Downloads/BigRLab_APIs/demoday_fs/web_lab/knn_as_a_service/AIaas/AIaas/router/AI_worker_client.py", line 112, in predict
    prediction_output.result = client.predict(prediction_input.data)
  File "/Users/leepand/Downloads/BigRLab_APIs/demoday_fs/web_lab/knn_as_a_service/AIaas/AIaas/router/common_client.py", line 115, in wrapped
    raise FireflyError('Firefly functions only accept named arguments')
FireflyError: Firefly functions only accept named arguments
2018-05-17 20:22:40,136 - AIaas.router.AI_worker_client - ERROR - Predict has failed.. 
Traceback (most recent call last):
  File "/Users/leepand/Downloads/BigRLab_APIs/demoday_fs/web_lab/knn_as_a_service/AIaas/AIaas/router/AI_worker_client.py", line 112, in predict
    prediction_output.result = client.predict(prediction_input.data)
  File "/Users/leepand/Downloads/BigRLab_APIs/demoday_fs/web_lab/knn_as_a_service/AIaas/AIaas/router/common_client.py", line 115, in wrapped
    raise FireflyError('Firefly functions only accept named arguments')
FireflyError: Firefly functions only accept named arguments
2018-05-17 20:22:40,138 - AIaas.router.AI_worker_client - ERROR - Predict has failed.. 
Traceback (most recent call last):
  File "/Users/leepand/Downloads/BigRLab_APIs/demoday_fs/web_lab/knn_as_a_service/AIaas/AIaas/router/AI_worker_client.py", line 112, in predict
    prediction_output.result = client.predict(prediction_input.data)
  File "/Users/leepand/Downloads/BigRLab_APIs/demoday_fs/web_lab/knn_as_a_service/AIaas/AIaas/router/common_client.py", line 115, in wrapped
    raise FireflyError('Firefly functions only accept named arguments')
FireflyError: Firefly functions only accept named arguments
2018-05-17 20:22:40,140 - AIaas.router.AI_worker_client - ERROR - Predict has failed.. 
Traceback (most recent call last):
  File "/Users/leepand/Downloads/BigRLab_APIs/demoday_fs/web_lab/knn_as_a_service/AIaas/AIaas/router/AI_worker_client.py", line 112, in predict
    prediction_output.result = client.predict(prediction_input.data)
  File "/Users/leepand/Downloads/BigRLab_APIs/demoday_fs/web_lab/knn_as_a_service/AIaas/AIaas/router/common_client.py", line 115, in wrapped
    raise FireflyError('Firefly functions only accept named arguments')
FireflyError: Firefly functions only accept named arguments
2018-05-17 20:22:40,142 - AIaas.router.AI_worker_client - ERROR - Predict has failed.. 
Traceback (most recent call last):
  File "/Users/leepand/Downloads/BigRLab_APIs/demoday_fs/web_lab/knn_as_a_service/AIaas/AIaas/router/AI_worker_client.py", line 112, in predict
    prediction_output.result = client.predict(prediction_input.data)
  File "/Users/leepand/Downloads/BigRLab_APIs/demoday_fs/web_lab/knn_as_a_service/AIaas/AIaas/router/common_client.py", line 115, in wrapped
    raise FireflyError('Firefly functions only accept named arguments')
FireflyError: Firefly functions only accept named arguments
2018-05-17 20:22:40,145 - AIaas.router.AI_worker_client - ERROR - Predict has failed.. 
Traceback (most recent call last):
  File "/Users/leepand/Downloads/BigRLab_APIs/demoday_fs/web_lab/knn_as_a_service/AIaas/AIaas/router/AI_worker_client.py", line 112, in predict
    prediction_output.result = client.predict(prediction_input.data)
  File "/Users/leepand/Downloads/BigRLab_APIs/demoday_fs/web_lab/knn_as_a_service/AIaas/AIaas/router/common_client.py", line 115, in wrapped
    raise FireflyError('Firefly functions only accept named arguments')
FireflyError: Firefly functions only accept named arguments
2018-05-17 20:26:06,404 - AIaas.router.AI_worker_client - ERROR - Predict has failed.. 
Traceback (most recent call last):
  File "/Users/leepand/Downloads/BigRLab_APIs/demoday_fs/web_lab/knn_as_a_service/AIaas/AIaas/router/AI_worker_client.py", line 112, in predict
    prediction_output.result = client.predict(prediction_input.data)
  File "/Users/leepand/Downloads/BigRLab_APIs/demoday_fs/web_lab/knn_as_a_service/AIaas/AIaas/router/common_client.py", line 115, in wrapped
    raise FireflyError('Firefly functions only accept named arguments')
FireflyError: Firefly functions only accept named arguments
2018-05-17 20:26:06,406 - AIaas.router.AI_worker_client - ERROR - Predict has failed.. 
Traceback (most recent call last):
  File "/Users/leepand/Downloads/BigRLab_APIs/demoday_fs/web_lab/knn_as_a_service/AIaas/AIaas/router/AI_worker_client.py", line 112, in predict
    prediction_output.result = client.predict(prediction_input.data)
  File "/Users/leepand/Downloads/BigRLab_APIs/demoday_fs/web_lab/knn_as_a_service/AIaas/AIaas/router/common_client.py", line 115, in wrapped
    raise FireflyError('Firefly functions only accept named arguments')
FireflyError: Firefly functions only accept named arguments
2018-05-17 20:26:06,407 - AIaas.router.AI_worker_client - ERROR - Predict has failed.. 
Traceback (most recent call last):
  File "/Users/leepand/Downloads/BigRLab_APIs/demoday_fs/web_lab/knn_as_a_service/AIaas/AIaas/router/AI_worker_client.py", line 112, in predict
    prediction_output.result = client.predict(prediction_input.data)
  File "/Users/leepand/Downloads/BigRLab_APIs/demoday_fs/web_lab/knn_as_a_service/AIaas/AIaas/router/common_client.py", line 115, in wrapped
    raise FireflyError('Firefly functions only accept named arguments')
FireflyError: Firefly functions only accept named arguments
2018-05-17 20:26:06,408 - AIaas.router.AI_worker_client - ERROR - Predict has failed.. 
Traceback (most recent call last):
  File "/Users/leepand/Downloads/BigRLab_APIs/demoday_fs/web_lab/knn_as_a_service/AIaas/AIaas/router/AI_worker_client.py", line 112, in predict
    prediction_output.result = client.predict(prediction_input.data)
  File "/Users/leepand/Downloads/BigRLab_APIs/demoday_fs/web_lab/knn_as_a_service/AIaas/AIaas/router/common_client.py", line 115, in wrapped
    raise FireflyError('Firefly functions only accept named arguments')
FireflyError: Firefly functions only accept named arguments
2018-05-17 20:26:06,410 - AIaas.router.AI_worker_client - ERROR - Predict has failed.. 
Traceback (most recent call last):
  File "/Users/leepand/Downloads/BigRLab_APIs/demoday_fs/web_lab/knn_as_a_service/AIaas/AIaas/router/AI_worker_client.py", line 112, in predict
    prediction_output.result = client.predict(prediction_input.data)
  File "/Users/leepand/Downloads/BigRLab_APIs/demoday_fs/web_lab/knn_as_a_service/AIaas/AIaas/router/common_client.py", line 115, in wrapped
    raise FireflyError('Firefly functions only accept named arguments')
FireflyError: Firefly functions only accept named arguments
2018-05-17 20:26:06,411 - AIaas.router.AI_worker_client - ERROR - Predict has failed.. 
Traceback (most recent call last):
  File "/Users/leepand/Downloads/BigRLab_APIs/demoday_fs/web_lab/knn_as_a_service/AIaas/AIaas/router/AI_worker_client.py", line 112, in predict
    prediction_output.result = client.predict(prediction_input.data)
  File "/Users/leepand/Downloads/BigRLab_APIs/demoday_fs/web_lab/knn_as_a_service/AIaas/AIaas/router/common_client.py", line 115, in wrapped
    raise FireflyError('Firefly functions only accept named arguments')
FireflyError: Firefly functions only accept named arguments
2018-05-17 20:38:44,477 - AIaas.router.AI_worker_client - ERROR - Predict has failed.. 
Traceback (most recent call last):
  File "/Users/leepand/Downloads/BigRLab_APIs/demoday_fs/web_lab/knn_as_a_service/AIaas/AIaas/router/AI_worker_client.py", line 113, in predict
    prediction_output.result = client.predict(prediction_input.data)
  File "/Users/leepand/Downloads/BigRLab_APIs/demoday_fs/web_lab/knn_as_a_service/AIaas/AIaas/router/common_client.py", line 115, in wrapped
    raise FireflyError('Firefly functions only accept named arguments')
FireflyError: Firefly functions only accept named arguments
2018-05-17 20:38:44,479 - AIaas.router.AI_worker_client - ERROR - Predict has failed.. 
Traceback (most recent call last):
  File "/Users/leepand/Downloads/BigRLab_APIs/demoday_fs/web_lab/knn_as_a_service/AIaas/AIaas/router/AI_worker_client.py", line 113, in predict
    prediction_output.result = client.predict(prediction_input.data)
  File "/Users/leepand/Downloads/BigRLab_APIs/demoday_fs/web_lab/knn_as_a_service/AIaas/AIaas/router/common_client.py", line 115, in wrapped
    raise FireflyError('Firefly functions only accept named arguments')
FireflyError: Firefly functions only accept named arguments
2018-05-17 20:38:44,481 - AIaas.router.AI_worker_client - ERROR - Predict has failed.. 
Traceback (most recent call last):
  File "/Users/leepand/Downloads/BigRLab_APIs/demoday_fs/web_lab/knn_as_a_service/AIaas/AIaas/router/AI_worker_client.py", line 113, in predict
    prediction_output.result = client.predict(prediction_input.data)
  File "/Users/leepand/Downloads/BigRLab_APIs/demoday_fs/web_lab/knn_as_a_service/AIaas/AIaas/router/common_client.py", line 115, in wrapped
    raise FireflyError('Firefly functions only accept named arguments')
FireflyError: Firefly functions only accept named arguments
2018-05-17 20:38:44,482 - AIaas.router.AI_worker_client - ERROR - Predict has failed.. 
Traceback (most recent call last):
  File "/Users/leepand/Downloads/BigRLab_APIs/demoday_fs/web_lab/knn_as_a_service/AIaas/AIaas/router/AI_worker_client.py", line 113, in predict
    prediction_output.result = client.predict(prediction_input.data)
  File "/Users/leepand/Downloads/BigRLab_APIs/demoday_fs/web_lab/knn_as_a_service/AIaas/AIaas/router/common_client.py", line 115, in wrapped
    raise FireflyError('Firefly functions only accept named arguments')
FireflyError: Firefly functions only accept named arguments
2018-05-17 20:38:44,484 - AIaas.router.AI_worker_client - ERROR - Predict has failed.. 
Traceback (most recent call last):
  File "/Users/leepand/Downloads/BigRLab_APIs/demoday_fs/web_lab/knn_as_a_service/AIaas/AIaas/router/AI_worker_client.py", line 113, in predict
    prediction_output.result = client.predict(prediction_input.data)
  File "/Users/leepand/Downloads/BigRLab_APIs/demoday_fs/web_lab/knn_as_a_service/AIaas/AIaas/router/common_client.py", line 115, in wrapped
    raise FireflyError('Firefly functions only accept named arguments')
FireflyError: Firefly functions only accept named arguments
2018-05-17 20:38:44,486 - AIaas.router.AI_worker_client - ERROR - Predict has failed.. 
Traceback (most recent call last):
  File "/Users/leepand/Downloads/BigRLab_APIs/demoday_fs/web_lab/knn_as_a_service/AIaas/AIaas/router/AI_worker_client.py", line 113, in predict
    prediction_output.result = client.predict(prediction_input.data)
  File "/Users/leepand/Downloads/BigRLab_APIs/demoday_fs/web_lab/knn_as_a_service/AIaas/AIaas/router/common_client.py", line 115, in wrapped
    raise FireflyError('Firefly functions only accept named arguments')
FireflyError: Firefly functions only accept named arguments
2018-05-17 20:39:01,684 - AIaas.router.AI_worker_client - ERROR - Predict has failed.. 
Traceback (most recent call last):
  File "/Users/leepand/Downloads/BigRLab_APIs/demoday_fs/web_lab/knn_as_a_service/AIaas/AIaas/router/AI_worker_client.py", line 113, in predict
    prediction_output.result = client.predict(prediction_input.data)
  File "/Users/leepand/Downloads/BigRLab_APIs/demoday_fs/web_lab/knn_as_a_service/AIaas/AIaas/router/common_client.py", line 115, in wrapped
    raise FireflyError('Firefly functions only accept named arguments')
FireflyError: Firefly functions only accept named arguments
2018-05-17 20:39:01,685 - AIaas.router.AI_worker_client - ERROR - Predict has failed.. 
Traceback (most recent call last):
  File "/Users/leepand/Downloads/BigRLab_APIs/demoday_fs/web_lab/knn_as_a_service/AIaas/AIaas/router/AI_worker_client.py", line 113, in predict
    prediction_output.result = client.predict(prediction_input.data)
  File "/Users/leepand/Downloads/BigRLab_APIs/demoday_fs/web_lab/knn_as_a_service/AIaas/AIaas/router/common_client.py", line 115, in wrapped
    raise FireflyError('Firefly functions only accept named arguments')
FireflyError: Firefly functions only accept named arguments
2018-05-17 20:39:01,687 - AIaas.router.AI_worker_client - ERROR - Predict has failed.. 
Traceback (most recent call last):
  File "/Users/leepand/Downloads/BigRLab_APIs/demoday_fs/web_lab/knn_as_a_service/AIaas/AIaas/router/AI_worker_client.py", line 113, in predict
    prediction_output.result = client.predict(prediction_input.data)
  File "/Users/leepand/Downloads/BigRLab_APIs/demoday_fs/web_lab/knn_as_a_service/AIaas/AIaas/router/common_client.py", line 115, in wrapped
    raise FireflyError('Firefly functions only accept named arguments')
FireflyError: Firefly functions only accept named arguments
2018-05-17 20:39:01,688 - AIaas.router.AI_worker_client - ERROR - Predict has failed.. 
Traceback (most recent call last):
  File "/Users/leepand/Downloads/BigRLab_APIs/demoday_fs/web_lab/knn_as_a_service/AIaas/AIaas/router/AI_worker_client.py", line 113, in predict
    prediction_output.result = client.predict(prediction_input.data)
  File "/Users/leepand/Downloads/BigRLab_APIs/demoday_fs/web_lab/knn_as_a_service/AIaas/AIaas/router/common_client.py", line 115, in wrapped
    raise FireflyError('Firefly functions only accept named arguments')
FireflyError: Firefly functions only accept named arguments
2018-05-17 20:39:01,690 - AIaas.router.AI_worker_client - ERROR - Predict has failed.. 
Traceback (most recent call last):
  File "/Users/leepand/Downloads/BigRLab_APIs/demoday_fs/web_lab/knn_as_a_service/AIaas/AIaas/router/AI_worker_client.py", line 113, in predict
    prediction_output.result = client.predict(prediction_input.data)
  File "/Users/leepand/Downloads/BigRLab_APIs/demoday_fs/web_lab/knn_as_a_service/AIaas/AIaas/router/common_client.py", line 115, in wrapped
    raise FireflyError('Firefly functions only accept named arguments')
FireflyError: Firefly functions only accept named arguments
2018-05-17 20:39:01,691 - AIaas.router.AI_worker_client - ERROR - Predict has failed.. 
Traceback (most recent call last):
  File "/Users/leepand/Downloads/BigRLab_APIs/demoday_fs/web_lab/knn_as_a_service/AIaas/AIaas/router/AI_worker_client.py", line 113, in predict
    prediction_output.result = client.predict(prediction_input.data)
  File "/Users/leepand/Downloads/BigRLab_APIs/demoday_fs/web_lab/knn_as_a_service/AIaas/AIaas/router/common_client.py", line 115, in wrapped
    raise FireflyError('Firefly functions only accept named arguments')
FireflyError: Firefly functions only accept named arguments
2018-05-17 21:38:43,090 - AIaas.router.AI_worker_client - ERROR - Predict has failed.. 
Traceback (most recent call last):
  File "/Users/leepand/Downloads/BigRLab_APIs/demoday_fs/web_lab/knn_as_a_service/AIaas/AIaas/router/AI_worker_client.py", line 113, in predict
    prediction_output.result = client.predict(prediction_input.data)
  File "/Users/leepand/Downloads/BigRLab_APIs/demoday_fs/web_lab/knn_as_a_service/AIaas/AIaas/router/common_client.py", line 116, in wrapped
    raise FireflyError('Firefly functions only accept named arguments')
FireflyError: Firefly functions only accept named arguments
2018-05-17 21:38:43,093 - AIaas.router.AI_worker_client - ERROR - Predict has failed.. 
Traceback (most recent call last):
  File "/Users/leepand/Downloads/BigRLab_APIs/demoday_fs/web_lab/knn_as_a_service/AIaas/AIaas/router/AI_worker_client.py", line 113, in predict
    prediction_output.result = client.predict(prediction_input.data)
  File "/Users/leepand/Downloads/BigRLab_APIs/demoday_fs/web_lab/knn_as_a_service/AIaas/AIaas/router/common_client.py", line 116, in wrapped
    raise FireflyError('Firefly functions only accept named arguments')
FireflyError: Firefly functions only accept named arguments
2018-05-17 21:38:43,094 - AIaas.router.AI_worker_client - ERROR - Predict has failed.. 
Traceback (most recent call last):
  File "/Users/leepand/Downloads/BigRLab_APIs/demoday_fs/web_lab/knn_as_a_service/AIaas/AIaas/router/AI_worker_client.py", line 113, in predict
    prediction_output.result = client.predict(prediction_input.data)
  File "/Users/leepand/Downloads/BigRLab_APIs/demoday_fs/web_lab/knn_as_a_service/AIaas/AIaas/router/common_client.py", line 116, in wrapped
    raise FireflyError('Firefly functions only accept named arguments')
FireflyError: Firefly functions only accept named arguments
2018-05-17 21:38:43,096 - AIaas.router.AI_worker_client - ERROR - Predict has failed.. 
Traceback (most recent call last):
  File "/Users/leepand/Downloads/BigRLab_APIs/demoday_fs/web_lab/knn_as_a_service/AIaas/AIaas/router/AI_worker_client.py", line 113, in predict
    prediction_output.result = client.predict(prediction_input.data)
  File "/Users/leepand/Downloads/BigRLab_APIs/demoday_fs/web_lab/knn_as_a_service/AIaas/AIaas/router/common_client.py", line 116, in wrapped
    raise FireflyError('Firefly functions only accept named arguments')
FireflyError: Firefly functions only accept named arguments
2018-05-17 21:38:43,098 - AIaas.router.AI_worker_client - ERROR - Predict has failed.. 
Traceback (most recent call last):
  File "/Users/leepand/Downloads/BigRLab_APIs/demoday_fs/web_lab/knn_as_a_service/AIaas/AIaas/router/AI_worker_client.py", line 113, in predict
    prediction_output.result = client.predict(prediction_input.data)
  File "/Users/leepand/Downloads/BigRLab_APIs/demoday_fs/web_lab/knn_as_a_service/AIaas/AIaas/router/common_client.py", line 116, in wrapped
    raise FireflyError('Firefly functions only accept named arguments')
FireflyError: Firefly functions only accept named arguments
2018-05-17 21:38:43,099 - AIaas.router.AI_worker_client - ERROR - Predict has failed.. 
Traceback (most recent call last):
  File "/Users/leepand/Downloads/BigRLab_APIs/demoday_fs/web_lab/knn_as_a_service/AIaas/AIaas/router/AI_worker_client.py", line 113, in predict
    prediction_output.result = client.predict(prediction_input.data)
  File "/Users/leepand/Downloads/BigRLab_APIs/demoday_fs/web_lab/knn_as_a_service/AIaas/AIaas/router/common_client.py", line 116, in wrapped
    raise FireflyError('Firefly functions only accept named arguments')
FireflyError: Firefly functions only accept named arguments
2018-05-17 21:40:11,301 - AIaas.router.AI_worker_client - ERROR - Predict has failed.. 
Traceback (most recent call last):
  File "/Users/leepand/Downloads/BigRLab_APIs/demoday_fs/web_lab/knn_as_a_service/AIaas/AIaas/router/AI_worker_client.py", line 113, in predict
    prediction_output.result = client.predict(prediction_input.data)
  File "/Users/leepand/Downloads/BigRLab_APIs/demoday_fs/web_lab/knn_as_a_service/AIaas/AIaas/router/common_client.py", line 116, in wrapped
    raise FireflyError('Firefly functions only accept named arguments')
FireflyError: Firefly functions only accept named arguments
2018-05-17 21:40:11,303 - AIaas.router.AI_worker_client - ERROR - Predict has failed.. 
Traceback (most recent call last):
  File "/Users/leepand/Downloads/BigRLab_APIs/demoday_fs/web_lab/knn_as_a_service/AIaas/AIaas/router/AI_worker_client.py", line 113, in predict
    prediction_output.result = client.predict(prediction_input.data)
  File "/Users/leepand/Downloads/BigRLab_APIs/demoday_fs/web_lab/knn_as_a_service/AIaas/AIaas/router/common_client.py", line 116, in wrapped
    raise FireflyError('Firefly functions only accept named arguments')
FireflyError: Firefly functions only accept named arguments
2018-05-17 21:40:11,304 - AIaas.router.AI_worker_client - ERROR - Predict has failed.. 
Traceback (most recent call last):
  File "/Users/leepand/Downloads/BigRLab_APIs/demoday_fs/web_lab/knn_as_a_service/AIaas/AIaas/router/AI_worker_client.py", line 113, in predict
    prediction_output.result = client.predict(prediction_input.data)
  File "/Users/leepand/Downloads/BigRLab_APIs/demoday_fs/web_lab/knn_as_a_service/AIaas/AIaas/router/common_client.py", line 116, in wrapped
    raise FireflyError('Firefly functions only accept named arguments')
FireflyError: Firefly functions only accept named arguments
2018-05-17 21:40:11,306 - AIaas.router.AI_worker_client - ERROR - Predict has failed.. 
Traceback (most recent call last):
  File "/Users/leepand/Downloads/BigRLab_APIs/demoday_fs/web_lab/knn_as_a_service/AIaas/AIaas/router/AI_worker_client.py", line 113, in predict
    prediction_output.result = client.predict(prediction_input.data)
  File "/Users/leepand/Downloads/BigRLab_APIs/demoday_fs/web_lab/knn_as_a_service/AIaas/AIaas/router/common_client.py", line 116, in wrapped
    raise FireflyError('Firefly functions only accept named arguments')
FireflyError: Firefly functions only accept named arguments
2018-05-17 21:40:11,307 - AIaas.router.AI_worker_client - ERROR - Predict has failed.. 
Traceback (most recent call last):
  File "/Users/leepand/Downloads/BigRLab_APIs/demoday_fs/web_lab/knn_as_a_service/AIaas/AIaas/router/AI_worker_client.py", line 113, in predict
    prediction_output.result = client.predict(prediction_input.data)
  File "/Users/leepand/Downloads/BigRLab_APIs/demoday_fs/web_lab/knn_as_a_service/AIaas/AIaas/router/common_client.py", line 116, in wrapped
    raise FireflyError('Firefly functions only accept named arguments')
FireflyError: Firefly functions only accept named arguments
2018-05-17 21:40:11,309 - AIaas.router.AI_worker_client - ERROR - Predict has failed.. 
Traceback (most recent call last):
  File "/Users/leepand/Downloads/BigRLab_APIs/demoday_fs/web_lab/knn_as_a_service/AIaas/AIaas/router/AI_worker_client.py", line 113, in predict
    prediction_output.result = client.predict(prediction_input.data)
  File "/Users/leepand/Downloads/BigRLab_APIs/demoday_fs/web_lab/knn_as_a_service/AIaas/AIaas/router/common_client.py", line 116, in wrapped
    raise FireflyError('Firefly functions only accept named arguments')
FireflyError: Firefly functions only accept named arguments
2018-05-17 21:40:20,839 - AIaas.router.AI_worker_client - ERROR - Predict has failed.. 
Traceback (most recent call last):
  File "/Users/leepand/Downloads/BigRLab_APIs/demoday_fs/web_lab/knn_as_a_service/AIaas/AIaas/router/AI_worker_client.py", line 113, in predict
    prediction_output.result = client.predict(prediction_input.data)
  File "/Users/leepand/Downloads/BigRLab_APIs/demoday_fs/web_lab/knn_as_a_service/AIaas/AIaas/router/common_client.py", line 116, in wrapped
    raise FireflyError('Firefly functions only accept named arguments')
FireflyError: Firefly functions only accept named arguments
2018-05-17 21:40:20,841 - AIaas.router.AI_worker_client - ERROR - Predict has failed.. 
Traceback (most recent call last):
  File "/Users/leepand/Downloads/BigRLab_APIs/demoday_fs/web_lab/knn_as_a_service/AIaas/AIaas/router/AI_worker_client.py", line 113, in predict
    prediction_output.result = client.predict(prediction_input.data)
  File "/Users/leepand/Downloads/BigRLab_APIs/demoday_fs/web_lab/knn_as_a_service/AIaas/AIaas/router/common_client.py", line 116, in wrapped
    raise FireflyError('Firefly functions only accept named arguments')
FireflyError: Firefly functions only accept named arguments
2018-05-17 21:40:20,842 - AIaas.router.AI_worker_client - ERROR - Predict has failed.. 
Traceback (most recent call last):
  File "/Users/leepand/Downloads/BigRLab_APIs/demoday_fs/web_lab/knn_as_a_service/AIaas/AIaas/router/AI_worker_client.py", line 113, in predict
    prediction_output.result = client.predict(prediction_input.data)
  File "/Users/leepand/Downloads/BigRLab_APIs/demoday_fs/web_lab/knn_as_a_service/AIaas/AIaas/router/common_client.py", line 116, in wrapped
    raise FireflyError('Firefly functions only accept named arguments')
FireflyError: Firefly functions only accept named arguments
2018-05-17 21:40:20,843 - AIaas.router.AI_worker_client - ERROR - Predict has failed.. 
Traceback (most recent call last):
  File "/Users/leepand/Downloads/BigRLab_APIs/demoday_fs/web_lab/knn_as_a_service/AIaas/AIaas/router/AI_worker_client.py", line 113, in predict
    prediction_output.result = client.predict(prediction_input.data)
  File "/Users/leepand/Downloads/BigRLab_APIs/demoday_fs/web_lab/knn_as_a_service/AIaas/AIaas/router/common_client.py", line 116, in wrapped
    raise FireflyError('Firefly functions only accept named arguments')
FireflyError: Firefly functions only accept named arguments
2018-05-17 21:40:20,845 - AIaas.router.AI_worker_client - ERROR - Predict has failed.. 
Traceback (most recent call last):
  File "/Users/leepand/Downloads/BigRLab_APIs/demoday_fs/web_lab/knn_as_a_service/AIaas/AIaas/router/AI_worker_client.py", line 113, in predict
    prediction_output.result = client.predict(prediction_input.data)
  File "/Users/leepand/Downloads/BigRLab_APIs/demoday_fs/web_lab/knn_as_a_service/AIaas/AIaas/router/common_client.py", line 116, in wrapped
    raise FireflyError('Firefly functions only accept named arguments')
FireflyError: Firefly functions only accept named arguments
2018-05-17 21:40:20,847 - AIaas.router.AI_worker_client - ERROR - Predict has failed.. 
Traceback (most recent call last):
  File "/Users/leepand/Downloads/BigRLab_APIs/demoday_fs/web_lab/knn_as_a_service/AIaas/AIaas/router/AI_worker_client.py", line 113, in predict
    prediction_output.result = client.predict(prediction_input.data)
  File "/Users/leepand/Downloads/BigRLab_APIs/demoday_fs/web_lab/knn_as_a_service/AIaas/AIaas/router/common_client.py", line 116, in wrapped
    raise FireflyError('Firefly functions only accept named arguments')
FireflyError: Firefly functions only accept named arguments
2018-05-17 21:40:43,792 - AIaas.router.AI_worker_client - ERROR - Predict has failed.. 
Traceback (most recent call last):
  File "/Users/leepand/Downloads/BigRLab_APIs/demoday_fs/web_lab/knn_as_a_service/AIaas/AIaas/router/AI_worker_client.py", line 113, in predict
    prediction_output.result = client.predict(prediction_input.data)
  File "/Users/leepand/Downloads/BigRLab_APIs/demoday_fs/web_lab/knn_as_a_service/AIaas/AIaas/router/common_client.py", line 116, in wrapped
    raise FireflyError('Firefly functions only accept named arguments')
FireflyError: Firefly functions only accept named arguments
2018-05-17 21:40:43,793 - AIaas.router.AI_worker_client - ERROR - Predict has failed.. 
Traceback (most recent call last):
  File "/Users/leepand/Downloads/BigRLab_APIs/demoday_fs/web_lab/knn_as_a_service/AIaas/AIaas/router/AI_worker_client.py", line 113, in predict
    prediction_output.result = client.predict(prediction_input.data)
  File "/Users/leepand/Downloads/BigRLab_APIs/demoday_fs/web_lab/knn_as_a_service/AIaas/AIaas/router/common_client.py", line 116, in wrapped
    raise FireflyError('Firefly functions only accept named arguments')
FireflyError: Firefly functions only accept named arguments
2018-05-17 21:40:43,795 - AIaas.router.AI_worker_client - ERROR - Predict has failed.. 
Traceback (most recent call last):
  File "/Users/leepand/Downloads/BigRLab_APIs/demoday_fs/web_lab/knn_as_a_service/AIaas/AIaas/router/AI_worker_client.py", line 113, in predict
    prediction_output.result = client.predict(prediction_input.data)
  File "/Users/leepand/Downloads/BigRLab_APIs/demoday_fs/web_lab/knn_as_a_service/AIaas/AIaas/router/common_client.py", line 116, in wrapped
    raise FireflyError('Firefly functions only accept named arguments')
FireflyError: Firefly functions only accept named arguments
2018-05-17 21:40:43,796 - AIaas.router.AI_worker_client - ERROR - Predict has failed.. 
Traceback (most recent call last):
  File "/Users/leepand/Downloads/BigRLab_APIs/demoday_fs/web_lab/knn_as_a_service/AIaas/AIaas/router/AI_worker_client.py", line 113, in predict
    prediction_output.result = client.predict(prediction_input.data)
  File "/Users/leepand/Downloads/BigRLab_APIs/demoday_fs/web_lab/knn_as_a_service/AIaas/AIaas/router/common_client.py", line 116, in wrapped
    raise FireflyError('Firefly functions only accept named arguments')
FireflyError: Firefly functions only accept named arguments
2018-05-17 21:40:43,798 - AIaas.router.AI_worker_client - ERROR - Predict has failed.. 
Traceback (most recent call last):
  File "/Users/leepand/Downloads/BigRLab_APIs/demoday_fs/web_lab/knn_as_a_service/AIaas/AIaas/router/AI_worker_client.py", line 113, in predict
    prediction_output.result = client.predict(prediction_input.data)
  File "/Users/leepand/Downloads/BigRLab_APIs/demoday_fs/web_lab/knn_as_a_service/AIaas/AIaas/router/common_client.py", line 116, in wrapped
    raise FireflyError('Firefly functions only accept named arguments')
FireflyError: Firefly functions only accept named arguments
2018-05-17 21:40:43,799 - AIaas.router.AI_worker_client - ERROR - Predict has failed.. 
Traceback (most recent call last):
  File "/Users/leepand/Downloads/BigRLab_APIs/demoday_fs/web_lab/knn_as_a_service/AIaas/AIaas/router/AI_worker_client.py", line 113, in predict
    prediction_output.result = client.predict(prediction_input.data)
  File "/Users/leepand/Downloads/BigRLab_APIs/demoday_fs/web_lab/knn_as_a_service/AIaas/AIaas/router/common_client.py", line 116, in wrapped
    raise FireflyError('Firefly functions only accept named arguments')
FireflyError: Firefly functions only accept named arguments
2018-05-17 21:41:53,836 - AIaas.router.AI_worker_client - ERROR - Predict has failed.. 
Traceback (most recent call last):
  File "/Users/leepand/Downloads/BigRLab_APIs/demoday_fs/web_lab/knn_as_a_service/AIaas/AIaas/router/AI_worker_client.py", line 113, in predict
    prediction_output.result = client.predict(prediction_input.data)
  File "/Users/leepand/Downloads/BigRLab_APIs/demoday_fs/web_lab/knn_as_a_service/AIaas/AIaas/router/common_client.py", line 116, in wrapped
    raise FireflyError('Firefly functions only accept named arguments')
FireflyError: Firefly functions only accept named arguments
2018-05-17 21:41:53,838 - AIaas.router.AI_worker_client - ERROR - Predict has failed.. 
Traceback (most recent call last):
  File "/Users/leepand/Downloads/BigRLab_APIs/demoday_fs/web_lab/knn_as_a_service/AIaas/AIaas/router/AI_worker_client.py", line 113, in predict
    prediction_output.result = client.predict(prediction_input.data)
  File "/Users/leepand/Downloads/BigRLab_APIs/demoday_fs/web_lab/knn_as_a_service/AIaas/AIaas/router/common_client.py", line 116, in wrapped
    raise FireflyError('Firefly functions only accept named arguments')
FireflyError: Firefly functions only accept named arguments
2018-05-17 21:41:53,839 - AIaas.router.AI_worker_client - ERROR - Predict has failed.. 
Traceback (most recent call last):
  File "/Users/leepand/Downloads/BigRLab_APIs/demoday_fs/web_lab/knn_as_a_service/AIaas/AIaas/router/AI_worker_client.py", line 113, in predict
    prediction_output.result = client.predict(prediction_input.data)
  File "/Users/leepand/Downloads/BigRLab_APIs/demoday_fs/web_lab/knn_as_a_service/AIaas/AIaas/router/common_client.py", line 116, in wrapped
    raise FireflyError('Firefly functions only accept named arguments')
FireflyError: Firefly functions only accept named arguments
2018-05-17 21:41:53,841 - AIaas.router.AI_worker_client - ERROR - Predict has failed.. 
Traceback (most recent call last):
  File "/Users/leepand/Downloads/BigRLab_APIs/demoday_fs/web_lab/knn_as_a_service/AIaas/AIaas/router/AI_worker_client.py", line 113, in predict
    prediction_output.result = client.predict(prediction_input.data)
  File "/Users/leepand/Downloads/BigRLab_APIs/demoday_fs/web_lab/knn_as_a_service/AIaas/AIaas/router/common_client.py", line 116, in wrapped
    raise FireflyError('Firefly functions only accept named arguments')
FireflyError: Firefly functions only accept named arguments
2018-05-17 21:41:53,843 - AIaas.router.AI_worker_client - ERROR - Predict has failed.. 
Traceback (most recent call last):
  File "/Users/leepand/Downloads/BigRLab_APIs/demoday_fs/web_lab/knn_as_a_service/AIaas/AIaas/router/AI_worker_client.py", line 113, in predict
    prediction_output.result = client.predict(prediction_input.data)
  File "/Users/leepand/Downloads/BigRLab_APIs/demoday_fs/web_lab/knn_as_a_service/AIaas/AIaas/router/common_client.py", line 116, in wrapped
    raise FireflyError('Firefly functions only accept named arguments')
FireflyError: Firefly functions only accept named arguments
2018-05-17 21:41:53,844 - AIaas.router.AI_worker_client - ERROR - Predict has failed.. 
Traceback (most recent call last):
  File "/Users/leepand/Downloads/BigRLab_APIs/demoday_fs/web_lab/knn_as_a_service/AIaas/AIaas/router/AI_worker_client.py", line 113, in predict
    prediction_output.result = client.predict(prediction_input.data)
  File "/Users/leepand/Downloads/BigRLab_APIs/demoday_fs/web_lab/knn_as_a_service/AIaas/AIaas/router/common_client.py", line 116, in wrapped
    raise FireflyError('Firefly functions only accept named arguments')
FireflyError: Firefly functions only accept named arguments
2018-05-17 21:42:27,228 - AIaas.router.AI_worker_client - ERROR - Predict has failed.. 
Traceback (most recent call last):
  File "/Users/leepand/Downloads/BigRLab_APIs/demoday_fs/web_lab/knn_as_a_service/AIaas/AIaas/router/AI_worker_client.py", line 113, in predict
    prediction_output.result = client.predict(prediction_input.data)
  File "/Users/leepand/Downloads/BigRLab_APIs/demoday_fs/web_lab/knn_as_a_service/AIaas/AIaas/router/common_client.py", line 116, in wrapped
    raise FireflyError('Firefly functions only accept named arguments')
FireflyError: Firefly functions only accept named arguments
2018-05-17 21:42:27,230 - AIaas.router.AI_worker_client - ERROR - Predict has failed.. 
Traceback (most recent call last):
  File "/Users/leepand/Downloads/BigRLab_APIs/demoday_fs/web_lab/knn_as_a_service/AIaas/AIaas/router/AI_worker_client.py", line 113, in predict
    prediction_output.result = client.predict(prediction_input.data)
  File "/Users/leepand/Downloads/BigRLab_APIs/demoday_fs/web_lab/knn_as_a_service/AIaas/AIaas/router/common_client.py", line 116, in wrapped
    raise FireflyError('Firefly functions only accept named arguments')
FireflyError: Firefly functions only accept named arguments
2018-05-17 21:42:27,231 - AIaas.router.AI_worker_client - ERROR - Predict has failed.. 
Traceback (most recent call last):
  File "/Users/leepand/Downloads/BigRLab_APIs/demoday_fs/web_lab/knn_as_a_service/AIaas/AIaas/router/AI_worker_client.py", line 113, in predict
    prediction_output.result = client.predict(prediction_input.data)
  File "/Users/leepand/Downloads/BigRLab_APIs/demoday_fs/web_lab/knn_as_a_service/AIaas/AIaas/router/common_client.py", line 116, in wrapped
    raise FireflyError('Firefly functions only accept named arguments')
FireflyError: Firefly functions only accept named arguments
2018-05-17 21:42:27,233 - AIaas.router.AI_worker_client - ERROR - Predict has failed.. 
Traceback (most recent call last):
  File "/Users/leepand/Downloads/BigRLab_APIs/demoday_fs/web_lab/knn_as_a_service/AIaas/AIaas/router/AI_worker_client.py", line 113, in predict
    prediction_output.result = client.predict(prediction_input.data)
  File "/Users/leepand/Downloads/BigRLab_APIs/demoday_fs/web_lab/knn_as_a_service/AIaas/AIaas/router/common_client.py", line 116, in wrapped
    raise FireflyError('Firefly functions only accept named arguments')
FireflyError: Firefly functions only accept named arguments
2018-05-17 21:42:27,234 - AIaas.router.AI_worker_client - ERROR - Predict has failed.. 
Traceback (most recent call last):
  File "/Users/leepand/Downloads/BigRLab_APIs/demoday_fs/web_lab/knn_as_a_service/AIaas/AIaas/router/AI_worker_client.py", line 113, in predict
    prediction_output.result = client.predict(prediction_input.data)
  File "/Users/leepand/Downloads/BigRLab_APIs/demoday_fs/web_lab/knn_as_a_service/AIaas/AIaas/router/common_client.py", line 116, in wrapped
    raise FireflyError('Firefly functions only accept named arguments')
FireflyError: Firefly functions only accept named arguments
2018-05-17 21:42:27,235 - AIaas.router.AI_worker_client - ERROR - Predict has failed.. 
Traceback (most recent call last):
  File "/Users/leepand/Downloads/BigRLab_APIs/demoday_fs/web_lab/knn_as_a_service/AIaas/AIaas/router/AI_worker_client.py", line 113, in predict
    prediction_output.result = client.predict(prediction_input.data)
  File "/Users/leepand/Downloads/BigRLab_APIs/demoday_fs/web_lab/knn_as_a_service/AIaas/AIaas/router/common_client.py", line 116, in wrapped
    raise FireflyError('Firefly functions only accept named arguments')
FireflyError: Firefly functions only accept named arguments
2018-05-17 21:42:40,807 - AIaas.router.AI_worker_client - ERROR - Predict has failed.. 
Traceback (most recent call last):
  File "/Users/leepand/Downloads/BigRLab_APIs/demoday_fs/web_lab/knn_as_a_service/AIaas/AIaas/router/AI_worker_client.py", line 113, in predict
    prediction_output.result = client.predict(prediction_input.data)
  File "/Users/leepand/Downloads/BigRLab_APIs/demoday_fs/web_lab/knn_as_a_service/AIaas/AIaas/router/common_client.py", line 116, in wrapped
    raise FireflyError('Firefly functions only accept named arguments')
FireflyError: Firefly functions only accept named arguments
2018-05-17 21:42:40,809 - AIaas.router.AI_worker_client - ERROR - Predict has failed.. 
Traceback (most recent call last):
  File "/Users/leepand/Downloads/BigRLab_APIs/demoday_fs/web_lab/knn_as_a_service/AIaas/AIaas/router/AI_worker_client.py", line 113, in predict
    prediction_output.result = client.predict(prediction_input.data)
  File "/Users/leepand/Downloads/BigRLab_APIs/demoday_fs/web_lab/knn_as_a_service/AIaas/AIaas/router/common_client.py", line 116, in wrapped
    raise FireflyError('Firefly functions only accept named arguments')
FireflyError: Firefly functions only accept named arguments
2018-05-17 21:42:40,811 - AIaas.router.AI_worker_client - ERROR - Predict has failed.. 
Traceback (most recent call last):
  File "/Users/leepand/Downloads/BigRLab_APIs/demoday_fs/web_lab/knn_as_a_service/AIaas/AIaas/router/AI_worker_client.py", line 113, in predict
    prediction_output.result = client.predict(prediction_input.data)
  File "/Users/leepand/Downloads/BigRLab_APIs/demoday_fs/web_lab/knn_as_a_service/AIaas/AIaas/router/common_client.py", line 116, in wrapped
    raise FireflyError('Firefly functions only accept named arguments')
FireflyError: Firefly functions only accept named arguments
2018-05-17 21:42:40,812 - AIaas.router.AI_worker_client - ERROR - Predict has failed.. 
Traceback (most recent call last):
  File "/Users/leepand/Downloads/BigRLab_APIs/demoday_fs/web_lab/knn_as_a_service/AIaas/AIaas/router/AI_worker_client.py", line 113, in predict
    prediction_output.result = client.predict(prediction_input.data)
  File "/Users/leepand/Downloads/BigRLab_APIs/demoday_fs/web_lab/knn_as_a_service/AIaas/AIaas/router/common_client.py", line 116, in wrapped
    raise FireflyError('Firefly functions only accept named arguments')
FireflyError: Firefly functions only accept named arguments
2018-05-17 21:42:40,814 - AIaas.router.AI_worker_client - ERROR - Predict has failed.. 
Traceback (most recent call last):
  File "/Users/leepand/Downloads/BigRLab_APIs/demoday_fs/web_lab/knn_as_a_service/AIaas/AIaas/router/AI_worker_client.py", line 113, in predict
    prediction_output.result = client.predict(prediction_input.data)
  File "/Users/leepand/Downloads/BigRLab_APIs/demoday_fs/web_lab/knn_as_a_service/AIaas/AIaas/router/common_client.py", line 116, in wrapped
    raise FireflyError('Firefly functions only accept named arguments')
FireflyError: Firefly functions only accept named arguments
2018-05-17 21:42:40,815 - AIaas.router.AI_worker_client - ERROR - Predict has failed.. 
Traceback (most recent call last):
  File "/Users/leepand/Downloads/BigRLab_APIs/demoday_fs/web_lab/knn_as_a_service/AIaas/AIaas/router/AI_worker_client.py", line 113, in predict
    prediction_output.result = client.predict(prediction_input.data)
  File "/Users/leepand/Downloads/BigRLab_APIs/demoday_fs/web_lab/knn_as_a_service/AIaas/AIaas/router/common_client.py", line 116, in wrapped
    raise FireflyError('Firefly functions only accept named arguments')
FireflyError: Firefly functions only accept named arguments
2018-05-18 09:11:59,444 - AIaas.router.AI_worker_client - ERROR - Predict has failed.. 
Traceback (most recent call last):
  File "/Users/leepand/anaconda2/lib/python2.7/site-packages/gunicorn/workers/sync.py", line 68, in run_for_one
    self.accept(listener)
  File "/Users/leepand/anaconda2/lib/python2.7/site-packages/gunicorn/workers/sync.py", line 27, in accept
    client, addr = listener.accept()
  File "/Users/leepand/anaconda2/lib/python2.7/socket.py", line 206, in accept
    sock, addr = self._sock.accept()
error: [Errno 35] Resource temporarily unavailable
2018-05-18 09:12:08,882 - AIaas.router.AI_worker_client - ERROR - Predict has failed.. 
Traceback (most recent call last):
  File "/Users/leepand/anaconda2/lib/python2.7/site-packages/gunicorn/workers/sync.py", line 68, in run_for_one
    self.accept(listener)
  File "/Users/leepand/anaconda2/lib/python2.7/site-packages/gunicorn/workers/sync.py", line 27, in accept
    client, addr = listener.accept()
  File "/Users/leepand/anaconda2/lib/python2.7/socket.py", line 206, in accept
    sock, addr = self._sock.accept()
error: [Errno 35] Resource temporarily unavailable
2018-05-18 09:15:09,225 - AIaas.router.AI_worker_client - ERROR - Predict has failed.. 
Traceback (most recent call last):
  File "/Users/leepand/anaconda2/lib/python2.7/site-packages/gunicorn/workers/sync.py", line 68, in run_for_one
    self.accept(listener)
  File "/Users/leepand/anaconda2/lib/python2.7/site-packages/gunicorn/workers/sync.py", line 27, in accept
    client, addr = listener.accept()
  File "/Users/leepand/anaconda2/lib/python2.7/socket.py", line 206, in accept
    sock, addr = self._sock.accept()
error: [Errno 35] Resource temporarily unavailable
2018-05-18 09:15:18,374 - AIaas.router.AI_worker_client - ERROR - Predict has failed.. 
Traceback (most recent call last):
  File "/Users/leepand/anaconda2/lib/python2.7/site-packages/gunicorn/workers/sync.py", line 68, in run_for_one
    self.accept(listener)
  File "/Users/leepand/anaconda2/lib/python2.7/site-packages/gunicorn/workers/sync.py", line 27, in accept
    client, addr = listener.accept()
  File "/Users/leepand/anaconda2/lib/python2.7/socket.py", line 206, in accept
    sock, addr = self._sock.accept()
error: [Errno 35] Resource temporarily unavailable
2018-05-18 09:16:44,238 - AIaas.router.AI_worker_client - ERROR - Predict has failed.. 
Traceback (most recent call last):
  File "/Users/leepand/anaconda2/lib/python2.7/site-packages/gunicorn/workers/sync.py", line 68, in run_for_one
    self.accept(listener)
  File "/Users/leepand/anaconda2/lib/python2.7/site-packages/gunicorn/workers/sync.py", line 27, in accept
    client, addr = listener.accept()
  File "/Users/leepand/anaconda2/lib/python2.7/socket.py", line 206, in accept
    sock, addr = self._sock.accept()
error: [Errno 35] Resource temporarily unavailable
2018-05-18 09:16:50,710 - AIaas.router.AI_worker_client - ERROR - Predict has failed.. 
Traceback (most recent call last):
  File "/Users/leepand/anaconda2/lib/python2.7/site-packages/gunicorn/workers/sync.py", line 68, in run_for_one
    self.accept(listener)
  File "/Users/leepand/anaconda2/lib/python2.7/site-packages/gunicorn/workers/sync.py", line 27, in accept
    client, addr = listener.accept()
  File "/Users/leepand/anaconda2/lib/python2.7/socket.py", line 206, in accept
    sock, addr = self._sock.accept()
error: [Errno 35] Resource temporarily unavailable
2018-05-18 09:17:00,688 - AIaas.router.AI_worker_client - ERROR - Predict has failed.. 
Traceback (most recent call last):
  File "/Users/leepand/anaconda2/lib/python2.7/site-packages/gunicorn/workers/sync.py", line 68, in run_for_one
    self.accept(listener)
  File "/Users/leepand/anaconda2/lib/python2.7/site-packages/gunicorn/workers/sync.py", line 27, in accept
    client, addr = listener.accept()
  File "/Users/leepand/anaconda2/lib/python2.7/socket.py", line 206, in accept
    sock, addr = self._sock.accept()
error: [Errno 35] Resource temporarily unavailable
2018-05-18 09:17:02,031 - AIaas.router.AI_worker_client - ERROR - Predict has failed.. 
Traceback (most recent call last):
  File "/Users/leepand/anaconda2/lib/python2.7/site-packages/gunicorn/workers/sync.py", line 68, in run_for_one
    self.accept(listener)
  File "/Users/leepand/anaconda2/lib/python2.7/site-packages/gunicorn/workers/sync.py", line 27, in accept
    client, addr = listener.accept()
  File "/Users/leepand/anaconda2/lib/python2.7/socket.py", line 206, in accept
    sock, addr = self._sock.accept()
error: [Errno 35] Resource temporarily unavailable
2018-05-18 09:17:03,237 - AIaas.router.AI_worker_client - ERROR - Predict has failed.. 
Traceback (most recent call last):
  File "/Users/leepand/anaconda2/lib/python2.7/site-packages/gunicorn/workers/sync.py", line 68, in run_for_one
    self.accept(listener)
  File "/Users/leepand/anaconda2/lib/python2.7/site-packages/gunicorn/workers/sync.py", line 27, in accept
    client, addr = listener.accept()
  File "/Users/leepand/anaconda2/lib/python2.7/socket.py", line 206, in accept
    sock, addr = self._sock.accept()
error: [Errno 35] Resource temporarily unavailable
2018-05-18 09:21:44,284 - AIaas.router.AI_worker_client - ERROR - Predict has failed.. 
Traceback (most recent call last):
  File "/Users/leepand/Downloads/BigRLab_APIs/demoday_fs/web_lab/knn_as_a_service/AIaas/AIaas/router/AI_worker_client.py", line 118, in predict
    prediction_output.result = client.predict(prediction_input.data)
  File "/Users/leepand/Downloads/BigRLab_APIs/demoday_fs/web_lab/knn_as_a_service/AIaas/AIaas/router/common_client.py", line 247, in predict
    return self.post(self.__urls["predict"], json=data)
  File "/Users/leepand/Downloads/BigRLab_APIs/demoday_fs/web_lab/knn_as_a_service/AIaas/AIaas/router/common_client.py", line 106, in post
    r = requests.post(url=url, json=json, params=params, timeout=DD_TIMEOUT)
  File "/Users/leepand/anaconda2/lib/python2.7/site-packages/requests/api.py", line 110, in post
    return request('post', url, data=data, json=json, **kwargs)
  File "/Users/leepand/anaconda2/lib/python2.7/site-packages/requests/api.py", line 56, in request
    return session.request(method=method, url=url, **kwargs)
  File "/Users/leepand/anaconda2/lib/python2.7/site-packages/requests/sessions.py", line 475, in request
    resp = self.send(prep, **send_kwargs)
  File "/Users/leepand/anaconda2/lib/python2.7/site-packages/requests/sessions.py", line 596, in send
    r = adapter.send(request, **kwargs)
  File "/Users/leepand/anaconda2/lib/python2.7/site-packages/requests/adapters.py", line 487, in send
    raise ConnectionError(e, request=request)
ConnectionError: HTTPConnectionPool(host='localhost', port=9001): Max retries exceeded with url: /predict (Caused by NewConnectionError('<requests.packages.urllib3.connection.HTTPConnection object at 0x10963bf50>: Failed to establish a new connection: [Errno 61] Connection refused',))
2018-05-18 09:21:44,286 - AIaas.router.AI_worker_client - ERROR - Predict has failed.. 
Traceback (most recent call last):
  File "/Users/leepand/Downloads/BigRLab_APIs/demoday_fs/web_lab/knn_as_a_service/AIaas/AIaas/router/AI_worker_client.py", line 118, in predict
    prediction_output.result = client.predict(prediction_input.data)
  File "/Users/leepand/Downloads/BigRLab_APIs/demoday_fs/web_lab/knn_as_a_service/AIaas/AIaas/router/common_client.py", line 247, in predict
    return self.post(self.__urls["predict"], json=data)
  File "/Users/leepand/Downloads/BigRLab_APIs/demoday_fs/web_lab/knn_as_a_service/AIaas/AIaas/router/common_client.py", line 106, in post
    r = requests.post(url=url, json=json, params=params, timeout=DD_TIMEOUT)
  File "/Users/leepand/anaconda2/lib/python2.7/site-packages/requests/api.py", line 110, in post
    return request('post', url, data=data, json=json, **kwargs)
  File "/Users/leepand/anaconda2/lib/python2.7/site-packages/requests/api.py", line 56, in request
    return session.request(method=method, url=url, **kwargs)
  File "/Users/leepand/anaconda2/lib/python2.7/site-packages/requests/sessions.py", line 475, in request
    resp = self.send(prep, **send_kwargs)
  File "/Users/leepand/anaconda2/lib/python2.7/site-packages/requests/sessions.py", line 596, in send
    r = adapter.send(request, **kwargs)
  File "/Users/leepand/anaconda2/lib/python2.7/site-packages/requests/adapters.py", line 487, in send
    raise ConnectionError(e, request=request)
ConnectionError: HTTPConnectionPool(host='localhost', port=9001): Max retries exceeded with url: /predict (Caused by NewConnectionError('<requests.packages.urllib3.connection.HTTPConnection object at 0x10963bf50>: Failed to establish a new connection: [Errno 61] Connection refused',))
2018-05-18 09:21:44,295 - AIaas.router.AI_worker_client - ERROR - Predict has failed.. 
Traceback (most recent call last):
  File "/Users/leepand/Downloads/BigRLab_APIs/demoday_fs/web_lab/knn_as_a_service/AIaas/AIaas/router/AI_worker_client.py", line 118, in predict
    prediction_output.result = client.predict(prediction_input.data)
  File "/Users/leepand/Downloads/BigRLab_APIs/demoday_fs/web_lab/knn_as_a_service/AIaas/AIaas/router/common_client.py", line 247, in predict
    return self.post(self.__urls["predict"], json=data)
  File "/Users/leepand/Downloads/BigRLab_APIs/demoday_fs/web_lab/knn_as_a_service/AIaas/AIaas/router/common_client.py", line 106, in post
    r = requests.post(url=url, json=json, params=params, timeout=DD_TIMEOUT)
  File "/Users/leepand/anaconda2/lib/python2.7/site-packages/requests/api.py", line 110, in post
    return request('post', url, data=data, json=json, **kwargs)
  File "/Users/leepand/anaconda2/lib/python2.7/site-packages/requests/api.py", line 56, in request
    return session.request(method=method, url=url, **kwargs)
  File "/Users/leepand/anaconda2/lib/python2.7/site-packages/requests/sessions.py", line 475, in request
    resp = self.send(prep, **send_kwargs)
  File "/Users/leepand/anaconda2/lib/python2.7/site-packages/requests/sessions.py", line 596, in send
    r = adapter.send(request, **kwargs)
  File "/Users/leepand/anaconda2/lib/python2.7/site-packages/requests/adapters.py", line 487, in send
    raise ConnectionError(e, request=request)
ConnectionError: HTTPConnectionPool(host='localhost', port=9001): Max retries exceeded with url: /predict (Caused by NewConnectionError('<requests.packages.urllib3.connection.HTTPConnection object at 0x109660c10>: Failed to establish a new connection: [Errno 61] Connection refused',))
2018-05-18 09:21:44,298 - AIaas.router.AI_worker_client - ERROR - Predict has failed.. 
Traceback (most recent call last):
  File "/Users/leepand/Downloads/BigRLab_APIs/demoday_fs/web_lab/knn_as_a_service/AIaas/AIaas/router/AI_worker_client.py", line 118, in predict
    prediction_output.result = client.predict(prediction_input.data)
  File "/Users/leepand/Downloads/BigRLab_APIs/demoday_fs/web_lab/knn_as_a_service/AIaas/AIaas/router/common_client.py", line 247, in predict
    return self.post(self.__urls["predict"], json=data)
  File "/Users/leepand/Downloads/BigRLab_APIs/demoday_fs/web_lab/knn_as_a_service/AIaas/AIaas/router/common_client.py", line 106, in post
    r = requests.post(url=url, json=json, params=params, timeout=DD_TIMEOUT)
  File "/Users/leepand/anaconda2/lib/python2.7/site-packages/requests/api.py", line 110, in post
    return request('post', url, data=data, json=json, **kwargs)
  File "/Users/leepand/anaconda2/lib/python2.7/site-packages/requests/api.py", line 56, in request
    return session.request(method=method, url=url, **kwargs)
  File "/Users/leepand/anaconda2/lib/python2.7/site-packages/requests/sessions.py", line 475, in request
    resp = self.send(prep, **send_kwargs)
  File "/Users/leepand/anaconda2/lib/python2.7/site-packages/requests/sessions.py", line 596, in send
    r = adapter.send(request, **kwargs)
  File "/Users/leepand/anaconda2/lib/python2.7/site-packages/requests/adapters.py", line 487, in send
    raise ConnectionError(e, request=request)
ConnectionError: HTTPConnectionPool(host='localhost', port=9001): Max retries exceeded with url: /predict (Caused by NewConnectionError('<requests.packages.urllib3.connection.HTTPConnection object at 0x109660c10>: Failed to establish a new connection: [Errno 61] Connection refused',))
2018-05-18 09:21:44,308 - AIaas.router.AI_worker_client - ERROR - Predict has failed.. 
Traceback (most recent call last):
  File "/Users/leepand/Downloads/BigRLab_APIs/demoday_fs/web_lab/knn_as_a_service/AIaas/AIaas/router/AI_worker_client.py", line 118, in predict
    prediction_output.result = client.predict(prediction_input.data)
  File "/Users/leepand/Downloads/BigRLab_APIs/demoday_fs/web_lab/knn_as_a_service/AIaas/AIaas/router/common_client.py", line 247, in predict
    return self.post(self.__urls["predict"], json=data)
  File "/Users/leepand/Downloads/BigRLab_APIs/demoday_fs/web_lab/knn_as_a_service/AIaas/AIaas/router/common_client.py", line 106, in post
    r = requests.post(url=url, json=json, params=params, timeout=DD_TIMEOUT)
  File "/Users/leepand/anaconda2/lib/python2.7/site-packages/requests/api.py", line 110, in post
    return request('post', url, data=data, json=json, **kwargs)
  File "/Users/leepand/anaconda2/lib/python2.7/site-packages/requests/api.py", line 56, in request
    return session.request(method=method, url=url, **kwargs)
  File "/Users/leepand/anaconda2/lib/python2.7/site-packages/requests/sessions.py", line 475, in request
    resp = self.send(prep, **send_kwargs)
  File "/Users/leepand/anaconda2/lib/python2.7/site-packages/requests/sessions.py", line 596, in send
    r = adapter.send(request, **kwargs)
  File "/Users/leepand/anaconda2/lib/python2.7/site-packages/requests/adapters.py", line 487, in send
    raise ConnectionError(e, request=request)
ConnectionError: HTTPConnectionPool(host='localhost', port=9001): Max retries exceeded with url: /predict (Caused by NewConnectionError('<requests.packages.urllib3.connection.HTTPConnection object at 0x109660b10>: Failed to establish a new connection: [Errno 61] Connection refused',))
2018-05-18 09:21:44,312 - AIaas.router.AI_worker_client - ERROR - Predict has failed.. 
Traceback (most recent call last):
  File "/Users/leepand/Downloads/BigRLab_APIs/demoday_fs/web_lab/knn_as_a_service/AIaas/AIaas/router/AI_worker_client.py", line 118, in predict
    prediction_output.result = client.predict(prediction_input.data)
  File "/Users/leepand/Downloads/BigRLab_APIs/demoday_fs/web_lab/knn_as_a_service/AIaas/AIaas/router/common_client.py", line 247, in predict
    return self.post(self.__urls["predict"], json=data)
  File "/Users/leepand/Downloads/BigRLab_APIs/demoday_fs/web_lab/knn_as_a_service/AIaas/AIaas/router/common_client.py", line 106, in post
    r = requests.post(url=url, json=json, params=params, timeout=DD_TIMEOUT)
  File "/Users/leepand/anaconda2/lib/python2.7/site-packages/requests/api.py", line 110, in post
    return request('post', url, data=data, json=json, **kwargs)
  File "/Users/leepand/anaconda2/lib/python2.7/site-packages/requests/api.py", line 56, in request
    return session.request(method=method, url=url, **kwargs)
  File "/Users/leepand/anaconda2/lib/python2.7/site-packages/requests/sessions.py", line 475, in request
    resp = self.send(prep, **send_kwargs)
  File "/Users/leepand/anaconda2/lib/python2.7/site-packages/requests/sessions.py", line 596, in send
    r = adapter.send(request, **kwargs)
  File "/Users/leepand/anaconda2/lib/python2.7/site-packages/requests/adapters.py", line 487, in send
    raise ConnectionError(e, request=request)
ConnectionError: HTTPConnectionPool(host='localhost', port=9001): Max retries exceeded with url: /predict (Caused by NewConnectionError('<requests.packages.urllib3.connection.HTTPConnection object at 0x109660b10>: Failed to establish a new connection: [Errno 61] Connection refused',))
2018-05-18 09:22:27,023 - AIaas.router.AI_worker_client - ERROR - Predict has failed.. 
Traceback (most recent call last):
  File "/Users/leepand/anaconda2/lib/python2.7/site-packages/gunicorn/workers/sync.py", line 68, in run_for_one
    self.accept(listener)
  File "/Users/leepand/anaconda2/lib/python2.7/site-packages/gunicorn/workers/sync.py", line 27, in accept
    client, addr = listener.accept()
  File "/Users/leepand/anaconda2/lib/python2.7/socket.py", line 206, in accept
    sock, addr = self._sock.accept()
error: [Errno 35] Resource temporarily unavailable
2018-05-18 09:22:29,781 - AIaas.router.AI_worker_client - ERROR - Predict has failed.. 
Traceback (most recent call last):
  File "/Users/leepand/anaconda2/lib/python2.7/site-packages/gunicorn/workers/sync.py", line 68, in run_for_one
    self.accept(listener)
  File "/Users/leepand/anaconda2/lib/python2.7/site-packages/gunicorn/workers/sync.py", line 27, in accept
    client, addr = listener.accept()
  File "/Users/leepand/anaconda2/lib/python2.7/socket.py", line 206, in accept
    sock, addr = self._sock.accept()
error: [Errno 35] Resource temporarily unavailable
2018-05-18 09:22:30,895 - AIaas.router.AI_worker_client - ERROR - Predict has failed.. 
Traceback (most recent call last):
  File "/Users/leepand/anaconda2/lib/python2.7/site-packages/gunicorn/workers/sync.py", line 68, in run_for_one
    self.accept(listener)
  File "/Users/leepand/anaconda2/lib/python2.7/site-packages/gunicorn/workers/sync.py", line 27, in accept
    client, addr = listener.accept()
  File "/Users/leepand/anaconda2/lib/python2.7/socket.py", line 206, in accept
    sock, addr = self._sock.accept()
error: [Errno 35] Resource temporarily unavailable
2018-05-18 09:22:32,183 - AIaas.router.AI_worker_client - ERROR - Predict has failed.. 
Traceback (most recent call last):
  File "/Users/leepand/anaconda2/lib/python2.7/site-packages/gunicorn/workers/sync.py", line 68, in run_for_one
    self.accept(listener)
  File "/Users/leepand/anaconda2/lib/python2.7/site-packages/gunicorn/workers/sync.py", line 27, in accept
    client, addr = listener.accept()
  File "/Users/leepand/anaconda2/lib/python2.7/socket.py", line 206, in accept
    sock, addr = self._sock.accept()
error: [Errno 35] Resource temporarily unavailable
2018-05-18 09:22:33,646 - AIaas.router.AI_worker_client - ERROR - Predict has failed.. 
Traceback (most recent call last):
  File "/Users/leepand/anaconda2/lib/python2.7/site-packages/gunicorn/workers/sync.py", line 68, in run_for_one
    self.accept(listener)
  File "/Users/leepand/anaconda2/lib/python2.7/site-packages/gunicorn/workers/sync.py", line 27, in accept
    client, addr = listener.accept()
  File "/Users/leepand/anaconda2/lib/python2.7/socket.py", line 206, in accept
    sock, addr = self._sock.accept()
error: [Errno 35] Resource temporarily unavailable
2018-05-18 09:22:34,753 - AIaas.router.AI_worker_client - ERROR - Predict has failed.. 
Traceback (most recent call last):
  File "/Users/leepand/anaconda2/lib/python2.7/site-packages/gunicorn/workers/sync.py", line 68, in run_for_one
    self.accept(listener)
  File "/Users/leepand/anaconda2/lib/python2.7/site-packages/gunicorn/workers/sync.py", line 27, in accept
    client, addr = listener.accept()
  File "/Users/leepand/anaconda2/lib/python2.7/socket.py", line 206, in accept
    sock, addr = self._sock.accept()
error: [Errno 35] Resource temporarily unavailable
2018-05-18 09:22:35,829 - AIaas.router.AI_worker_client - ERROR - Predict has failed.. 
Traceback (most recent call last):
  File "/Users/leepand/Downloads/BigRLab_APIs/demoday_fs/web_lab/knn_as_a_service/AIaas/AIaas/router/AI_worker_client.py", line 118, in predict
    prediction_output.result = client.predict(prediction_input.data)
  File "/Users/leepand/Downloads/BigRLab_APIs/demoday_fs/web_lab/knn_as_a_service/AIaas/AIaas/router/common_client.py", line 247, in predict
    return self.post(self.__urls["predict"], json=data)
  File "/Users/leepand/Downloads/BigRLab_APIs/demoday_fs/web_lab/knn_as_a_service/AIaas/AIaas/router/common_client.py", line 106, in post
    r = requests.post(url=url, json=json, params=params, timeout=DD_TIMEOUT)
  File "/Users/leepand/anaconda2/lib/python2.7/site-packages/requests/api.py", line 110, in post
    return request('post', url, data=data, json=json, **kwargs)
  File "/Users/leepand/anaconda2/lib/python2.7/site-packages/requests/api.py", line 56, in request
    return session.request(method=method, url=url, **kwargs)
  File "/Users/leepand/anaconda2/lib/python2.7/site-packages/requests/sessions.py", line 475, in request
    resp = self.send(prep, **send_kwargs)
  File "/Users/leepand/anaconda2/lib/python2.7/site-packages/requests/sessions.py", line 596, in send
    r = adapter.send(request, **kwargs)
  File "/Users/leepand/anaconda2/lib/python2.7/site-packages/requests/adapters.py", line 487, in send
    raise ConnectionError(e, request=request)
ConnectionError: HTTPConnectionPool(host='localhost', port=9001): Max retries exceeded with url: /predict (Caused by NewConnectionError('<requests.packages.urllib3.connection.HTTPConnection object at 0x109660950>: Failed to establish a new connection: [Errno 61] Connection refused',))
2018-05-18 09:22:35,831 - AIaas.router.AI_worker_client - ERROR - Predict has failed.. 
Traceback (most recent call last):
  File "/Users/leepand/Downloads/BigRLab_APIs/demoday_fs/web_lab/knn_as_a_service/AIaas/AIaas/router/AI_worker_client.py", line 118, in predict
    prediction_output.result = client.predict(prediction_input.data)
  File "/Users/leepand/Downloads/BigRLab_APIs/demoday_fs/web_lab/knn_as_a_service/AIaas/AIaas/router/common_client.py", line 247, in predict
    return self.post(self.__urls["predict"], json=data)
  File "/Users/leepand/Downloads/BigRLab_APIs/demoday_fs/web_lab/knn_as_a_service/AIaas/AIaas/router/common_client.py", line 106, in post
    r = requests.post(url=url, json=json, params=params, timeout=DD_TIMEOUT)
  File "/Users/leepand/anaconda2/lib/python2.7/site-packages/requests/api.py", line 110, in post
    return request('post', url, data=data, json=json, **kwargs)
  File "/Users/leepand/anaconda2/lib/python2.7/site-packages/requests/api.py", line 56, in request
    return session.request(method=method, url=url, **kwargs)
  File "/Users/leepand/anaconda2/lib/python2.7/site-packages/requests/sessions.py", line 475, in request
    resp = self.send(prep, **send_kwargs)
  File "/Users/leepand/anaconda2/lib/python2.7/site-packages/requests/sessions.py", line 596, in send
    r = adapter.send(request, **kwargs)
  File "/Users/leepand/anaconda2/lib/python2.7/site-packages/requests/adapters.py", line 487, in send
    raise ConnectionError(e, request=request)
ConnectionError: HTTPConnectionPool(host='localhost', port=9001): Max retries exceeded with url: /predict (Caused by NewConnectionError('<requests.packages.urllib3.connection.HTTPConnection object at 0x109660950>: Failed to establish a new connection: [Errno 61] Connection refused',))
2018-05-18 09:22:35,839 - AIaas.router.AI_worker_client - ERROR - Predict has failed.. 
Traceback (most recent call last):
  File "/Users/leepand/Downloads/BigRLab_APIs/demoday_fs/web_lab/knn_as_a_service/AIaas/AIaas/router/AI_worker_client.py", line 118, in predict
    prediction_output.result = client.predict(prediction_input.data)
  File "/Users/leepand/Downloads/BigRLab_APIs/demoday_fs/web_lab/knn_as_a_service/AIaas/AIaas/router/common_client.py", line 247, in predict
    return self.post(self.__urls["predict"], json=data)
  File "/Users/leepand/Downloads/BigRLab_APIs/demoday_fs/web_lab/knn_as_a_service/AIaas/AIaas/router/common_client.py", line 106, in post
    r = requests.post(url=url, json=json, params=params, timeout=DD_TIMEOUT)
  File "/Users/leepand/anaconda2/lib/python2.7/site-packages/requests/api.py", line 110, in post
    return request('post', url, data=data, json=json, **kwargs)
  File "/Users/leepand/anaconda2/lib/python2.7/site-packages/requests/api.py", line 56, in request
    return session.request(method=method, url=url, **kwargs)
  File "/Users/leepand/anaconda2/lib/python2.7/site-packages/requests/sessions.py", line 475, in request
    resp = self.send(prep, **send_kwargs)
  File "/Users/leepand/anaconda2/lib/python2.7/site-packages/requests/sessions.py", line 596, in send
    r = adapter.send(request, **kwargs)
  File "/Users/leepand/anaconda2/lib/python2.7/site-packages/requests/adapters.py", line 487, in send
    raise ConnectionError(e, request=request)
ConnectionError: HTTPConnectionPool(host='localhost', port=9001): Max retries exceeded with url: /predict (Caused by NewConnectionError('<requests.packages.urllib3.connection.HTTPConnection object at 0x109660c50>: Failed to establish a new connection: [Errno 61] Connection refused',))
2018-05-18 09:22:35,842 - AIaas.router.AI_worker_client - ERROR - Predict has failed.. 
Traceback (most recent call last):
  File "/Users/leepand/Downloads/BigRLab_APIs/demoday_fs/web_lab/knn_as_a_service/AIaas/AIaas/router/AI_worker_client.py", line 118, in predict
    prediction_output.result = client.predict(prediction_input.data)
  File "/Users/leepand/Downloads/BigRLab_APIs/demoday_fs/web_lab/knn_as_a_service/AIaas/AIaas/router/common_client.py", line 247, in predict
    return self.post(self.__urls["predict"], json=data)
  File "/Users/leepand/Downloads/BigRLab_APIs/demoday_fs/web_lab/knn_as_a_service/AIaas/AIaas/router/common_client.py", line 106, in post
    r = requests.post(url=url, json=json, params=params, timeout=DD_TIMEOUT)
  File "/Users/leepand/anaconda2/lib/python2.7/site-packages/requests/api.py", line 110, in post
    return request('post', url, data=data, json=json, **kwargs)
  File "/Users/leepand/anaconda2/lib/python2.7/site-packages/requests/api.py", line 56, in request
    return session.request(method=method, url=url, **kwargs)
  File "/Users/leepand/anaconda2/lib/python2.7/site-packages/requests/sessions.py", line 475, in request
    resp = self.send(prep, **send_kwargs)
  File "/Users/leepand/anaconda2/lib/python2.7/site-packages/requests/sessions.py", line 596, in send
    r = adapter.send(request, **kwargs)
  File "/Users/leepand/anaconda2/lib/python2.7/site-packages/requests/adapters.py", line 487, in send
    raise ConnectionError(e, request=request)
ConnectionError: HTTPConnectionPool(host='localhost', port=9001): Max retries exceeded with url: /predict (Caused by NewConnectionError('<requests.packages.urllib3.connection.HTTPConnection object at 0x109660c50>: Failed to establish a new connection: [Errno 61] Connection refused',))
2018-05-18 09:22:35,851 - AIaas.router.AI_worker_client - ERROR - Predict has failed.. 
Traceback (most recent call last):
  File "/Users/leepand/Downloads/BigRLab_APIs/demoday_fs/web_lab/knn_as_a_service/AIaas/AIaas/router/AI_worker_client.py", line 118, in predict
    prediction_output.result = client.predict(prediction_input.data)
  File "/Users/leepand/Downloads/BigRLab_APIs/demoday_fs/web_lab/knn_as_a_service/AIaas/AIaas/router/common_client.py", line 247, in predict
    return self.post(self.__urls["predict"], json=data)
  File "/Users/leepand/Downloads/BigRLab_APIs/demoday_fs/web_lab/knn_as_a_service/AIaas/AIaas/router/common_client.py", line 106, in post
    r = requests.post(url=url, json=json, params=params, timeout=DD_TIMEOUT)
  File "/Users/leepand/anaconda2/lib/python2.7/site-packages/requests/api.py", line 110, in post
    return request('post', url, data=data, json=json, **kwargs)
  File "/Users/leepand/anaconda2/lib/python2.7/site-packages/requests/api.py", line 56, in request
    return session.request(method=method, url=url, **kwargs)
  File "/Users/leepand/anaconda2/lib/python2.7/site-packages/requests/sessions.py", line 475, in request
    resp = self.send(prep, **send_kwargs)
  File "/Users/leepand/anaconda2/lib/python2.7/site-packages/requests/sessions.py", line 596, in send
    r = adapter.send(request, **kwargs)
  File "/Users/leepand/anaconda2/lib/python2.7/site-packages/requests/adapters.py", line 487, in send
    raise ConnectionError(e, request=request)
ConnectionError: HTTPConnectionPool(host='localhost', port=9001): Max retries exceeded with url: /predict (Caused by NewConnectionError('<requests.packages.urllib3.connection.HTTPConnection object at 0x109660b50>: Failed to establish a new connection: [Errno 61] Connection refused',))
2018-05-18 09:22:35,854 - AIaas.router.AI_worker_client - ERROR - Predict has failed.. 
Traceback (most recent call last):
  File "/Users/leepand/Downloads/BigRLab_APIs/demoday_fs/web_lab/knn_as_a_service/AIaas/AIaas/router/AI_worker_client.py", line 118, in predict
    prediction_output.result = client.predict(prediction_input.data)
  File "/Users/leepand/Downloads/BigRLab_APIs/demoday_fs/web_lab/knn_as_a_service/AIaas/AIaas/router/common_client.py", line 247, in predict
    return self.post(self.__urls["predict"], json=data)
  File "/Users/leepand/Downloads/BigRLab_APIs/demoday_fs/web_lab/knn_as_a_service/AIaas/AIaas/router/common_client.py", line 106, in post
    r = requests.post(url=url, json=json, params=params, timeout=DD_TIMEOUT)
  File "/Users/leepand/anaconda2/lib/python2.7/site-packages/requests/api.py", line 110, in post
    return request('post', url, data=data, json=json, **kwargs)
  File "/Users/leepand/anaconda2/lib/python2.7/site-packages/requests/api.py", line 56, in request
    return session.request(method=method, url=url, **kwargs)
  File "/Users/leepand/anaconda2/lib/python2.7/site-packages/requests/sessions.py", line 475, in request
    resp = self.send(prep, **send_kwargs)
  File "/Users/leepand/anaconda2/lib/python2.7/site-packages/requests/sessions.py", line 596, in send
    r = adapter.send(request, **kwargs)
  File "/Users/leepand/anaconda2/lib/python2.7/site-packages/requests/adapters.py", line 487, in send
    raise ConnectionError(e, request=request)
ConnectionError: HTTPConnectionPool(host='localhost', port=9001): Max retries exceeded with url: /predict (Caused by NewConnectionError('<requests.packages.urllib3.connection.HTTPConnection object at 0x109660b50>: Failed to establish a new connection: [Errno 61] Connection refused',))
2018-05-18 10:34:53,161 - AIaas.router.AI_worker_client - ERROR - Predict has failed.. 
Traceback (most recent call last):
  File "/Users/leepand/anaconda2/lib/python2.7/site-packages/gunicorn/workers/sync.py", line 68, in run_for_one
    self.accept(listener)
  File "/Users/leepand/anaconda2/lib/python2.7/site-packages/gunicorn/workers/sync.py", line 27, in accept
    client, addr = listener.accept()
  File "/Users/leepand/anaconda2/lib/python2.7/socket.py", line 206, in accept
    sock, addr = self._sock.accept()
error: [Errno 35] Resource temporarily unavailable
2018-05-18 10:36:05,839 - AIaas.router.AI_worker_client - ERROR - Predict has failed.. 
Traceback (most recent call last):
  File "/Users/leepand/anaconda2/lib/python2.7/site-packages/gunicorn/workers/sync.py", line 68, in run_for_one
    self.accept(listener)
  File "/Users/leepand/anaconda2/lib/python2.7/site-packages/gunicorn/workers/sync.py", line 27, in accept
    client, addr = listener.accept()
  File "/Users/leepand/anaconda2/lib/python2.7/socket.py", line 206, in accept
    sock, addr = self._sock.accept()
error: [Errno 35] Resource temporarily unavailable
2018-05-18 10:36:26,056 - AIaas.router.AI_worker_client - ERROR - Predict has failed.. 
Traceback (most recent call last):
  File "/Users/leepand/anaconda2/lib/python2.7/site-packages/gunicorn/workers/sync.py", line 68, in run_for_one
    self.accept(listener)
  File "/Users/leepand/anaconda2/lib/python2.7/site-packages/gunicorn/workers/sync.py", line 27, in accept
    client, addr = listener.accept()
  File "/Users/leepand/anaconda2/lib/python2.7/socket.py", line 206, in accept
    sock, addr = self._sock.accept()
error: [Errno 35] Resource temporarily unavailable
2018-05-18 10:36:38,205 - AIaas.router.AI_worker_client - ERROR - Predict has failed.. 
Traceback (most recent call last):
  File "/Users/leepand/anaconda2/lib/python2.7/site-packages/gunicorn/workers/sync.py", line 68, in run_for_one
    self.accept(listener)
  File "/Users/leepand/anaconda2/lib/python2.7/site-packages/gunicorn/workers/sync.py", line 27, in accept
    client, addr = listener.accept()
  File "/Users/leepand/anaconda2/lib/python2.7/socket.py", line 206, in accept
    sock, addr = self._sock.accept()
error: [Errno 35] Resource temporarily unavailable
