2018-05-17 09:39:39,844 - router.router_app - INFO - Starting Router...
2018-05-17 09:43:36,698 - router.router_app - INFO - Starting Router...
2018-05-17 09:46:01,009 - router.router_app - INFO - Starting Router...
2018-05-17 10:00:37,169 - router.router_app - INFO - Starting Router...
2018-05-17 10:02:33,378 - router.router_app - INFO - Starting Router...
2018-05-17 10:04:13,450 - router.router_app - INFO - Starting Router...
2018-05-17 10:39:14,984 - router.router_app - INFO - Starting Router...
2018-05-17 10:45:00,896 - router.router_app - INFO - Starting Router...
2018-05-17 10:45:43,988 - router.router_app - INFO - Starting Router...
2018-05-17 10:49:14,909 - router.router_app - INFO - Starting Router...
2018-05-17 10:49:21,506 - router.router_app - INFO - Starting Router...
2018-05-17 10:50:45,230 - router.router_app - INFO - Starting Router...
2018-05-17 10:51:51,816 - router.router_app - INFO - Starting Router...
2018-05-17 10:52:49,842 - router.router_app - INFO - Starting Router...
2018-05-17 10:55:24,282 - router.router_app - INFO - Starting Router...
2018-05-17 10:59:09,920 - router.router_app - INFO - Starting Router...
2018-05-17 11:33:31,401 - router.router_app - INFO - Starting Router...
2018-05-17 11:35:42,435 - router.router_app - INFO - Starting Router...
2018-05-17 11:36:53,373 - router.router_app - INFO - Starting Router...
2018-05-17 12:26:30,088 - router.router_app - INFO - Starting Router...
2018-05-17 13:23:51,163 - router.router_app - INFO - Starting Router...
2018-05-17 15:44:45,144 - router.router_app - INFO - Starting Router...
2018-05-17 16:19:23,100 - router.router_app - INFO - Starting Router...
2018-05-17 16:20:14,870 - router.router_app - INFO - Starting Router...
2018-05-17 16:39:21,598 - router.router_app - INFO - Starting Router...
2018-05-17 18:00:12,757 - router.router_app - INFO - Starting Router...
2018-05-17 18:00:12,767 - AIaas.router.AI_worker_client - INFO - load balancer inited...
2018-05-17 18:00:12,768 - AIaas.router.AI_worker_client - INFO - AIWorkerClient Inited...
2018-05-17 18:00:12,768 - AIaas.router.predict - INFO - Predict Inited...
2018-05-17 18:31:42,403 - router.router_app - INFO - Starting Router...
2018-05-17 18:31:42,429 - AIaas.router.AI_worker_client - INFO - load balancer inited...
2018-05-17 18:31:42,430 - AIaas.router.AI_worker_client - INFO - AIWorkerClient Inited...
2018-05-17 18:31:42,431 - AIaas.router.predict - INFO - Predict Inited...
2018-05-17 18:59:45,812 - AIaas.router.AI_worker_client - INFO - Caffe predict has been called..
2018-05-17 19:00:29,396 - AIaas.router.AI_worker_client - INFO - Caffe predict has been called..
2018-05-17 19:26:29,389 - router.router_app - INFO - Starting Router...
2018-05-17 19:26:29,397 - AIaas.router.AI_worker_client - INFO - load balancer inited...
2018-05-17 19:26:29,397 - AIaas.router.AI_worker_client - INFO - AIWorkerClient Inited...
2018-05-17 19:26:29,398 - AIaas.router.predict - INFO - Predict Inited...
2018-05-17 19:39:17,558 - router.router_app - INFO - Starting Router...
2018-05-17 19:39:17,567 - AIaas.router.AI_worker_client - INFO - load balancer inited...
2018-05-17 19:39:17,568 - AIaas.router.AI_worker_client - INFO - AIWorkerClient Inited...
2018-05-17 19:39:17,569 - AIaas.router.predict - INFO - Predict Inited...
2018-05-17 19:45:32,408 - AIaas.router.AI_worker_client - INFO - Caffe predict has been called..
2018-05-17 19:47:46,064 - router.router_app - INFO - Starting Router...
2018-05-17 19:47:46,072 - AIaas.router.AI_worker_client - INFO - load balancer inited...
2018-05-17 19:47:46,073 - AIaas.router.AI_worker_client - INFO - AIWorkerClient Inited...
2018-05-17 19:47:46,073 - AIaas.router.predict - INFO - Predict Inited...
2018-05-17 19:48:47,484 - AIaas.router.AI_worker_client - INFO - Caffe predict has been called..
2018-05-17 19:55:10,013 - router.router_app - INFO - Starting Router...
2018-05-17 19:55:10,021 - AIaas.router.AI_worker_client - INFO - load balancer inited...
2018-05-17 19:55:10,022 - AIaas.router.AI_worker_client - INFO - AIWorkerClient Inited...
2018-05-17 19:55:10,022 - AIaas.router.predict - INFO - Predict Inited...
2018-05-17 19:56:29,206 - AIaas.router.AI_worker_client - INFO - Caffe predict has been called..
2018-05-17 20:08:02,427 - router.router_app - INFO - Starting Router...
2018-05-17 20:08:02,435 - AIaas.router.AI_worker_client - INFO - load balancer inited...
2018-05-17 20:08:02,436 - AIaas.router.AI_worker_client - INFO - AIWorkerClient Inited...
2018-05-17 20:08:02,436 - AIaas.router.predict - INFO - Predict Inited...
2018-05-17 20:08:42,278 - AIaas.router.AI_worker_client - INFO - Caffe predict has been called..
2018-05-17 20:08:42,298 - requests.packages.urllib3.connectionpool - INFO - Starting new HTTP connection (1): localhost
2018-05-17 20:08:42,308 - AIaas.router.AI_worker_client - ERROR - Predict has failed.. 
Traceback (most recent call last):
  File "/Users/leepand/Downloads/BigRLab_APIs/demoday_fs/web_lab/knn_as_a_service/AIaas/AIaas/router/AI_worker_client.py", line 101, in predict
    po = client.predict(prediction_input.data)
  File "/Users/leepand/Downloads/BigRLab_APIs/demoday_fs/web_lab/knn_as_a_service/AIaas/AIaas/router/common_client.py", line 115, in wrapped
    raise FireflyError('Firefly functions only accept named arguments')
FireflyError: Firefly functions only accept named arguments
2018-05-17 20:08:50,924 - router.router_app - INFO - Starting Router...
2018-05-17 20:08:50,932 - AIaas.router.AI_worker_client - INFO - load balancer inited...
2018-05-17 20:08:50,932 - AIaas.router.AI_worker_client - INFO - AIWorkerClient Inited...
2018-05-17 20:08:50,933 - AIaas.router.predict - INFO - Predict Inited...
2018-05-17 20:16:14,184 - router.router_app - INFO - Starting Router...
2018-05-17 20:16:14,192 - AIaas.router.AI_worker_client - INFO - load balancer inited...
2018-05-17 20:16:14,193 - AIaas.router.AI_worker_client - INFO - AIWorkerClient Inited...
2018-05-17 20:16:14,194 - AIaas.router.predict - INFO - Predict Inited...
2018-05-17 20:16:33,019 - AIaas.router.AI_worker_client - INFO - Caffe predict has been called..
2018-05-17 20:16:33,021 - AIaas.router.AI_worker_client - ERROR - Predict has failed.. 
Traceback (most recent call last):
  File "/Users/leepand/Downloads/BigRLab_APIs/demoday_fs/web_lab/knn_as_a_service/AIaas/AIaas/router/AI_worker_client.py", line 110, in predict
    po=prediction_output()
TypeError: __init__() takes exactly 3 arguments (1 given)
2018-05-17 20:17:52,460 - router.router_app - INFO - Starting Router...
2018-05-17 20:17:52,468 - AIaas.router.AI_worker_client - INFO - load balancer inited...
2018-05-17 20:17:52,469 - AIaas.router.AI_worker_client - INFO - AIWorkerClient Inited...
2018-05-17 20:17:52,469 - AIaas.router.predict - INFO - Predict Inited...
2018-05-17 20:18:01,718 - AIaas.router.AI_worker_client - INFO - Caffe predict has been called..
2018-05-17 20:18:01,720 - AIaas.router.AI_worker_client - ERROR - Predict has failed.. 
Traceback (most recent call last):
  File "/Users/leepand/Downloads/BigRLab_APIs/demoday_fs/web_lab/knn_as_a_service/AIaas/AIaas/router/AI_worker_client.py", line 110, in predict
    po=prediction_output()
TypeError: __init__() takes exactly 3 arguments (1 given)
2018-05-17 20:20:07,894 - router.router_app - INFO - Starting Router...
2018-05-17 20:20:07,902 - AIaas.router.AI_worker_client - INFO - load balancer inited...
2018-05-17 20:20:07,903 - AIaas.router.AI_worker_client - INFO - AIWorkerClient Inited...
2018-05-17 20:20:07,903 - AIaas.router.predict - INFO - Predict Inited...
2018-05-17 20:20:14,682 - AIaas.router.AI_worker_client - INFO - Caffe predict has been called..
2018-05-17 20:20:14,700 - requests.packages.urllib3.connectionpool - INFO - Starting new HTTP connection (1): localhost
2018-05-17 20:20:14,726 - AIaas.router.AI_worker_client - ERROR - Predict has failed.. 
Traceback (most recent call last):
  File "/Users/leepand/Downloads/BigRLab_APIs/demoday_fs/web_lab/knn_as_a_service/AIaas/AIaas/router/AI_worker_client.py", line 112, in predict
    prediction_output.result = client.predict(prediction_input.data)
  File "/Users/leepand/Downloads/BigRLab_APIs/demoday_fs/web_lab/knn_as_a_service/AIaas/AIaas/router/common_client.py", line 115, in wrapped
    raise FireflyError('Firefly functions only accept named arguments')
FireflyError: Firefly functions only accept named arguments
2018-05-17 20:20:14,729 - AIaas.router.AI_worker_client - ERROR - Predict has failed.. 
Traceback (most recent call last):
  File "/Users/leepand/Downloads/BigRLab_APIs/demoday_fs/web_lab/knn_as_a_service/AIaas/AIaas/router/AI_worker_client.py", line 112, in predict
    prediction_output.result = client.predict(prediction_input.data)
  File "/Users/leepand/Downloads/BigRLab_APIs/demoday_fs/web_lab/knn_as_a_service/AIaas/AIaas/router/common_client.py", line 115, in wrapped
    raise FireflyError('Firefly functions only accept named arguments')
FireflyError: Firefly functions only accept named arguments
2018-05-17 20:20:14,732 - AIaas.router.AI_worker_client - ERROR - Predict has failed.. 
Traceback (most recent call last):
  File "/Users/leepand/Downloads/BigRLab_APIs/demoday_fs/web_lab/knn_as_a_service/AIaas/AIaas/router/AI_worker_client.py", line 112, in predict
    prediction_output.result = client.predict(prediction_input.data)
  File "/Users/leepand/Downloads/BigRLab_APIs/demoday_fs/web_lab/knn_as_a_service/AIaas/AIaas/router/common_client.py", line 115, in wrapped
    raise FireflyError('Firefly functions only accept named arguments')
FireflyError: Firefly functions only accept named arguments
2018-05-17 20:20:14,734 - AIaas.router.AI_worker_client - ERROR - Predict has failed.. 
Traceback (most recent call last):
  File "/Users/leepand/Downloads/BigRLab_APIs/demoday_fs/web_lab/knn_as_a_service/AIaas/AIaas/router/AI_worker_client.py", line 112, in predict
    prediction_output.result = client.predict(prediction_input.data)
  File "/Users/leepand/Downloads/BigRLab_APIs/demoday_fs/web_lab/knn_as_a_service/AIaas/AIaas/router/common_client.py", line 115, in wrapped
    raise FireflyError('Firefly functions only accept named arguments')
FireflyError: Firefly functions only accept named arguments
2018-05-17 20:20:14,736 - AIaas.router.AI_worker_client - ERROR - Predict has failed.. 
Traceback (most recent call last):
  File "/Users/leepand/Downloads/BigRLab_APIs/demoday_fs/web_lab/knn_as_a_service/AIaas/AIaas/router/AI_worker_client.py", line 112, in predict
    prediction_output.result = client.predict(prediction_input.data)
  File "/Users/leepand/Downloads/BigRLab_APIs/demoday_fs/web_lab/knn_as_a_service/AIaas/AIaas/router/common_client.py", line 115, in wrapped
    raise FireflyError('Firefly functions only accept named arguments')
FireflyError: Firefly functions only accept named arguments
2018-05-17 20:20:14,738 - AIaas.router.AI_worker_client - ERROR - Predict has failed.. 
Traceback (most recent call last):
  File "/Users/leepand/Downloads/BigRLab_APIs/demoday_fs/web_lab/knn_as_a_service/AIaas/AIaas/router/AI_worker_client.py", line 112, in predict
    prediction_output.result = client.predict(prediction_input.data)
  File "/Users/leepand/Downloads/BigRLab_APIs/demoday_fs/web_lab/knn_as_a_service/AIaas/AIaas/router/common_client.py", line 115, in wrapped
    raise FireflyError('Firefly functions only accept named arguments')
FireflyError: Firefly functions only accept named arguments
2018-05-17 20:20:32,188 - AIaas.router.AI_worker_client - INFO - Caffe predict has been called..
2018-05-17 20:20:32,189 - AIaas.router.AI_worker_client - ERROR - Predict has failed.. 
Traceback (most recent call last):
  File "/Users/leepand/Downloads/BigRLab_APIs/demoday_fs/web_lab/knn_as_a_service/AIaas/AIaas/router/AI_worker_client.py", line 112, in predict
    prediction_output.result = client.predict(prediction_input.data)
  File "/Users/leepand/Downloads/BigRLab_APIs/demoday_fs/web_lab/knn_as_a_service/AIaas/AIaas/router/common_client.py", line 115, in wrapped
    raise FireflyError('Firefly functions only accept named arguments')
FireflyError: Firefly functions only accept named arguments
2018-05-17 20:20:32,191 - AIaas.router.AI_worker_client - ERROR - Predict has failed.. 
Traceback (most recent call last):
  File "/Users/leepand/Downloads/BigRLab_APIs/demoday_fs/web_lab/knn_as_a_service/AIaas/AIaas/router/AI_worker_client.py", line 112, in predict
    prediction_output.result = client.predict(prediction_input.data)
  File "/Users/leepand/Downloads/BigRLab_APIs/demoday_fs/web_lab/knn_as_a_service/AIaas/AIaas/router/common_client.py", line 115, in wrapped
    raise FireflyError('Firefly functions only accept named arguments')
FireflyError: Firefly functions only accept named arguments
2018-05-17 20:20:32,192 - AIaas.router.AI_worker_client - ERROR - Predict has failed.. 
Traceback (most recent call last):
  File "/Users/leepand/Downloads/BigRLab_APIs/demoday_fs/web_lab/knn_as_a_service/AIaas/AIaas/router/AI_worker_client.py", line 112, in predict
    prediction_output.result = client.predict(prediction_input.data)
  File "/Users/leepand/Downloads/BigRLab_APIs/demoday_fs/web_lab/knn_as_a_service/AIaas/AIaas/router/common_client.py", line 115, in wrapped
    raise FireflyError('Firefly functions only accept named arguments')
FireflyError: Firefly functions only accept named arguments
2018-05-17 20:20:32,193 - AIaas.router.AI_worker_client - ERROR - Predict has failed.. 
Traceback (most recent call last):
  File "/Users/leepand/Downloads/BigRLab_APIs/demoday_fs/web_lab/knn_as_a_service/AIaas/AIaas/router/AI_worker_client.py", line 112, in predict
    prediction_output.result = client.predict(prediction_input.data)
  File "/Users/leepand/Downloads/BigRLab_APIs/demoday_fs/web_lab/knn_as_a_service/AIaas/AIaas/router/common_client.py", line 115, in wrapped
    raise FireflyError('Firefly functions only accept named arguments')
FireflyError: Firefly functions only accept named arguments
2018-05-17 20:20:32,195 - AIaas.router.AI_worker_client - ERROR - Predict has failed.. 
Traceback (most recent call last):
  File "/Users/leepand/Downloads/BigRLab_APIs/demoday_fs/web_lab/knn_as_a_service/AIaas/AIaas/router/AI_worker_client.py", line 112, in predict
    prediction_output.result = client.predict(prediction_input.data)
  File "/Users/leepand/Downloads/BigRLab_APIs/demoday_fs/web_lab/knn_as_a_service/AIaas/AIaas/router/common_client.py", line 115, in wrapped
    raise FireflyError('Firefly functions only accept named arguments')
FireflyError: Firefly functions only accept named arguments
2018-05-17 20:20:32,196 - AIaas.router.AI_worker_client - ERROR - Predict has failed.. 
Traceback (most recent call last):
  File "/Users/leepand/Downloads/BigRLab_APIs/demoday_fs/web_lab/knn_as_a_service/AIaas/AIaas/router/AI_worker_client.py", line 112, in predict
    prediction_output.result = client.predict(prediction_input.data)
  File "/Users/leepand/Downloads/BigRLab_APIs/demoday_fs/web_lab/knn_as_a_service/AIaas/AIaas/router/common_client.py", line 115, in wrapped
    raise FireflyError('Firefly functions only accept named arguments')
FireflyError: Firefly functions only accept named arguments
2018-05-17 20:21:03,810 - AIaas.router.AI_worker_client - INFO - Caffe predict has been called..
2018-05-17 20:21:03,812 - AIaas.router.AI_worker_client - ERROR - Predict has failed.. 
Traceback (most recent call last):
  File "/Users/leepand/Downloads/BigRLab_APIs/demoday_fs/web_lab/knn_as_a_service/AIaas/AIaas/router/AI_worker_client.py", line 112, in predict
    prediction_output.result = client.predict(prediction_input.data)
  File "/Users/leepand/Downloads/BigRLab_APIs/demoday_fs/web_lab/knn_as_a_service/AIaas/AIaas/router/common_client.py", line 115, in wrapped
    raise FireflyError('Firefly functions only accept named arguments')
FireflyError: Firefly functions only accept named arguments
2018-05-17 20:21:03,814 - AIaas.router.AI_worker_client - ERROR - Predict has failed.. 
Traceback (most recent call last):
  File "/Users/leepand/Downloads/BigRLab_APIs/demoday_fs/web_lab/knn_as_a_service/AIaas/AIaas/router/AI_worker_client.py", line 112, in predict
    prediction_output.result = client.predict(prediction_input.data)
  File "/Users/leepand/Downloads/BigRLab_APIs/demoday_fs/web_lab/knn_as_a_service/AIaas/AIaas/router/common_client.py", line 115, in wrapped
    raise FireflyError('Firefly functions only accept named arguments')
FireflyError: Firefly functions only accept named arguments
2018-05-17 20:21:03,815 - AIaas.router.AI_worker_client - ERROR - Predict has failed.. 
Traceback (most recent call last):
  File "/Users/leepand/Downloads/BigRLab_APIs/demoday_fs/web_lab/knn_as_a_service/AIaas/AIaas/router/AI_worker_client.py", line 112, in predict
    prediction_output.result = client.predict(prediction_input.data)
  File "/Users/leepand/Downloads/BigRLab_APIs/demoday_fs/web_lab/knn_as_a_service/AIaas/AIaas/router/common_client.py", line 115, in wrapped
    raise FireflyError('Firefly functions only accept named arguments')
FireflyError: Firefly functions only accept named arguments
2018-05-17 20:21:03,817 - AIaas.router.AI_worker_client - ERROR - Predict has failed.. 
Traceback (most recent call last):
  File "/Users/leepand/Downloads/BigRLab_APIs/demoday_fs/web_lab/knn_as_a_service/AIaas/AIaas/router/AI_worker_client.py", line 112, in predict
    prediction_output.result = client.predict(prediction_input.data)
  File "/Users/leepand/Downloads/BigRLab_APIs/demoday_fs/web_lab/knn_as_a_service/AIaas/AIaas/router/common_client.py", line 115, in wrapped
    raise FireflyError('Firefly functions only accept named arguments')
FireflyError: Firefly functions only accept named arguments
2018-05-17 20:21:03,818 - AIaas.router.AI_worker_client - ERROR - Predict has failed.. 
Traceback (most recent call last):
  File "/Users/leepand/Downloads/BigRLab_APIs/demoday_fs/web_lab/knn_as_a_service/AIaas/AIaas/router/AI_worker_client.py", line 112, in predict
    prediction_output.result = client.predict(prediction_input.data)
  File "/Users/leepand/Downloads/BigRLab_APIs/demoday_fs/web_lab/knn_as_a_service/AIaas/AIaas/router/common_client.py", line 115, in wrapped
    raise FireflyError('Firefly functions only accept named arguments')
FireflyError: Firefly functions only accept named arguments
2018-05-17 20:21:03,820 - AIaas.router.AI_worker_client - ERROR - Predict has failed.. 
Traceback (most recent call last):
  File "/Users/leepand/Downloads/BigRLab_APIs/demoday_fs/web_lab/knn_as_a_service/AIaas/AIaas/router/AI_worker_client.py", line 112, in predict
    prediction_output.result = client.predict(prediction_input.data)
  File "/Users/leepand/Downloads/BigRLab_APIs/demoday_fs/web_lab/knn_as_a_service/AIaas/AIaas/router/common_client.py", line 115, in wrapped
    raise FireflyError('Firefly functions only accept named arguments')
FireflyError: Firefly functions only accept named arguments
2018-05-17 20:21:38,163 - router.router_app - INFO - Starting Router...
2018-05-17 20:21:38,171 - AIaas.router.AI_worker_client - INFO - load balancer inited...
2018-05-17 20:21:38,171 - AIaas.router.AI_worker_client - INFO - AIWorkerClient Inited...
2018-05-17 20:21:38,172 - AIaas.router.predict - INFO - Predict Inited...
2018-05-17 20:21:47,041 - AIaas.router.AI_worker_client - INFO - Caffe predict has been called..
2018-05-17 20:22:40,111 - AIaas.router.AI_worker_client - INFO - Caffe predict has been called..
2018-05-17 20:22:40,126 - requests.packages.urllib3.connectionpool - INFO - Starting new HTTP connection (1): localhost
2018-05-17 20:22:40,135 - AIaas.router.AI_worker_client - ERROR - Predict has failed.. 
Traceback (most recent call last):
  File "/Users/leepand/Downloads/BigRLab_APIs/demoday_fs/web_lab/knn_as_a_service/AIaas/AIaas/router/AI_worker_client.py", line 112, in predict
    prediction_output.result = client.predict(prediction_input.data)
  File "/Users/leepand/Downloads/BigRLab_APIs/demoday_fs/web_lab/knn_as_a_service/AIaas/AIaas/router/common_client.py", line 115, in wrapped
    raise FireflyError('Firefly functions only accept named arguments')
FireflyError: Firefly functions only accept named arguments
2018-05-17 20:22:40,136 - AIaas.router.AI_worker_client - ERROR - Predict has failed.. 
Traceback (most recent call last):
  File "/Users/leepand/Downloads/BigRLab_APIs/demoday_fs/web_lab/knn_as_a_service/AIaas/AIaas/router/AI_worker_client.py", line 112, in predict
    prediction_output.result = client.predict(prediction_input.data)
  File "/Users/leepand/Downloads/BigRLab_APIs/demoday_fs/web_lab/knn_as_a_service/AIaas/AIaas/router/common_client.py", line 115, in wrapped
    raise FireflyError('Firefly functions only accept named arguments')
FireflyError: Firefly functions only accept named arguments
2018-05-17 20:22:40,138 - AIaas.router.AI_worker_client - ERROR - Predict has failed.. 
Traceback (most recent call last):
  File "/Users/leepand/Downloads/BigRLab_APIs/demoday_fs/web_lab/knn_as_a_service/AIaas/AIaas/router/AI_worker_client.py", line 112, in predict
    prediction_output.result = client.predict(prediction_input.data)
  File "/Users/leepand/Downloads/BigRLab_APIs/demoday_fs/web_lab/knn_as_a_service/AIaas/AIaas/router/common_client.py", line 115, in wrapped
    raise FireflyError('Firefly functions only accept named arguments')
FireflyError: Firefly functions only accept named arguments
2018-05-17 20:22:40,140 - AIaas.router.AI_worker_client - ERROR - Predict has failed.. 
Traceback (most recent call last):
  File "/Users/leepand/Downloads/BigRLab_APIs/demoday_fs/web_lab/knn_as_a_service/AIaas/AIaas/router/AI_worker_client.py", line 112, in predict
    prediction_output.result = client.predict(prediction_input.data)
  File "/Users/leepand/Downloads/BigRLab_APIs/demoday_fs/web_lab/knn_as_a_service/AIaas/AIaas/router/common_client.py", line 115, in wrapped
    raise FireflyError('Firefly functions only accept named arguments')
FireflyError: Firefly functions only accept named arguments
2018-05-17 20:22:40,142 - AIaas.router.AI_worker_client - ERROR - Predict has failed.. 
Traceback (most recent call last):
  File "/Users/leepand/Downloads/BigRLab_APIs/demoday_fs/web_lab/knn_as_a_service/AIaas/AIaas/router/AI_worker_client.py", line 112, in predict
    prediction_output.result = client.predict(prediction_input.data)
  File "/Users/leepand/Downloads/BigRLab_APIs/demoday_fs/web_lab/knn_as_a_service/AIaas/AIaas/router/common_client.py", line 115, in wrapped
    raise FireflyError('Firefly functions only accept named arguments')
FireflyError: Firefly functions only accept named arguments
2018-05-17 20:22:40,145 - AIaas.router.AI_worker_client - ERROR - Predict has failed.. 
Traceback (most recent call last):
  File "/Users/leepand/Downloads/BigRLab_APIs/demoday_fs/web_lab/knn_as_a_service/AIaas/AIaas/router/AI_worker_client.py", line 112, in predict
    prediction_output.result = client.predict(prediction_input.data)
  File "/Users/leepand/Downloads/BigRLab_APIs/demoday_fs/web_lab/knn_as_a_service/AIaas/AIaas/router/common_client.py", line 115, in wrapped
    raise FireflyError('Firefly functions only accept named arguments')
FireflyError: Firefly functions only accept named arguments
2018-05-17 20:26:06,402 - AIaas.router.AI_worker_client - INFO - Caffe predict has been called..
2018-05-17 20:26:06,404 - AIaas.router.AI_worker_client - ERROR - Predict has failed.. 
Traceback (most recent call last):
  File "/Users/leepand/Downloads/BigRLab_APIs/demoday_fs/web_lab/knn_as_a_service/AIaas/AIaas/router/AI_worker_client.py", line 112, in predict
    prediction_output.result = client.predict(prediction_input.data)
  File "/Users/leepand/Downloads/BigRLab_APIs/demoday_fs/web_lab/knn_as_a_service/AIaas/AIaas/router/common_client.py", line 115, in wrapped
    raise FireflyError('Firefly functions only accept named arguments')
FireflyError: Firefly functions only accept named arguments
2018-05-17 20:26:06,406 - AIaas.router.AI_worker_client - ERROR - Predict has failed.. 
Traceback (most recent call last):
  File "/Users/leepand/Downloads/BigRLab_APIs/demoday_fs/web_lab/knn_as_a_service/AIaas/AIaas/router/AI_worker_client.py", line 112, in predict
    prediction_output.result = client.predict(prediction_input.data)
  File "/Users/leepand/Downloads/BigRLab_APIs/demoday_fs/web_lab/knn_as_a_service/AIaas/AIaas/router/common_client.py", line 115, in wrapped
    raise FireflyError('Firefly functions only accept named arguments')
FireflyError: Firefly functions only accept named arguments
2018-05-17 20:26:06,407 - AIaas.router.AI_worker_client - ERROR - Predict has failed.. 
Traceback (most recent call last):
  File "/Users/leepand/Downloads/BigRLab_APIs/demoday_fs/web_lab/knn_as_a_service/AIaas/AIaas/router/AI_worker_client.py", line 112, in predict
    prediction_output.result = client.predict(prediction_input.data)
  File "/Users/leepand/Downloads/BigRLab_APIs/demoday_fs/web_lab/knn_as_a_service/AIaas/AIaas/router/common_client.py", line 115, in wrapped
    raise FireflyError('Firefly functions only accept named arguments')
FireflyError: Firefly functions only accept named arguments
2018-05-17 20:26:06,408 - AIaas.router.AI_worker_client - ERROR - Predict has failed.. 
Traceback (most recent call last):
  File "/Users/leepand/Downloads/BigRLab_APIs/demoday_fs/web_lab/knn_as_a_service/AIaas/AIaas/router/AI_worker_client.py", line 112, in predict
    prediction_output.result = client.predict(prediction_input.data)
  File "/Users/leepand/Downloads/BigRLab_APIs/demoday_fs/web_lab/knn_as_a_service/AIaas/AIaas/router/common_client.py", line 115, in wrapped
    raise FireflyError('Firefly functions only accept named arguments')
FireflyError: Firefly functions only accept named arguments
2018-05-17 20:26:06,410 - AIaas.router.AI_worker_client - ERROR - Predict has failed.. 
Traceback (most recent call last):
  File "/Users/leepand/Downloads/BigRLab_APIs/demoday_fs/web_lab/knn_as_a_service/AIaas/AIaas/router/AI_worker_client.py", line 112, in predict
    prediction_output.result = client.predict(prediction_input.data)
  File "/Users/leepand/Downloads/BigRLab_APIs/demoday_fs/web_lab/knn_as_a_service/AIaas/AIaas/router/common_client.py", line 115, in wrapped
    raise FireflyError('Firefly functions only accept named arguments')
FireflyError: Firefly functions only accept named arguments
2018-05-17 20:26:06,411 - AIaas.router.AI_worker_client - ERROR - Predict has failed.. 
Traceback (most recent call last):
  File "/Users/leepand/Downloads/BigRLab_APIs/demoday_fs/web_lab/knn_as_a_service/AIaas/AIaas/router/AI_worker_client.py", line 112, in predict
    prediction_output.result = client.predict(prediction_input.data)
  File "/Users/leepand/Downloads/BigRLab_APIs/demoday_fs/web_lab/knn_as_a_service/AIaas/AIaas/router/common_client.py", line 115, in wrapped
    raise FireflyError('Firefly functions only accept named arguments')
FireflyError: Firefly functions only accept named arguments
2018-05-17 20:38:31,803 - router.router_app - INFO - Starting Router...
2018-05-17 20:38:31,811 - AIaas.router.AI_worker_client - INFO - load balancer inited...
2018-05-17 20:38:31,812 - AIaas.router.AI_worker_client - INFO - AIWorkerClient Inited...
2018-05-17 20:38:31,812 - AIaas.router.predict - INFO - Predict Inited...
2018-05-17 20:38:44,454 - AIaas.router.AI_worker_client - INFO - Caffe predict has been called..
2018-05-17 20:38:44,468 - requests.packages.urllib3.connectionpool - INFO - Starting new HTTP connection (1): localhost
2018-05-17 20:38:44,477 - AIaas.router.AI_worker_client - ERROR - Predict has failed.. 
Traceback (most recent call last):
  File "/Users/leepand/Downloads/BigRLab_APIs/demoday_fs/web_lab/knn_as_a_service/AIaas/AIaas/router/AI_worker_client.py", line 113, in predict
    prediction_output.result = client.predict(prediction_input.data)
  File "/Users/leepand/Downloads/BigRLab_APIs/demoday_fs/web_lab/knn_as_a_service/AIaas/AIaas/router/common_client.py", line 115, in wrapped
    raise FireflyError('Firefly functions only accept named arguments')
FireflyError: Firefly functions only accept named arguments
2018-05-17 20:38:44,479 - AIaas.router.AI_worker_client - ERROR - Predict has failed.. 
Traceback (most recent call last):
  File "/Users/leepand/Downloads/BigRLab_APIs/demoday_fs/web_lab/knn_as_a_service/AIaas/AIaas/router/AI_worker_client.py", line 113, in predict
    prediction_output.result = client.predict(prediction_input.data)
  File "/Users/leepand/Downloads/BigRLab_APIs/demoday_fs/web_lab/knn_as_a_service/AIaas/AIaas/router/common_client.py", line 115, in wrapped
    raise FireflyError('Firefly functions only accept named arguments')
FireflyError: Firefly functions only accept named arguments
2018-05-17 20:38:44,481 - AIaas.router.AI_worker_client - ERROR - Predict has failed.. 
Traceback (most recent call last):
  File "/Users/leepand/Downloads/BigRLab_APIs/demoday_fs/web_lab/knn_as_a_service/AIaas/AIaas/router/AI_worker_client.py", line 113, in predict
    prediction_output.result = client.predict(prediction_input.data)
  File "/Users/leepand/Downloads/BigRLab_APIs/demoday_fs/web_lab/knn_as_a_service/AIaas/AIaas/router/common_client.py", line 115, in wrapped
    raise FireflyError('Firefly functions only accept named arguments')
FireflyError: Firefly functions only accept named arguments
2018-05-17 20:38:44,482 - AIaas.router.AI_worker_client - ERROR - Predict has failed.. 
Traceback (most recent call last):
  File "/Users/leepand/Downloads/BigRLab_APIs/demoday_fs/web_lab/knn_as_a_service/AIaas/AIaas/router/AI_worker_client.py", line 113, in predict
    prediction_output.result = client.predict(prediction_input.data)
  File "/Users/leepand/Downloads/BigRLab_APIs/demoday_fs/web_lab/knn_as_a_service/AIaas/AIaas/router/common_client.py", line 115, in wrapped
    raise FireflyError('Firefly functions only accept named arguments')
FireflyError: Firefly functions only accept named arguments
2018-05-17 20:38:44,484 - AIaas.router.AI_worker_client - ERROR - Predict has failed.. 
Traceback (most recent call last):
  File "/Users/leepand/Downloads/BigRLab_APIs/demoday_fs/web_lab/knn_as_a_service/AIaas/AIaas/router/AI_worker_client.py", line 113, in predict
    prediction_output.result = client.predict(prediction_input.data)
  File "/Users/leepand/Downloads/BigRLab_APIs/demoday_fs/web_lab/knn_as_a_service/AIaas/AIaas/router/common_client.py", line 115, in wrapped
    raise FireflyError('Firefly functions only accept named arguments')
FireflyError: Firefly functions only accept named arguments
2018-05-17 20:38:44,486 - AIaas.router.AI_worker_client - ERROR - Predict has failed.. 
Traceback (most recent call last):
  File "/Users/leepand/Downloads/BigRLab_APIs/demoday_fs/web_lab/knn_as_a_service/AIaas/AIaas/router/AI_worker_client.py", line 113, in predict
    prediction_output.result = client.predict(prediction_input.data)
  File "/Users/leepand/Downloads/BigRLab_APIs/demoday_fs/web_lab/knn_as_a_service/AIaas/AIaas/router/common_client.py", line 115, in wrapped
    raise FireflyError('Firefly functions only accept named arguments')
FireflyError: Firefly functions only accept named arguments
2018-05-17 20:39:01,682 - AIaas.router.AI_worker_client - INFO - Caffe predict has been called..
2018-05-17 20:39:01,684 - AIaas.router.AI_worker_client - ERROR - Predict has failed.. 
Traceback (most recent call last):
  File "/Users/leepand/Downloads/BigRLab_APIs/demoday_fs/web_lab/knn_as_a_service/AIaas/AIaas/router/AI_worker_client.py", line 113, in predict
    prediction_output.result = client.predict(prediction_input.data)
  File "/Users/leepand/Downloads/BigRLab_APIs/demoday_fs/web_lab/knn_as_a_service/AIaas/AIaas/router/common_client.py", line 115, in wrapped
    raise FireflyError('Firefly functions only accept named arguments')
FireflyError: Firefly functions only accept named arguments
2018-05-17 20:39:01,685 - AIaas.router.AI_worker_client - ERROR - Predict has failed.. 
Traceback (most recent call last):
  File "/Users/leepand/Downloads/BigRLab_APIs/demoday_fs/web_lab/knn_as_a_service/AIaas/AIaas/router/AI_worker_client.py", line 113, in predict
    prediction_output.result = client.predict(prediction_input.data)
  File "/Users/leepand/Downloads/BigRLab_APIs/demoday_fs/web_lab/knn_as_a_service/AIaas/AIaas/router/common_client.py", line 115, in wrapped
    raise FireflyError('Firefly functions only accept named arguments')
FireflyError: Firefly functions only accept named arguments
2018-05-17 20:39:01,687 - AIaas.router.AI_worker_client - ERROR - Predict has failed.. 
Traceback (most recent call last):
  File "/Users/leepand/Downloads/BigRLab_APIs/demoday_fs/web_lab/knn_as_a_service/AIaas/AIaas/router/AI_worker_client.py", line 113, in predict
    prediction_output.result = client.predict(prediction_input.data)
  File "/Users/leepand/Downloads/BigRLab_APIs/demoday_fs/web_lab/knn_as_a_service/AIaas/AIaas/router/common_client.py", line 115, in wrapped
    raise FireflyError('Firefly functions only accept named arguments')
FireflyError: Firefly functions only accept named arguments
2018-05-17 20:39:01,688 - AIaas.router.AI_worker_client - ERROR - Predict has failed.. 
Traceback (most recent call last):
  File "/Users/leepand/Downloads/BigRLab_APIs/demoday_fs/web_lab/knn_as_a_service/AIaas/AIaas/router/AI_worker_client.py", line 113, in predict
    prediction_output.result = client.predict(prediction_input.data)
  File "/Users/leepand/Downloads/BigRLab_APIs/demoday_fs/web_lab/knn_as_a_service/AIaas/AIaas/router/common_client.py", line 115, in wrapped
    raise FireflyError('Firefly functions only accept named arguments')
FireflyError: Firefly functions only accept named arguments
2018-05-17 20:39:01,690 - AIaas.router.AI_worker_client - ERROR - Predict has failed.. 
Traceback (most recent call last):
  File "/Users/leepand/Downloads/BigRLab_APIs/demoday_fs/web_lab/knn_as_a_service/AIaas/AIaas/router/AI_worker_client.py", line 113, in predict
    prediction_output.result = client.predict(prediction_input.data)
  File "/Users/leepand/Downloads/BigRLab_APIs/demoday_fs/web_lab/knn_as_a_service/AIaas/AIaas/router/common_client.py", line 115, in wrapped
    raise FireflyError('Firefly functions only accept named arguments')
FireflyError: Firefly functions only accept named arguments
2018-05-17 20:39:01,691 - AIaas.router.AI_worker_client - ERROR - Predict has failed.. 
Traceback (most recent call last):
  File "/Users/leepand/Downloads/BigRLab_APIs/demoday_fs/web_lab/knn_as_a_service/AIaas/AIaas/router/AI_worker_client.py", line 113, in predict
    prediction_output.result = client.predict(prediction_input.data)
  File "/Users/leepand/Downloads/BigRLab_APIs/demoday_fs/web_lab/knn_as_a_service/AIaas/AIaas/router/common_client.py", line 115, in wrapped
    raise FireflyError('Firefly functions only accept named arguments')
FireflyError: Firefly functions only accept named arguments
2018-05-17 20:39:13,115 - router.router_app - INFO - Starting Router...
2018-05-17 20:39:13,123 - AIaas.router.AI_worker_client - INFO - load balancer inited...
2018-05-17 20:39:13,124 - AIaas.router.AI_worker_client - INFO - AIWorkerClient Inited...
2018-05-17 20:39:13,125 - AIaas.router.predict - INFO - Predict Inited...
2018-05-17 20:39:21,200 - AIaas.router.AI_worker_client - INFO - Caffe predict has been called..
2018-05-17 20:40:53,692 - router.router_app - INFO - Starting Router...
2018-05-17 20:40:53,701 - AIaas.router.AI_worker_client - INFO - load balancer inited...
2018-05-17 20:40:53,701 - AIaas.router.AI_worker_client - INFO - AIWorkerClient Inited...
2018-05-17 20:40:53,702 - AIaas.router.predict - INFO - Predict Inited...
2018-05-17 20:41:00,413 - AIaas.router.AI_worker_client - INFO - Caffe predict has been called..
2018-05-17 20:56:32,648 - router.router_app - INFO - Starting Router...
2018-05-17 20:56:32,657 - AIaas.router.AI_worker_client - INFO - load balancer inited...
2018-05-17 20:56:32,658 - AIaas.router.AI_worker_client - INFO - AIWorkerClient Inited...
2018-05-17 20:56:32,659 - AIaas.router.predict - INFO - Predict Inited...
2018-05-17 20:57:05,580 - AIaas.router.AI_worker_client - INFO - Caffe predict has been called..
2018-05-17 21:07:59,323 - router.router_app - INFO - Starting Router...
2018-05-17 21:07:59,332 - AIaas.router.AI_worker_client - INFO - load balancer inited...
2018-05-17 21:07:59,333 - AIaas.router.AI_worker_client - INFO - AIWorkerClient Inited...
2018-05-17 21:07:59,333 - AIaas.router.predict - INFO - Predict Inited...
2018-05-17 21:08:14,266 - AIaas.router.AI_worker_client - INFO - Caffe predict has been called..
2018-05-17 21:38:15,254 - router.router_app - INFO - Starting Router...
2018-05-17 21:38:15,265 - AIaas.router.AI_worker_client - INFO - load balancer inited...
2018-05-17 21:38:15,266 - AIaas.router.AI_worker_client - INFO - AIWorkerClient Inited...
2018-05-17 21:38:15,266 - AIaas.router.predict - INFO - Predict Inited...
2018-05-17 21:38:17,757 - AIaas.router.AI_worker_client - INFO - Caffe predict has been called..
2018-05-17 21:38:43,068 - AIaas.router.AI_worker_client - INFO - Caffe predict has been called..
2018-05-17 21:38:43,082 - requests.packages.urllib3.connectionpool - INFO - Starting new HTTP connection (1): localhost
2018-05-17 21:38:43,090 - AIaas.router.AI_worker_client - ERROR - Predict has failed.. 
Traceback (most recent call last):
  File "/Users/leepand/Downloads/BigRLab_APIs/demoday_fs/web_lab/knn_as_a_service/AIaas/AIaas/router/AI_worker_client.py", line 113, in predict
    prediction_output.result = client.predict(prediction_input.data)
  File "/Users/leepand/Downloads/BigRLab_APIs/demoday_fs/web_lab/knn_as_a_service/AIaas/AIaas/router/common_client.py", line 116, in wrapped
    raise FireflyError('Firefly functions only accept named arguments')
FireflyError: Firefly functions only accept named arguments
2018-05-17 21:38:43,093 - AIaas.router.AI_worker_client - ERROR - Predict has failed.. 
Traceback (most recent call last):
  File "/Users/leepand/Downloads/BigRLab_APIs/demoday_fs/web_lab/knn_as_a_service/AIaas/AIaas/router/AI_worker_client.py", line 113, in predict
    prediction_output.result = client.predict(prediction_input.data)
  File "/Users/leepand/Downloads/BigRLab_APIs/demoday_fs/web_lab/knn_as_a_service/AIaas/AIaas/router/common_client.py", line 116, in wrapped
    raise FireflyError('Firefly functions only accept named arguments')
FireflyError: Firefly functions only accept named arguments
2018-05-17 21:38:43,094 - AIaas.router.AI_worker_client - ERROR - Predict has failed.. 
Traceback (most recent call last):
  File "/Users/leepand/Downloads/BigRLab_APIs/demoday_fs/web_lab/knn_as_a_service/AIaas/AIaas/router/AI_worker_client.py", line 113, in predict
    prediction_output.result = client.predict(prediction_input.data)
  File "/Users/leepand/Downloads/BigRLab_APIs/demoday_fs/web_lab/knn_as_a_service/AIaas/AIaas/router/common_client.py", line 116, in wrapped
    raise FireflyError('Firefly functions only accept named arguments')
FireflyError: Firefly functions only accept named arguments
2018-05-17 21:38:43,096 - AIaas.router.AI_worker_client - ERROR - Predict has failed.. 
Traceback (most recent call last):
  File "/Users/leepand/Downloads/BigRLab_APIs/demoday_fs/web_lab/knn_as_a_service/AIaas/AIaas/router/AI_worker_client.py", line 113, in predict
    prediction_output.result = client.predict(prediction_input.data)
  File "/Users/leepand/Downloads/BigRLab_APIs/demoday_fs/web_lab/knn_as_a_service/AIaas/AIaas/router/common_client.py", line 116, in wrapped
    raise FireflyError('Firefly functions only accept named arguments')
FireflyError: Firefly functions only accept named arguments
2018-05-17 21:38:43,098 - AIaas.router.AI_worker_client - ERROR - Predict has failed.. 
Traceback (most recent call last):
  File "/Users/leepand/Downloads/BigRLab_APIs/demoday_fs/web_lab/knn_as_a_service/AIaas/AIaas/router/AI_worker_client.py", line 113, in predict
    prediction_output.result = client.predict(prediction_input.data)
  File "/Users/leepand/Downloads/BigRLab_APIs/demoday_fs/web_lab/knn_as_a_service/AIaas/AIaas/router/common_client.py", line 116, in wrapped
    raise FireflyError('Firefly functions only accept named arguments')
FireflyError: Firefly functions only accept named arguments
2018-05-17 21:38:43,099 - AIaas.router.AI_worker_client - ERROR - Predict has failed.. 
Traceback (most recent call last):
  File "/Users/leepand/Downloads/BigRLab_APIs/demoday_fs/web_lab/knn_as_a_service/AIaas/AIaas/router/AI_worker_client.py", line 113, in predict
    prediction_output.result = client.predict(prediction_input.data)
  File "/Users/leepand/Downloads/BigRLab_APIs/demoday_fs/web_lab/knn_as_a_service/AIaas/AIaas/router/common_client.py", line 116, in wrapped
    raise FireflyError('Firefly functions only accept named arguments')
FireflyError: Firefly functions only accept named arguments
2018-05-17 21:40:11,299 - AIaas.router.AI_worker_client - INFO - Caffe predict has been called..
2018-05-17 21:40:11,301 - AIaas.router.AI_worker_client - ERROR - Predict has failed.. 
Traceback (most recent call last):
  File "/Users/leepand/Downloads/BigRLab_APIs/demoday_fs/web_lab/knn_as_a_service/AIaas/AIaas/router/AI_worker_client.py", line 113, in predict
    prediction_output.result = client.predict(prediction_input.data)
  File "/Users/leepand/Downloads/BigRLab_APIs/demoday_fs/web_lab/knn_as_a_service/AIaas/AIaas/router/common_client.py", line 116, in wrapped
    raise FireflyError('Firefly functions only accept named arguments')
FireflyError: Firefly functions only accept named arguments
2018-05-17 21:40:11,303 - AIaas.router.AI_worker_client - ERROR - Predict has failed.. 
Traceback (most recent call last):
  File "/Users/leepand/Downloads/BigRLab_APIs/demoday_fs/web_lab/knn_as_a_service/AIaas/AIaas/router/AI_worker_client.py", line 113, in predict
    prediction_output.result = client.predict(prediction_input.data)
  File "/Users/leepand/Downloads/BigRLab_APIs/demoday_fs/web_lab/knn_as_a_service/AIaas/AIaas/router/common_client.py", line 116, in wrapped
    raise FireflyError('Firefly functions only accept named arguments')
FireflyError: Firefly functions only accept named arguments
2018-05-17 21:40:11,304 - AIaas.router.AI_worker_client - ERROR - Predict has failed.. 
Traceback (most recent call last):
  File "/Users/leepand/Downloads/BigRLab_APIs/demoday_fs/web_lab/knn_as_a_service/AIaas/AIaas/router/AI_worker_client.py", line 113, in predict
    prediction_output.result = client.predict(prediction_input.data)
  File "/Users/leepand/Downloads/BigRLab_APIs/demoday_fs/web_lab/knn_as_a_service/AIaas/AIaas/router/common_client.py", line 116, in wrapped
    raise FireflyError('Firefly functions only accept named arguments')
FireflyError: Firefly functions only accept named arguments
2018-05-17 21:40:11,306 - AIaas.router.AI_worker_client - ERROR - Predict has failed.. 
Traceback (most recent call last):
  File "/Users/leepand/Downloads/BigRLab_APIs/demoday_fs/web_lab/knn_as_a_service/AIaas/AIaas/router/AI_worker_client.py", line 113, in predict
    prediction_output.result = client.predict(prediction_input.data)
  File "/Users/leepand/Downloads/BigRLab_APIs/demoday_fs/web_lab/knn_as_a_service/AIaas/AIaas/router/common_client.py", line 116, in wrapped
    raise FireflyError('Firefly functions only accept named arguments')
FireflyError: Firefly functions only accept named arguments
2018-05-17 21:40:11,307 - AIaas.router.AI_worker_client - ERROR - Predict has failed.. 
Traceback (most recent call last):
  File "/Users/leepand/Downloads/BigRLab_APIs/demoday_fs/web_lab/knn_as_a_service/AIaas/AIaas/router/AI_worker_client.py", line 113, in predict
    prediction_output.result = client.predict(prediction_input.data)
  File "/Users/leepand/Downloads/BigRLab_APIs/demoday_fs/web_lab/knn_as_a_service/AIaas/AIaas/router/common_client.py", line 116, in wrapped
    raise FireflyError('Firefly functions only accept named arguments')
FireflyError: Firefly functions only accept named arguments
2018-05-17 21:40:11,309 - AIaas.router.AI_worker_client - ERROR - Predict has failed.. 
Traceback (most recent call last):
  File "/Users/leepand/Downloads/BigRLab_APIs/demoday_fs/web_lab/knn_as_a_service/AIaas/AIaas/router/AI_worker_client.py", line 113, in predict
    prediction_output.result = client.predict(prediction_input.data)
  File "/Users/leepand/Downloads/BigRLab_APIs/demoday_fs/web_lab/knn_as_a_service/AIaas/AIaas/router/common_client.py", line 116, in wrapped
    raise FireflyError('Firefly functions only accept named arguments')
FireflyError: Firefly functions only accept named arguments
2018-05-17 21:40:20,837 - AIaas.router.AI_worker_client - INFO - Caffe predict has been called..
2018-05-17 21:40:20,839 - AIaas.router.AI_worker_client - ERROR - Predict has failed.. 
Traceback (most recent call last):
  File "/Users/leepand/Downloads/BigRLab_APIs/demoday_fs/web_lab/knn_as_a_service/AIaas/AIaas/router/AI_worker_client.py", line 113, in predict
    prediction_output.result = client.predict(prediction_input.data)
  File "/Users/leepand/Downloads/BigRLab_APIs/demoday_fs/web_lab/knn_as_a_service/AIaas/AIaas/router/common_client.py", line 116, in wrapped
    raise FireflyError('Firefly functions only accept named arguments')
FireflyError: Firefly functions only accept named arguments
2018-05-17 21:40:20,841 - AIaas.router.AI_worker_client - ERROR - Predict has failed.. 
Traceback (most recent call last):
  File "/Users/leepand/Downloads/BigRLab_APIs/demoday_fs/web_lab/knn_as_a_service/AIaas/AIaas/router/AI_worker_client.py", line 113, in predict
    prediction_output.result = client.predict(prediction_input.data)
  File "/Users/leepand/Downloads/BigRLab_APIs/demoday_fs/web_lab/knn_as_a_service/AIaas/AIaas/router/common_client.py", line 116, in wrapped
    raise FireflyError('Firefly functions only accept named arguments')
FireflyError: Firefly functions only accept named arguments
2018-05-17 21:40:20,842 - AIaas.router.AI_worker_client - ERROR - Predict has failed.. 
Traceback (most recent call last):
  File "/Users/leepand/Downloads/BigRLab_APIs/demoday_fs/web_lab/knn_as_a_service/AIaas/AIaas/router/AI_worker_client.py", line 113, in predict
    prediction_output.result = client.predict(prediction_input.data)
  File "/Users/leepand/Downloads/BigRLab_APIs/demoday_fs/web_lab/knn_as_a_service/AIaas/AIaas/router/common_client.py", line 116, in wrapped
    raise FireflyError('Firefly functions only accept named arguments')
FireflyError: Firefly functions only accept named arguments
2018-05-17 21:40:20,843 - AIaas.router.AI_worker_client - ERROR - Predict has failed.. 
Traceback (most recent call last):
  File "/Users/leepand/Downloads/BigRLab_APIs/demoday_fs/web_lab/knn_as_a_service/AIaas/AIaas/router/AI_worker_client.py", line 113, in predict
    prediction_output.result = client.predict(prediction_input.data)
  File "/Users/leepand/Downloads/BigRLab_APIs/demoday_fs/web_lab/knn_as_a_service/AIaas/AIaas/router/common_client.py", line 116, in wrapped
    raise FireflyError('Firefly functions only accept named arguments')
FireflyError: Firefly functions only accept named arguments
2018-05-17 21:40:20,845 - AIaas.router.AI_worker_client - ERROR - Predict has failed.. 
Traceback (most recent call last):
  File "/Users/leepand/Downloads/BigRLab_APIs/demoday_fs/web_lab/knn_as_a_service/AIaas/AIaas/router/AI_worker_client.py", line 113, in predict
    prediction_output.result = client.predict(prediction_input.data)
  File "/Users/leepand/Downloads/BigRLab_APIs/demoday_fs/web_lab/knn_as_a_service/AIaas/AIaas/router/common_client.py", line 116, in wrapped
    raise FireflyError('Firefly functions only accept named arguments')
FireflyError: Firefly functions only accept named arguments
2018-05-17 21:40:20,847 - AIaas.router.AI_worker_client - ERROR - Predict has failed.. 
Traceback (most recent call last):
  File "/Users/leepand/Downloads/BigRLab_APIs/demoday_fs/web_lab/knn_as_a_service/AIaas/AIaas/router/AI_worker_client.py", line 113, in predict
    prediction_output.result = client.predict(prediction_input.data)
  File "/Users/leepand/Downloads/BigRLab_APIs/demoday_fs/web_lab/knn_as_a_service/AIaas/AIaas/router/common_client.py", line 116, in wrapped
    raise FireflyError('Firefly functions only accept named arguments')
FireflyError: Firefly functions only accept named arguments
2018-05-17 21:40:43,790 - AIaas.router.AI_worker_client - INFO - Caffe predict has been called..
2018-05-17 21:40:43,792 - AIaas.router.AI_worker_client - ERROR - Predict has failed.. 
Traceback (most recent call last):
  File "/Users/leepand/Downloads/BigRLab_APIs/demoday_fs/web_lab/knn_as_a_service/AIaas/AIaas/router/AI_worker_client.py", line 113, in predict
    prediction_output.result = client.predict(prediction_input.data)
  File "/Users/leepand/Downloads/BigRLab_APIs/demoday_fs/web_lab/knn_as_a_service/AIaas/AIaas/router/common_client.py", line 116, in wrapped
    raise FireflyError('Firefly functions only accept named arguments')
FireflyError: Firefly functions only accept named arguments
2018-05-17 21:40:43,793 - AIaas.router.AI_worker_client - ERROR - Predict has failed.. 
Traceback (most recent call last):
  File "/Users/leepand/Downloads/BigRLab_APIs/demoday_fs/web_lab/knn_as_a_service/AIaas/AIaas/router/AI_worker_client.py", line 113, in predict
    prediction_output.result = client.predict(prediction_input.data)
  File "/Users/leepand/Downloads/BigRLab_APIs/demoday_fs/web_lab/knn_as_a_service/AIaas/AIaas/router/common_client.py", line 116, in wrapped
    raise FireflyError('Firefly functions only accept named arguments')
FireflyError: Firefly functions only accept named arguments
2018-05-17 21:40:43,795 - AIaas.router.AI_worker_client - ERROR - Predict has failed.. 
Traceback (most recent call last):
  File "/Users/leepand/Downloads/BigRLab_APIs/demoday_fs/web_lab/knn_as_a_service/AIaas/AIaas/router/AI_worker_client.py", line 113, in predict
    prediction_output.result = client.predict(prediction_input.data)
  File "/Users/leepand/Downloads/BigRLab_APIs/demoday_fs/web_lab/knn_as_a_service/AIaas/AIaas/router/common_client.py", line 116, in wrapped
    raise FireflyError('Firefly functions only accept named arguments')
FireflyError: Firefly functions only accept named arguments
2018-05-17 21:40:43,796 - AIaas.router.AI_worker_client - ERROR - Predict has failed.. 
Traceback (most recent call last):
  File "/Users/leepand/Downloads/BigRLab_APIs/demoday_fs/web_lab/knn_as_a_service/AIaas/AIaas/router/AI_worker_client.py", line 113, in predict
    prediction_output.result = client.predict(prediction_input.data)
  File "/Users/leepand/Downloads/BigRLab_APIs/demoday_fs/web_lab/knn_as_a_service/AIaas/AIaas/router/common_client.py", line 116, in wrapped
    raise FireflyError('Firefly functions only accept named arguments')
FireflyError: Firefly functions only accept named arguments
2018-05-17 21:40:43,798 - AIaas.router.AI_worker_client - ERROR - Predict has failed.. 
Traceback (most recent call last):
  File "/Users/leepand/Downloads/BigRLab_APIs/demoday_fs/web_lab/knn_as_a_service/AIaas/AIaas/router/AI_worker_client.py", line 113, in predict
    prediction_output.result = client.predict(prediction_input.data)
  File "/Users/leepand/Downloads/BigRLab_APIs/demoday_fs/web_lab/knn_as_a_service/AIaas/AIaas/router/common_client.py", line 116, in wrapped
    raise FireflyError('Firefly functions only accept named arguments')
FireflyError: Firefly functions only accept named arguments
2018-05-17 21:40:43,799 - AIaas.router.AI_worker_client - ERROR - Predict has failed.. 
Traceback (most recent call last):
  File "/Users/leepand/Downloads/BigRLab_APIs/demoday_fs/web_lab/knn_as_a_service/AIaas/AIaas/router/AI_worker_client.py", line 113, in predict
    prediction_output.result = client.predict(prediction_input.data)
  File "/Users/leepand/Downloads/BigRLab_APIs/demoday_fs/web_lab/knn_as_a_service/AIaas/AIaas/router/common_client.py", line 116, in wrapped
    raise FireflyError('Firefly functions only accept named arguments')
FireflyError: Firefly functions only accept named arguments
2018-05-17 21:41:53,834 - AIaas.router.AI_worker_client - INFO - Caffe predict has been called..
2018-05-17 21:41:53,836 - AIaas.router.AI_worker_client - ERROR - Predict has failed.. 
Traceback (most recent call last):
  File "/Users/leepand/Downloads/BigRLab_APIs/demoday_fs/web_lab/knn_as_a_service/AIaas/AIaas/router/AI_worker_client.py", line 113, in predict
    prediction_output.result = client.predict(prediction_input.data)
  File "/Users/leepand/Downloads/BigRLab_APIs/demoday_fs/web_lab/knn_as_a_service/AIaas/AIaas/router/common_client.py", line 116, in wrapped
    raise FireflyError('Firefly functions only accept named arguments')
FireflyError: Firefly functions only accept named arguments
2018-05-17 21:41:53,838 - AIaas.router.AI_worker_client - ERROR - Predict has failed.. 
Traceback (most recent call last):
  File "/Users/leepand/Downloads/BigRLab_APIs/demoday_fs/web_lab/knn_as_a_service/AIaas/AIaas/router/AI_worker_client.py", line 113, in predict
    prediction_output.result = client.predict(prediction_input.data)
  File "/Users/leepand/Downloads/BigRLab_APIs/demoday_fs/web_lab/knn_as_a_service/AIaas/AIaas/router/common_client.py", line 116, in wrapped
    raise FireflyError('Firefly functions only accept named arguments')
FireflyError: Firefly functions only accept named arguments
2018-05-17 21:41:53,839 - AIaas.router.AI_worker_client - ERROR - Predict has failed.. 
Traceback (most recent call last):
  File "/Users/leepand/Downloads/BigRLab_APIs/demoday_fs/web_lab/knn_as_a_service/AIaas/AIaas/router/AI_worker_client.py", line 113, in predict
    prediction_output.result = client.predict(prediction_input.data)
  File "/Users/leepand/Downloads/BigRLab_APIs/demoday_fs/web_lab/knn_as_a_service/AIaas/AIaas/router/common_client.py", line 116, in wrapped
    raise FireflyError('Firefly functions only accept named arguments')
FireflyError: Firefly functions only accept named arguments
2018-05-17 21:41:53,841 - AIaas.router.AI_worker_client - ERROR - Predict has failed.. 
Traceback (most recent call last):
  File "/Users/leepand/Downloads/BigRLab_APIs/demoday_fs/web_lab/knn_as_a_service/AIaas/AIaas/router/AI_worker_client.py", line 113, in predict
    prediction_output.result = client.predict(prediction_input.data)
  File "/Users/leepand/Downloads/BigRLab_APIs/demoday_fs/web_lab/knn_as_a_service/AIaas/AIaas/router/common_client.py", line 116, in wrapped
    raise FireflyError('Firefly functions only accept named arguments')
FireflyError: Firefly functions only accept named arguments
2018-05-17 21:41:53,843 - AIaas.router.AI_worker_client - ERROR - Predict has failed.. 
Traceback (most recent call last):
  File "/Users/leepand/Downloads/BigRLab_APIs/demoday_fs/web_lab/knn_as_a_service/AIaas/AIaas/router/AI_worker_client.py", line 113, in predict
    prediction_output.result = client.predict(prediction_input.data)
  File "/Users/leepand/Downloads/BigRLab_APIs/demoday_fs/web_lab/knn_as_a_service/AIaas/AIaas/router/common_client.py", line 116, in wrapped
    raise FireflyError('Firefly functions only accept named arguments')
FireflyError: Firefly functions only accept named arguments
2018-05-17 21:41:53,844 - AIaas.router.AI_worker_client - ERROR - Predict has failed.. 
Traceback (most recent call last):
  File "/Users/leepand/Downloads/BigRLab_APIs/demoday_fs/web_lab/knn_as_a_service/AIaas/AIaas/router/AI_worker_client.py", line 113, in predict
    prediction_output.result = client.predict(prediction_input.data)
  File "/Users/leepand/Downloads/BigRLab_APIs/demoday_fs/web_lab/knn_as_a_service/AIaas/AIaas/router/common_client.py", line 116, in wrapped
    raise FireflyError('Firefly functions only accept named arguments')
FireflyError: Firefly functions only accept named arguments
2018-05-17 21:42:07,767 - AIaas.router.AI_worker_client - INFO - Caffe predict has been called..
2018-05-17 21:42:27,226 - AIaas.router.AI_worker_client - INFO - Caffe predict has been called..
2018-05-17 21:42:27,228 - AIaas.router.AI_worker_client - ERROR - Predict has failed.. 
Traceback (most recent call last):
  File "/Users/leepand/Downloads/BigRLab_APIs/demoday_fs/web_lab/knn_as_a_service/AIaas/AIaas/router/AI_worker_client.py", line 113, in predict
    prediction_output.result = client.predict(prediction_input.data)
  File "/Users/leepand/Downloads/BigRLab_APIs/demoday_fs/web_lab/knn_as_a_service/AIaas/AIaas/router/common_client.py", line 116, in wrapped
    raise FireflyError('Firefly functions only accept named arguments')
FireflyError: Firefly functions only accept named arguments
2018-05-17 21:42:27,230 - AIaas.router.AI_worker_client - ERROR - Predict has failed.. 
Traceback (most recent call last):
  File "/Users/leepand/Downloads/BigRLab_APIs/demoday_fs/web_lab/knn_as_a_service/AIaas/AIaas/router/AI_worker_client.py", line 113, in predict
    prediction_output.result = client.predict(prediction_input.data)
  File "/Users/leepand/Downloads/BigRLab_APIs/demoday_fs/web_lab/knn_as_a_service/AIaas/AIaas/router/common_client.py", line 116, in wrapped
    raise FireflyError('Firefly functions only accept named arguments')
FireflyError: Firefly functions only accept named arguments
2018-05-17 21:42:27,231 - AIaas.router.AI_worker_client - ERROR - Predict has failed.. 
Traceback (most recent call last):
  File "/Users/leepand/Downloads/BigRLab_APIs/demoday_fs/web_lab/knn_as_a_service/AIaas/AIaas/router/AI_worker_client.py", line 113, in predict
    prediction_output.result = client.predict(prediction_input.data)
  File "/Users/leepand/Downloads/BigRLab_APIs/demoday_fs/web_lab/knn_as_a_service/AIaas/AIaas/router/common_client.py", line 116, in wrapped
    raise FireflyError('Firefly functions only accept named arguments')
FireflyError: Firefly functions only accept named arguments
2018-05-17 21:42:27,233 - AIaas.router.AI_worker_client - ERROR - Predict has failed.. 
Traceback (most recent call last):
  File "/Users/leepand/Downloads/BigRLab_APIs/demoday_fs/web_lab/knn_as_a_service/AIaas/AIaas/router/AI_worker_client.py", line 113, in predict
    prediction_output.result = client.predict(prediction_input.data)
  File "/Users/leepand/Downloads/BigRLab_APIs/demoday_fs/web_lab/knn_as_a_service/AIaas/AIaas/router/common_client.py", line 116, in wrapped
    raise FireflyError('Firefly functions only accept named arguments')
FireflyError: Firefly functions only accept named arguments
2018-05-17 21:42:27,234 - AIaas.router.AI_worker_client - ERROR - Predict has failed.. 
Traceback (most recent call last):
  File "/Users/leepand/Downloads/BigRLab_APIs/demoday_fs/web_lab/knn_as_a_service/AIaas/AIaas/router/AI_worker_client.py", line 113, in predict
    prediction_output.result = client.predict(prediction_input.data)
  File "/Users/leepand/Downloads/BigRLab_APIs/demoday_fs/web_lab/knn_as_a_service/AIaas/AIaas/router/common_client.py", line 116, in wrapped
    raise FireflyError('Firefly functions only accept named arguments')
FireflyError: Firefly functions only accept named arguments
2018-05-17 21:42:27,235 - AIaas.router.AI_worker_client - ERROR - Predict has failed.. 
Traceback (most recent call last):
  File "/Users/leepand/Downloads/BigRLab_APIs/demoday_fs/web_lab/knn_as_a_service/AIaas/AIaas/router/AI_worker_client.py", line 113, in predict
    prediction_output.result = client.predict(prediction_input.data)
  File "/Users/leepand/Downloads/BigRLab_APIs/demoday_fs/web_lab/knn_as_a_service/AIaas/AIaas/router/common_client.py", line 116, in wrapped
    raise FireflyError('Firefly functions only accept named arguments')
FireflyError: Firefly functions only accept named arguments
2018-05-17 21:42:40,806 - AIaas.router.AI_worker_client - INFO - Caffe predict has been called..
2018-05-17 21:42:40,807 - AIaas.router.AI_worker_client - ERROR - Predict has failed.. 
Traceback (most recent call last):
  File "/Users/leepand/Downloads/BigRLab_APIs/demoday_fs/web_lab/knn_as_a_service/AIaas/AIaas/router/AI_worker_client.py", line 113, in predict
    prediction_output.result = client.predict(prediction_input.data)
  File "/Users/leepand/Downloads/BigRLab_APIs/demoday_fs/web_lab/knn_as_a_service/AIaas/AIaas/router/common_client.py", line 116, in wrapped
    raise FireflyError('Firefly functions only accept named arguments')
FireflyError: Firefly functions only accept named arguments
2018-05-17 21:42:40,809 - AIaas.router.AI_worker_client - ERROR - Predict has failed.. 
Traceback (most recent call last):
  File "/Users/leepand/Downloads/BigRLab_APIs/demoday_fs/web_lab/knn_as_a_service/AIaas/AIaas/router/AI_worker_client.py", line 113, in predict
    prediction_output.result = client.predict(prediction_input.data)
  File "/Users/leepand/Downloads/BigRLab_APIs/demoday_fs/web_lab/knn_as_a_service/AIaas/AIaas/router/common_client.py", line 116, in wrapped
    raise FireflyError('Firefly functions only accept named arguments')
FireflyError: Firefly functions only accept named arguments
2018-05-17 21:42:40,811 - AIaas.router.AI_worker_client - ERROR - Predict has failed.. 
Traceback (most recent call last):
  File "/Users/leepand/Downloads/BigRLab_APIs/demoday_fs/web_lab/knn_as_a_service/AIaas/AIaas/router/AI_worker_client.py", line 113, in predict
    prediction_output.result = client.predict(prediction_input.data)
  File "/Users/leepand/Downloads/BigRLab_APIs/demoday_fs/web_lab/knn_as_a_service/AIaas/AIaas/router/common_client.py", line 116, in wrapped
    raise FireflyError('Firefly functions only accept named arguments')
FireflyError: Firefly functions only accept named arguments
2018-05-17 21:42:40,812 - AIaas.router.AI_worker_client - ERROR - Predict has failed.. 
Traceback (most recent call last):
  File "/Users/leepand/Downloads/BigRLab_APIs/demoday_fs/web_lab/knn_as_a_service/AIaas/AIaas/router/AI_worker_client.py", line 113, in predict
    prediction_output.result = client.predict(prediction_input.data)
  File "/Users/leepand/Downloads/BigRLab_APIs/demoday_fs/web_lab/knn_as_a_service/AIaas/AIaas/router/common_client.py", line 116, in wrapped
    raise FireflyError('Firefly functions only accept named arguments')
FireflyError: Firefly functions only accept named arguments
2018-05-17 21:42:40,814 - AIaas.router.AI_worker_client - ERROR - Predict has failed.. 
Traceback (most recent call last):
  File "/Users/leepand/Downloads/BigRLab_APIs/demoday_fs/web_lab/knn_as_a_service/AIaas/AIaas/router/AI_worker_client.py", line 113, in predict
    prediction_output.result = client.predict(prediction_input.data)
  File "/Users/leepand/Downloads/BigRLab_APIs/demoday_fs/web_lab/knn_as_a_service/AIaas/AIaas/router/common_client.py", line 116, in wrapped
    raise FireflyError('Firefly functions only accept named arguments')
FireflyError: Firefly functions only accept named arguments
2018-05-17 21:42:40,815 - AIaas.router.AI_worker_client - ERROR - Predict has failed.. 
Traceback (most recent call last):
  File "/Users/leepand/Downloads/BigRLab_APIs/demoday_fs/web_lab/knn_as_a_service/AIaas/AIaas/router/AI_worker_client.py", line 113, in predict
    prediction_output.result = client.predict(prediction_input.data)
  File "/Users/leepand/Downloads/BigRLab_APIs/demoday_fs/web_lab/knn_as_a_service/AIaas/AIaas/router/common_client.py", line 116, in wrapped
    raise FireflyError('Firefly functions only accept named arguments')
FireflyError: Firefly functions only accept named arguments
2018-05-17 21:44:38,735 - router.router_app - INFO - Starting Router...
2018-05-17 21:44:38,744 - AIaas.router.AI_worker_client - INFO - load balancer inited...
2018-05-17 21:44:38,745 - AIaas.router.AI_worker_client - INFO - AIWorkerClient Inited...
2018-05-17 21:44:38,746 - AIaas.router.predict - INFO - Predict Inited...
2018-05-17 21:45:00,495 - AIaas.router.AI_worker_client - INFO - Caffe predict has been called..
2018-05-17 22:21:11,322 - router.router_app - INFO - Starting Router...
2018-05-17 22:21:11,331 - AIaas.router.AI_worker_client - INFO - load balancer inited...
2018-05-17 22:21:11,332 - AIaas.router.AI_worker_client - INFO - AIWorkerClient Inited...
2018-05-17 22:21:11,333 - AIaas.router.predict - INFO - Predict Inited...
2018-05-17 22:21:16,467 - router.router_app - INFO - Starting Router...
2018-05-17 22:21:16,475 - AIaas.router.AI_worker_client - INFO - load balancer inited...
2018-05-17 22:21:16,476 - AIaas.router.AI_worker_client - INFO - AIWorkerClient Inited...
2018-05-17 22:21:16,477 - AIaas.router.predict - INFO - Predict Inited...
2018-05-17 22:25:05,327 - router.router_app - INFO - Starting Router...
2018-05-17 22:25:05,329 - router.router_app - INFO - Starting Router...
2018-05-17 22:25:05,337 - AIaas.router.AI_worker_client - INFO - load balancer inited...
2018-05-17 22:25:05,338 - AIaas.router.AI_worker_client - INFO - AIWorkerClient Inited...
2018-05-17 22:25:05,339 - AIaas.router.predict - INFO - Predict Inited...
2018-05-17 22:25:05,339 - AIaas.router.AI_worker_client - INFO - load balancer inited...
2018-05-17 22:25:05,340 - AIaas.router.AI_worker_client - INFO - AIWorkerClient Inited...
2018-05-17 22:25:05,340 - AIaas.router.predict - INFO - Predict Inited...
2018-05-17 22:58:15,340 - router.router_app - INFO - Starting Router...
2018-05-17 22:58:15,369 - router.router_app - INFO - Starting Router...
2018-05-17 22:58:15,456 - AIaas.router.AI_worker_client - INFO - load balancer inited...
2018-05-17 22:58:15,458 - AIaas.router.AI_worker_client - INFO - AIWorkerClient Inited...
2018-05-17 22:58:15,460 - AIaas.router.predict - INFO - Predict Inited...
2018-05-17 22:58:15,462 - AIaas.router.AI_worker_client - INFO - load balancer inited...
2018-05-17 22:58:15,465 - AIaas.router.AI_worker_client - INFO - AIWorkerClient Inited...
2018-05-17 22:58:15,467 - AIaas.router.predict - INFO - Predict Inited...
2018-05-17 23:31:23,298 - router.router_app - INFO - Starting Router...
2018-05-17 23:31:23,299 - router.router_app - INFO - Starting Router...
2018-05-17 23:31:23,313 - AIaas.router.AI_worker_client - INFO - load balancer inited...
2018-05-17 23:31:23,314 - AIaas.router.AI_worker_client - INFO - load balancer inited...
2018-05-17 23:31:23,314 - AIaas.router.AI_worker_client - INFO - AIWorkerClient Inited...
2018-05-17 23:31:23,315 - AIaas.router.AI_worker_client - INFO - AIWorkerClient Inited...
2018-05-17 23:31:23,315 - AIaas.router.predict - INFO - Predict Inited...
2018-05-17 23:31:23,316 - AIaas.router.predict - INFO - Predict Inited...
2018-05-18 07:18:13,809 - router.router_app - INFO - Starting Router...
2018-05-18 07:18:13,809 - router.router_app - INFO - Starting Router...
2018-05-18 07:18:13,819 - AIaas.router.AI_worker_client - INFO - load balancer inited...
2018-05-18 07:18:13,819 - AIaas.router.AI_worker_client - INFO - load balancer inited...
2018-05-18 07:18:13,819 - AIaas.router.AI_worker_client - INFO - AIWorkerClient Inited...
2018-05-18 07:18:13,819 - AIaas.router.AI_worker_client - INFO - AIWorkerClient Inited...
2018-05-18 07:18:13,820 - AIaas.router.predict - INFO - Predict Inited...
2018-05-18 07:18:13,820 - AIaas.router.predict - INFO - Predict Inited...
2018-05-18 07:21:47,903 - router.router_app - INFO - Starting Router...
2018-05-18 07:21:47,912 - AIaas.router.AI_worker_client - INFO - load balancer inited...
2018-05-18 07:21:47,913 - AIaas.router.AI_worker_client - INFO - AIWorkerClient Inited...
2018-05-18 07:21:47,914 - AIaas.router.predict - INFO - Predict Inited...
2018-05-18 07:31:21,813 - router.router_app - INFO - Starting Router...
2018-05-18 07:31:21,814 - router.router_app - INFO - Starting Router...
2018-05-18 07:31:21,825 - AIaas.router.AI_worker_client - INFO - load balancer inited...
2018-05-18 07:31:21,826 - AIaas.router.AI_worker_client - INFO - AIWorkerClient Inited...
2018-05-18 07:31:21,827 - AIaas.router.predict - INFO - Predict Inited...
2018-05-18 07:31:21,827 - AIaas.router.AI_worker_client - INFO - load balancer inited...
2018-05-18 07:31:21,828 - AIaas.router.AI_worker_client - INFO - AIWorkerClient Inited...
2018-05-18 07:31:21,828 - AIaas.router.predict - INFO - Predict Inited...
2018-05-18 07:55:49,471 - router.router_app - INFO - Starting Router...
2018-05-18 07:55:49,471 - router.router_app - INFO - Starting Router...
2018-05-18 07:55:49,482 - AIaas.router.AI_worker_client - INFO - load balancer inited...
2018-05-18 07:55:49,482 - AIaas.router.AI_worker_client - INFO - load balancer inited...
2018-05-18 07:55:49,482 - AIaas.router.AI_worker_client - INFO - AIWorkerClient Inited...
2018-05-18 07:55:49,483 - AIaas.router.predict - INFO - Predict Inited...
2018-05-18 07:55:49,483 - AIaas.router.AI_worker_client - INFO - AIWorkerClient Inited...
2018-05-18 07:55:49,484 - AIaas.router.predict - INFO - Predict Inited...
2018-05-18 08:26:04,432 - router.router_app - INFO - Starting Router...
2018-05-18 08:26:04,432 - router.router_app - INFO - Starting Router...
2018-05-18 08:26:04,441 - AIaas.router.AI_worker_client - INFO - load balancer inited...
2018-05-18 08:26:04,441 - AIaas.router.AI_worker_client - INFO - load balancer inited...
2018-05-18 08:26:04,442 - AIaas.router.AI_worker_client - INFO - AIWorkerClient Inited...
2018-05-18 08:26:04,442 - AIaas.router.AI_worker_client - INFO - AIWorkerClient Inited...
2018-05-18 08:26:04,442 - AIaas.router.predict - INFO - Predict Inited...
2018-05-18 08:26:04,443 - AIaas.router.predict - INFO - Predict Inited...
2018-05-18 08:29:16,620 - AIaas.router.AI_worker_client - INFO - Caffe predict has been called..
2018-05-18 09:10:53,551 - router.router_app - INFO - Starting Router...
2018-05-18 09:10:53,559 - AIaas.router.AI_worker_client - INFO - load balancer inited...
2018-05-18 09:10:53,560 - AIaas.router.AI_worker_client - INFO - AIWorkerClient Inited...
2018-05-18 09:10:53,561 - AIaas.router.predict - INFO - Predict Inited...
2018-05-18 09:11:59,400 - AIaas.router.AI_worker_client - INFO - Caffe predict has been called..
2018-05-18 09:11:59,417 - requests.packages.urllib3.connectionpool - INFO - Starting new HTTP connection (1): localhost
2018-05-18 09:11:59,444 - AIaas.router.AI_worker_client - ERROR - Predict has failed.. 
Traceback (most recent call last):
  File "/Users/leepand/anaconda2/lib/python2.7/site-packages/gunicorn/workers/sync.py", line 68, in run_for_one
    self.accept(listener)
  File "/Users/leepand/anaconda2/lib/python2.7/site-packages/gunicorn/workers/sync.py", line 27, in accept
    client, addr = listener.accept()
  File "/Users/leepand/anaconda2/lib/python2.7/socket.py", line 206, in accept
    sock, addr = self._sock.accept()
error: [Errno 35] Resource temporarily unavailable
2018-05-18 09:12:08,872 - AIaas.router.AI_worker_client - INFO - Caffe predict has been called..
2018-05-18 09:12:08,876 - requests.packages.urllib3.connectionpool - INFO - Starting new HTTP connection (1): localhost
2018-05-18 09:12:08,882 - AIaas.router.AI_worker_client - ERROR - Predict has failed.. 
Traceback (most recent call last):
  File "/Users/leepand/anaconda2/lib/python2.7/site-packages/gunicorn/workers/sync.py", line 68, in run_for_one
    self.accept(listener)
  File "/Users/leepand/anaconda2/lib/python2.7/site-packages/gunicorn/workers/sync.py", line 27, in accept
    client, addr = listener.accept()
  File "/Users/leepand/anaconda2/lib/python2.7/socket.py", line 206, in accept
    sock, addr = self._sock.accept()
error: [Errno 35] Resource temporarily unavailable
2018-05-18 09:15:09,217 - AIaas.router.AI_worker_client - INFO - Caffe predict has been called..
2018-05-18 09:15:09,220 - requests.packages.urllib3.connectionpool - INFO - Starting new HTTP connection (1): localhost
2018-05-18 09:15:09,225 - AIaas.router.AI_worker_client - ERROR - Predict has failed.. 
Traceback (most recent call last):
  File "/Users/leepand/anaconda2/lib/python2.7/site-packages/gunicorn/workers/sync.py", line 68, in run_for_one
    self.accept(listener)
  File "/Users/leepand/anaconda2/lib/python2.7/site-packages/gunicorn/workers/sync.py", line 27, in accept
    client, addr = listener.accept()
  File "/Users/leepand/anaconda2/lib/python2.7/socket.py", line 206, in accept
    sock, addr = self._sock.accept()
error: [Errno 35] Resource temporarily unavailable
2018-05-18 09:15:18,364 - AIaas.router.AI_worker_client - INFO - Caffe predict has been called..
2018-05-18 09:15:18,367 - requests.packages.urllib3.connectionpool - INFO - Starting new HTTP connection (1): localhost
2018-05-18 09:15:18,374 - AIaas.router.AI_worker_client - ERROR - Predict has failed.. 
Traceback (most recent call last):
  File "/Users/leepand/anaconda2/lib/python2.7/site-packages/gunicorn/workers/sync.py", line 68, in run_for_one
    self.accept(listener)
  File "/Users/leepand/anaconda2/lib/python2.7/site-packages/gunicorn/workers/sync.py", line 27, in accept
    client, addr = listener.accept()
  File "/Users/leepand/anaconda2/lib/python2.7/socket.py", line 206, in accept
    sock, addr = self._sock.accept()
error: [Errno 35] Resource temporarily unavailable
2018-05-18 09:16:44,229 - AIaas.router.AI_worker_client - INFO - Caffe predict has been called..
2018-05-18 09:16:44,232 - requests.packages.urllib3.connectionpool - INFO - Starting new HTTP connection (1): localhost
2018-05-18 09:16:44,238 - AIaas.router.AI_worker_client - ERROR - Predict has failed.. 
Traceback (most recent call last):
  File "/Users/leepand/anaconda2/lib/python2.7/site-packages/gunicorn/workers/sync.py", line 68, in run_for_one
    self.accept(listener)
  File "/Users/leepand/anaconda2/lib/python2.7/site-packages/gunicorn/workers/sync.py", line 27, in accept
    client, addr = listener.accept()
  File "/Users/leepand/anaconda2/lib/python2.7/socket.py", line 206, in accept
    sock, addr = self._sock.accept()
error: [Errno 35] Resource temporarily unavailable
2018-05-18 09:16:50,700 - AIaas.router.AI_worker_client - INFO - Caffe predict has been called..
2018-05-18 09:16:50,703 - requests.packages.urllib3.connectionpool - INFO - Starting new HTTP connection (1): localhost
2018-05-18 09:16:50,710 - AIaas.router.AI_worker_client - ERROR - Predict has failed.. 
Traceback (most recent call last):
  File "/Users/leepand/anaconda2/lib/python2.7/site-packages/gunicorn/workers/sync.py", line 68, in run_for_one
    self.accept(listener)
  File "/Users/leepand/anaconda2/lib/python2.7/site-packages/gunicorn/workers/sync.py", line 27, in accept
    client, addr = listener.accept()
  File "/Users/leepand/anaconda2/lib/python2.7/socket.py", line 206, in accept
    sock, addr = self._sock.accept()
error: [Errno 35] Resource temporarily unavailable
2018-05-18 09:17:00,679 - AIaas.router.AI_worker_client - INFO - Caffe predict has been called..
2018-05-18 09:17:00,682 - requests.packages.urllib3.connectionpool - INFO - Starting new HTTP connection (1): localhost
2018-05-18 09:17:00,688 - AIaas.router.AI_worker_client - ERROR - Predict has failed.. 
Traceback (most recent call last):
  File "/Users/leepand/anaconda2/lib/python2.7/site-packages/gunicorn/workers/sync.py", line 68, in run_for_one
    self.accept(listener)
  File "/Users/leepand/anaconda2/lib/python2.7/site-packages/gunicorn/workers/sync.py", line 27, in accept
    client, addr = listener.accept()
  File "/Users/leepand/anaconda2/lib/python2.7/socket.py", line 206, in accept
    sock, addr = self._sock.accept()
error: [Errno 35] Resource temporarily unavailable
2018-05-18 09:17:02,021 - AIaas.router.AI_worker_client - INFO - Caffe predict has been called..
2018-05-18 09:17:02,024 - requests.packages.urllib3.connectionpool - INFO - Starting new HTTP connection (1): localhost
2018-05-18 09:17:02,031 - AIaas.router.AI_worker_client - ERROR - Predict has failed.. 
Traceback (most recent call last):
  File "/Users/leepand/anaconda2/lib/python2.7/site-packages/gunicorn/workers/sync.py", line 68, in run_for_one
    self.accept(listener)
  File "/Users/leepand/anaconda2/lib/python2.7/site-packages/gunicorn/workers/sync.py", line 27, in accept
    client, addr = listener.accept()
  File "/Users/leepand/anaconda2/lib/python2.7/socket.py", line 206, in accept
    sock, addr = self._sock.accept()
error: [Errno 35] Resource temporarily unavailable
2018-05-18 09:17:03,228 - AIaas.router.AI_worker_client - INFO - Caffe predict has been called..
2018-05-18 09:17:03,231 - requests.packages.urllib3.connectionpool - INFO - Starting new HTTP connection (1): localhost
2018-05-18 09:17:03,237 - AIaas.router.AI_worker_client - ERROR - Predict has failed.. 
Traceback (most recent call last):
  File "/Users/leepand/anaconda2/lib/python2.7/site-packages/gunicorn/workers/sync.py", line 68, in run_for_one
    self.accept(listener)
  File "/Users/leepand/anaconda2/lib/python2.7/site-packages/gunicorn/workers/sync.py", line 27, in accept
    client, addr = listener.accept()
  File "/Users/leepand/anaconda2/lib/python2.7/socket.py", line 206, in accept
    sock, addr = self._sock.accept()
error: [Errno 35] Resource temporarily unavailable
2018-05-18 09:21:44,278 - AIaas.router.AI_worker_client - INFO - Caffe predict has been called..
2018-05-18 09:21:44,281 - requests.packages.urllib3.connectionpool - INFO - Starting new HTTP connection (1): localhost
2018-05-18 09:21:44,284 - AIaas.router.AI_worker_client - ERROR - Predict has failed.. 
Traceback (most recent call last):
  File "/Users/leepand/Downloads/BigRLab_APIs/demoday_fs/web_lab/knn_as_a_service/AIaas/AIaas/router/AI_worker_client.py", line 118, in predict
    prediction_output.result = client.predict(prediction_input.data)
  File "/Users/leepand/Downloads/BigRLab_APIs/demoday_fs/web_lab/knn_as_a_service/AIaas/AIaas/router/common_client.py", line 247, in predict
    return self.post(self.__urls["predict"], json=data)
  File "/Users/leepand/Downloads/BigRLab_APIs/demoday_fs/web_lab/knn_as_a_service/AIaas/AIaas/router/common_client.py", line 106, in post
    r = requests.post(url=url, json=json, params=params, timeout=DD_TIMEOUT)
  File "/Users/leepand/anaconda2/lib/python2.7/site-packages/requests/api.py", line 110, in post
    return request('post', url, data=data, json=json, **kwargs)
  File "/Users/leepand/anaconda2/lib/python2.7/site-packages/requests/api.py", line 56, in request
    return session.request(method=method, url=url, **kwargs)
  File "/Users/leepand/anaconda2/lib/python2.7/site-packages/requests/sessions.py", line 475, in request
    resp = self.send(prep, **send_kwargs)
  File "/Users/leepand/anaconda2/lib/python2.7/site-packages/requests/sessions.py", line 596, in send
    r = adapter.send(request, **kwargs)
  File "/Users/leepand/anaconda2/lib/python2.7/site-packages/requests/adapters.py", line 487, in send
    raise ConnectionError(e, request=request)
ConnectionError: HTTPConnectionPool(host='localhost', port=9001): Max retries exceeded with url: /predict (Caused by NewConnectionError('<requests.packages.urllib3.connection.HTTPConnection object at 0x10963bf50>: Failed to establish a new connection: [Errno 61] Connection refused',))
2018-05-18 09:21:44,286 - AIaas.router.AI_worker_client - ERROR - Predict has failed.. 
Traceback (most recent call last):
  File "/Users/leepand/Downloads/BigRLab_APIs/demoday_fs/web_lab/knn_as_a_service/AIaas/AIaas/router/AI_worker_client.py", line 118, in predict
    prediction_output.result = client.predict(prediction_input.data)
  File "/Users/leepand/Downloads/BigRLab_APIs/demoday_fs/web_lab/knn_as_a_service/AIaas/AIaas/router/common_client.py", line 247, in predict
    return self.post(self.__urls["predict"], json=data)
  File "/Users/leepand/Downloads/BigRLab_APIs/demoday_fs/web_lab/knn_as_a_service/AIaas/AIaas/router/common_client.py", line 106, in post
    r = requests.post(url=url, json=json, params=params, timeout=DD_TIMEOUT)
  File "/Users/leepand/anaconda2/lib/python2.7/site-packages/requests/api.py", line 110, in post
    return request('post', url, data=data, json=json, **kwargs)
  File "/Users/leepand/anaconda2/lib/python2.7/site-packages/requests/api.py", line 56, in request
    return session.request(method=method, url=url, **kwargs)
  File "/Users/leepand/anaconda2/lib/python2.7/site-packages/requests/sessions.py", line 475, in request
    resp = self.send(prep, **send_kwargs)
  File "/Users/leepand/anaconda2/lib/python2.7/site-packages/requests/sessions.py", line 596, in send
    r = adapter.send(request, **kwargs)
  File "/Users/leepand/anaconda2/lib/python2.7/site-packages/requests/adapters.py", line 487, in send
    raise ConnectionError(e, request=request)
ConnectionError: HTTPConnectionPool(host='localhost', port=9001): Max retries exceeded with url: /predict (Caused by NewConnectionError('<requests.packages.urllib3.connection.HTTPConnection object at 0x10963bf50>: Failed to establish a new connection: [Errno 61] Connection refused',))
2018-05-18 09:21:44,291 - requests.packages.urllib3.connectionpool - INFO - Starting new HTTP connection (1): localhost
2018-05-18 09:21:44,295 - AIaas.router.AI_worker_client - ERROR - Predict has failed.. 
Traceback (most recent call last):
  File "/Users/leepand/Downloads/BigRLab_APIs/demoday_fs/web_lab/knn_as_a_service/AIaas/AIaas/router/AI_worker_client.py", line 118, in predict
    prediction_output.result = client.predict(prediction_input.data)
  File "/Users/leepand/Downloads/BigRLab_APIs/demoday_fs/web_lab/knn_as_a_service/AIaas/AIaas/router/common_client.py", line 247, in predict
    return self.post(self.__urls["predict"], json=data)
  File "/Users/leepand/Downloads/BigRLab_APIs/demoday_fs/web_lab/knn_as_a_service/AIaas/AIaas/router/common_client.py", line 106, in post
    r = requests.post(url=url, json=json, params=params, timeout=DD_TIMEOUT)
  File "/Users/leepand/anaconda2/lib/python2.7/site-packages/requests/api.py", line 110, in post
    return request('post', url, data=data, json=json, **kwargs)
  File "/Users/leepand/anaconda2/lib/python2.7/site-packages/requests/api.py", line 56, in request
    return session.request(method=method, url=url, **kwargs)
  File "/Users/leepand/anaconda2/lib/python2.7/site-packages/requests/sessions.py", line 475, in request
    resp = self.send(prep, **send_kwargs)
  File "/Users/leepand/anaconda2/lib/python2.7/site-packages/requests/sessions.py", line 596, in send
    r = adapter.send(request, **kwargs)
  File "/Users/leepand/anaconda2/lib/python2.7/site-packages/requests/adapters.py", line 487, in send
    raise ConnectionError(e, request=request)
ConnectionError: HTTPConnectionPool(host='localhost', port=9001): Max retries exceeded with url: /predict (Caused by NewConnectionError('<requests.packages.urllib3.connection.HTTPConnection object at 0x109660c10>: Failed to establish a new connection: [Errno 61] Connection refused',))
2018-05-18 09:21:44,298 - AIaas.router.AI_worker_client - ERROR - Predict has failed.. 
Traceback (most recent call last):
  File "/Users/leepand/Downloads/BigRLab_APIs/demoday_fs/web_lab/knn_as_a_service/AIaas/AIaas/router/AI_worker_client.py", line 118, in predict
    prediction_output.result = client.predict(prediction_input.data)
  File "/Users/leepand/Downloads/BigRLab_APIs/demoday_fs/web_lab/knn_as_a_service/AIaas/AIaas/router/common_client.py", line 247, in predict
    return self.post(self.__urls["predict"], json=data)
  File "/Users/leepand/Downloads/BigRLab_APIs/demoday_fs/web_lab/knn_as_a_service/AIaas/AIaas/router/common_client.py", line 106, in post
    r = requests.post(url=url, json=json, params=params, timeout=DD_TIMEOUT)
  File "/Users/leepand/anaconda2/lib/python2.7/site-packages/requests/api.py", line 110, in post
    return request('post', url, data=data, json=json, **kwargs)
  File "/Users/leepand/anaconda2/lib/python2.7/site-packages/requests/api.py", line 56, in request
    return session.request(method=method, url=url, **kwargs)
  File "/Users/leepand/anaconda2/lib/python2.7/site-packages/requests/sessions.py", line 475, in request
    resp = self.send(prep, **send_kwargs)
  File "/Users/leepand/anaconda2/lib/python2.7/site-packages/requests/sessions.py", line 596, in send
    r = adapter.send(request, **kwargs)
  File "/Users/leepand/anaconda2/lib/python2.7/site-packages/requests/adapters.py", line 487, in send
    raise ConnectionError(e, request=request)
ConnectionError: HTTPConnectionPool(host='localhost', port=9001): Max retries exceeded with url: /predict (Caused by NewConnectionError('<requests.packages.urllib3.connection.HTTPConnection object at 0x109660c10>: Failed to establish a new connection: [Errno 61] Connection refused',))
2018-05-18 09:21:44,303 - requests.packages.urllib3.connectionpool - INFO - Starting new HTTP connection (1): localhost
2018-05-18 09:21:44,308 - AIaas.router.AI_worker_client - ERROR - Predict has failed.. 
Traceback (most recent call last):
  File "/Users/leepand/Downloads/BigRLab_APIs/demoday_fs/web_lab/knn_as_a_service/AIaas/AIaas/router/AI_worker_client.py", line 118, in predict
    prediction_output.result = client.predict(prediction_input.data)
  File "/Users/leepand/Downloads/BigRLab_APIs/demoday_fs/web_lab/knn_as_a_service/AIaas/AIaas/router/common_client.py", line 247, in predict
    return self.post(self.__urls["predict"], json=data)
  File "/Users/leepand/Downloads/BigRLab_APIs/demoday_fs/web_lab/knn_as_a_service/AIaas/AIaas/router/common_client.py", line 106, in post
    r = requests.post(url=url, json=json, params=params, timeout=DD_TIMEOUT)
  File "/Users/leepand/anaconda2/lib/python2.7/site-packages/requests/api.py", line 110, in post
    return request('post', url, data=data, json=json, **kwargs)
  File "/Users/leepand/anaconda2/lib/python2.7/site-packages/requests/api.py", line 56, in request
    return session.request(method=method, url=url, **kwargs)
  File "/Users/leepand/anaconda2/lib/python2.7/site-packages/requests/sessions.py", line 475, in request
    resp = self.send(prep, **send_kwargs)
  File "/Users/leepand/anaconda2/lib/python2.7/site-packages/requests/sessions.py", line 596, in send
    r = adapter.send(request, **kwargs)
  File "/Users/leepand/anaconda2/lib/python2.7/site-packages/requests/adapters.py", line 487, in send
    raise ConnectionError(e, request=request)
ConnectionError: HTTPConnectionPool(host='localhost', port=9001): Max retries exceeded with url: /predict (Caused by NewConnectionError('<requests.packages.urllib3.connection.HTTPConnection object at 0x109660b10>: Failed to establish a new connection: [Errno 61] Connection refused',))
2018-05-18 09:21:44,312 - AIaas.router.AI_worker_client - ERROR - Predict has failed.. 
Traceback (most recent call last):
  File "/Users/leepand/Downloads/BigRLab_APIs/demoday_fs/web_lab/knn_as_a_service/AIaas/AIaas/router/AI_worker_client.py", line 118, in predict
    prediction_output.result = client.predict(prediction_input.data)
  File "/Users/leepand/Downloads/BigRLab_APIs/demoday_fs/web_lab/knn_as_a_service/AIaas/AIaas/router/common_client.py", line 247, in predict
    return self.post(self.__urls["predict"], json=data)
  File "/Users/leepand/Downloads/BigRLab_APIs/demoday_fs/web_lab/knn_as_a_service/AIaas/AIaas/router/common_client.py", line 106, in post
    r = requests.post(url=url, json=json, params=params, timeout=DD_TIMEOUT)
  File "/Users/leepand/anaconda2/lib/python2.7/site-packages/requests/api.py", line 110, in post
    return request('post', url, data=data, json=json, **kwargs)
  File "/Users/leepand/anaconda2/lib/python2.7/site-packages/requests/api.py", line 56, in request
    return session.request(method=method, url=url, **kwargs)
  File "/Users/leepand/anaconda2/lib/python2.7/site-packages/requests/sessions.py", line 475, in request
    resp = self.send(prep, **send_kwargs)
  File "/Users/leepand/anaconda2/lib/python2.7/site-packages/requests/sessions.py", line 596, in send
    r = adapter.send(request, **kwargs)
  File "/Users/leepand/anaconda2/lib/python2.7/site-packages/requests/adapters.py", line 487, in send
    raise ConnectionError(e, request=request)
ConnectionError: HTTPConnectionPool(host='localhost', port=9001): Max retries exceeded with url: /predict (Caused by NewConnectionError('<requests.packages.urllib3.connection.HTTPConnection object at 0x109660b10>: Failed to establish a new connection: [Errno 61] Connection refused',))
2018-05-18 09:22:27,013 - AIaas.router.AI_worker_client - INFO - Caffe predict has been called..
2018-05-18 09:22:27,017 - requests.packages.urllib3.connectionpool - INFO - Starting new HTTP connection (1): localhost
2018-05-18 09:22:27,023 - AIaas.router.AI_worker_client - ERROR - Predict has failed.. 
Traceback (most recent call last):
  File "/Users/leepand/anaconda2/lib/python2.7/site-packages/gunicorn/workers/sync.py", line 68, in run_for_one
    self.accept(listener)
  File "/Users/leepand/anaconda2/lib/python2.7/site-packages/gunicorn/workers/sync.py", line 27, in accept
    client, addr = listener.accept()
  File "/Users/leepand/anaconda2/lib/python2.7/socket.py", line 206, in accept
    sock, addr = self._sock.accept()
error: [Errno 35] Resource temporarily unavailable
2018-05-18 09:22:29,768 - AIaas.router.AI_worker_client - INFO - Caffe predict has been called..
2018-05-18 09:22:29,772 - requests.packages.urllib3.connectionpool - INFO - Starting new HTTP connection (1): localhost
2018-05-18 09:22:29,781 - AIaas.router.AI_worker_client - ERROR - Predict has failed.. 
Traceback (most recent call last):
  File "/Users/leepand/anaconda2/lib/python2.7/site-packages/gunicorn/workers/sync.py", line 68, in run_for_one
    self.accept(listener)
  File "/Users/leepand/anaconda2/lib/python2.7/site-packages/gunicorn/workers/sync.py", line 27, in accept
    client, addr = listener.accept()
  File "/Users/leepand/anaconda2/lib/python2.7/socket.py", line 206, in accept
    sock, addr = self._sock.accept()
error: [Errno 35] Resource temporarily unavailable
2018-05-18 09:22:30,885 - AIaas.router.AI_worker_client - INFO - Caffe predict has been called..
2018-05-18 09:22:30,888 - requests.packages.urllib3.connectionpool - INFO - Starting new HTTP connection (1): localhost
2018-05-18 09:22:30,895 - AIaas.router.AI_worker_client - ERROR - Predict has failed.. 
Traceback (most recent call last):
  File "/Users/leepand/anaconda2/lib/python2.7/site-packages/gunicorn/workers/sync.py", line 68, in run_for_one
    self.accept(listener)
  File "/Users/leepand/anaconda2/lib/python2.7/site-packages/gunicorn/workers/sync.py", line 27, in accept
    client, addr = listener.accept()
  File "/Users/leepand/anaconda2/lib/python2.7/socket.py", line 206, in accept
    sock, addr = self._sock.accept()
error: [Errno 35] Resource temporarily unavailable
2018-05-18 09:22:32,174 - AIaas.router.AI_worker_client - INFO - Caffe predict has been called..
2018-05-18 09:22:32,177 - requests.packages.urllib3.connectionpool - INFO - Starting new HTTP connection (1): localhost
2018-05-18 09:22:32,183 - AIaas.router.AI_worker_client - ERROR - Predict has failed.. 
Traceback (most recent call last):
  File "/Users/leepand/anaconda2/lib/python2.7/site-packages/gunicorn/workers/sync.py", line 68, in run_for_one
    self.accept(listener)
  File "/Users/leepand/anaconda2/lib/python2.7/site-packages/gunicorn/workers/sync.py", line 27, in accept
    client, addr = listener.accept()
  File "/Users/leepand/anaconda2/lib/python2.7/socket.py", line 206, in accept
    sock, addr = self._sock.accept()
error: [Errno 35] Resource temporarily unavailable
2018-05-18 09:22:33,637 - AIaas.router.AI_worker_client - INFO - Caffe predict has been called..
2018-05-18 09:22:33,640 - requests.packages.urllib3.connectionpool - INFO - Starting new HTTP connection (1): localhost
2018-05-18 09:22:33,646 - AIaas.router.AI_worker_client - ERROR - Predict has failed.. 
Traceback (most recent call last):
  File "/Users/leepand/anaconda2/lib/python2.7/site-packages/gunicorn/workers/sync.py", line 68, in run_for_one
    self.accept(listener)
  File "/Users/leepand/anaconda2/lib/python2.7/site-packages/gunicorn/workers/sync.py", line 27, in accept
    client, addr = listener.accept()
  File "/Users/leepand/anaconda2/lib/python2.7/socket.py", line 206, in accept
    sock, addr = self._sock.accept()
error: [Errno 35] Resource temporarily unavailable
2018-05-18 09:22:34,744 - AIaas.router.AI_worker_client - INFO - Caffe predict has been called..
2018-05-18 09:22:34,747 - requests.packages.urllib3.connectionpool - INFO - Starting new HTTP connection (1): localhost
2018-05-18 09:22:34,753 - AIaas.router.AI_worker_client - ERROR - Predict has failed.. 
Traceback (most recent call last):
  File "/Users/leepand/anaconda2/lib/python2.7/site-packages/gunicorn/workers/sync.py", line 68, in run_for_one
    self.accept(listener)
  File "/Users/leepand/anaconda2/lib/python2.7/site-packages/gunicorn/workers/sync.py", line 27, in accept
    client, addr = listener.accept()
  File "/Users/leepand/anaconda2/lib/python2.7/socket.py", line 206, in accept
    sock, addr = self._sock.accept()
error: [Errno 35] Resource temporarily unavailable
2018-05-18 09:22:35,821 - AIaas.router.AI_worker_client - INFO - Caffe predict has been called..
2018-05-18 09:22:35,825 - requests.packages.urllib3.connectionpool - INFO - Starting new HTTP connection (1): localhost
2018-05-18 09:22:35,829 - AIaas.router.AI_worker_client - ERROR - Predict has failed.. 
Traceback (most recent call last):
  File "/Users/leepand/Downloads/BigRLab_APIs/demoday_fs/web_lab/knn_as_a_service/AIaas/AIaas/router/AI_worker_client.py", line 118, in predict
    prediction_output.result = client.predict(prediction_input.data)
  File "/Users/leepand/Downloads/BigRLab_APIs/demoday_fs/web_lab/knn_as_a_service/AIaas/AIaas/router/common_client.py", line 247, in predict
    return self.post(self.__urls["predict"], json=data)
  File "/Users/leepand/Downloads/BigRLab_APIs/demoday_fs/web_lab/knn_as_a_service/AIaas/AIaas/router/common_client.py", line 106, in post
    r = requests.post(url=url, json=json, params=params, timeout=DD_TIMEOUT)
  File "/Users/leepand/anaconda2/lib/python2.7/site-packages/requests/api.py", line 110, in post
    return request('post', url, data=data, json=json, **kwargs)
  File "/Users/leepand/anaconda2/lib/python2.7/site-packages/requests/api.py", line 56, in request
    return session.request(method=method, url=url, **kwargs)
  File "/Users/leepand/anaconda2/lib/python2.7/site-packages/requests/sessions.py", line 475, in request
    resp = self.send(prep, **send_kwargs)
  File "/Users/leepand/anaconda2/lib/python2.7/site-packages/requests/sessions.py", line 596, in send
    r = adapter.send(request, **kwargs)
  File "/Users/leepand/anaconda2/lib/python2.7/site-packages/requests/adapters.py", line 487, in send
    raise ConnectionError(e, request=request)
ConnectionError: HTTPConnectionPool(host='localhost', port=9001): Max retries exceeded with url: /predict (Caused by NewConnectionError('<requests.packages.urllib3.connection.HTTPConnection object at 0x109660950>: Failed to establish a new connection: [Errno 61] Connection refused',))
2018-05-18 09:22:35,831 - AIaas.router.AI_worker_client - ERROR - Predict has failed.. 
Traceback (most recent call last):
  File "/Users/leepand/Downloads/BigRLab_APIs/demoday_fs/web_lab/knn_as_a_service/AIaas/AIaas/router/AI_worker_client.py", line 118, in predict
    prediction_output.result = client.predict(prediction_input.data)
  File "/Users/leepand/Downloads/BigRLab_APIs/demoday_fs/web_lab/knn_as_a_service/AIaas/AIaas/router/common_client.py", line 247, in predict
    return self.post(self.__urls["predict"], json=data)
  File "/Users/leepand/Downloads/BigRLab_APIs/demoday_fs/web_lab/knn_as_a_service/AIaas/AIaas/router/common_client.py", line 106, in post
    r = requests.post(url=url, json=json, params=params, timeout=DD_TIMEOUT)
  File "/Users/leepand/anaconda2/lib/python2.7/site-packages/requests/api.py", line 110, in post
    return request('post', url, data=data, json=json, **kwargs)
  File "/Users/leepand/anaconda2/lib/python2.7/site-packages/requests/api.py", line 56, in request
    return session.request(method=method, url=url, **kwargs)
  File "/Users/leepand/anaconda2/lib/python2.7/site-packages/requests/sessions.py", line 475, in request
    resp = self.send(prep, **send_kwargs)
  File "/Users/leepand/anaconda2/lib/python2.7/site-packages/requests/sessions.py", line 596, in send
    r = adapter.send(request, **kwargs)
  File "/Users/leepand/anaconda2/lib/python2.7/site-packages/requests/adapters.py", line 487, in send
    raise ConnectionError(e, request=request)
ConnectionError: HTTPConnectionPool(host='localhost', port=9001): Max retries exceeded with url: /predict (Caused by NewConnectionError('<requests.packages.urllib3.connection.HTTPConnection object at 0x109660950>: Failed to establish a new connection: [Errno 61] Connection refused',))
2018-05-18 09:22:35,835 - requests.packages.urllib3.connectionpool - INFO - Starting new HTTP connection (1): localhost
2018-05-18 09:22:35,839 - AIaas.router.AI_worker_client - ERROR - Predict has failed.. 
Traceback (most recent call last):
  File "/Users/leepand/Downloads/BigRLab_APIs/demoday_fs/web_lab/knn_as_a_service/AIaas/AIaas/router/AI_worker_client.py", line 118, in predict
    prediction_output.result = client.predict(prediction_input.data)
  File "/Users/leepand/Downloads/BigRLab_APIs/demoday_fs/web_lab/knn_as_a_service/AIaas/AIaas/router/common_client.py", line 247, in predict
    return self.post(self.__urls["predict"], json=data)
  File "/Users/leepand/Downloads/BigRLab_APIs/demoday_fs/web_lab/knn_as_a_service/AIaas/AIaas/router/common_client.py", line 106, in post
    r = requests.post(url=url, json=json, params=params, timeout=DD_TIMEOUT)
  File "/Users/leepand/anaconda2/lib/python2.7/site-packages/requests/api.py", line 110, in post
    return request('post', url, data=data, json=json, **kwargs)
  File "/Users/leepand/anaconda2/lib/python2.7/site-packages/requests/api.py", line 56, in request
    return session.request(method=method, url=url, **kwargs)
  File "/Users/leepand/anaconda2/lib/python2.7/site-packages/requests/sessions.py", line 475, in request
    resp = self.send(prep, **send_kwargs)
  File "/Users/leepand/anaconda2/lib/python2.7/site-packages/requests/sessions.py", line 596, in send
    r = adapter.send(request, **kwargs)
  File "/Users/leepand/anaconda2/lib/python2.7/site-packages/requests/adapters.py", line 487, in send
    raise ConnectionError(e, request=request)
ConnectionError: HTTPConnectionPool(host='localhost', port=9001): Max retries exceeded with url: /predict (Caused by NewConnectionError('<requests.packages.urllib3.connection.HTTPConnection object at 0x109660c50>: Failed to establish a new connection: [Errno 61] Connection refused',))
2018-05-18 09:22:35,842 - AIaas.router.AI_worker_client - ERROR - Predict has failed.. 
Traceback (most recent call last):
  File "/Users/leepand/Downloads/BigRLab_APIs/demoday_fs/web_lab/knn_as_a_service/AIaas/AIaas/router/AI_worker_client.py", line 118, in predict
    prediction_output.result = client.predict(prediction_input.data)
  File "/Users/leepand/Downloads/BigRLab_APIs/demoday_fs/web_lab/knn_as_a_service/AIaas/AIaas/router/common_client.py", line 247, in predict
    return self.post(self.__urls["predict"], json=data)
  File "/Users/leepand/Downloads/BigRLab_APIs/demoday_fs/web_lab/knn_as_a_service/AIaas/AIaas/router/common_client.py", line 106, in post
    r = requests.post(url=url, json=json, params=params, timeout=DD_TIMEOUT)
  File "/Users/leepand/anaconda2/lib/python2.7/site-packages/requests/api.py", line 110, in post
    return request('post', url, data=data, json=json, **kwargs)
  File "/Users/leepand/anaconda2/lib/python2.7/site-packages/requests/api.py", line 56, in request
    return session.request(method=method, url=url, **kwargs)
  File "/Users/leepand/anaconda2/lib/python2.7/site-packages/requests/sessions.py", line 475, in request
    resp = self.send(prep, **send_kwargs)
  File "/Users/leepand/anaconda2/lib/python2.7/site-packages/requests/sessions.py", line 596, in send
    r = adapter.send(request, **kwargs)
  File "/Users/leepand/anaconda2/lib/python2.7/site-packages/requests/adapters.py", line 487, in send
    raise ConnectionError(e, request=request)
ConnectionError: HTTPConnectionPool(host='localhost', port=9001): Max retries exceeded with url: /predict (Caused by NewConnectionError('<requests.packages.urllib3.connection.HTTPConnection object at 0x109660c50>: Failed to establish a new connection: [Errno 61] Connection refused',))
2018-05-18 09:22:35,848 - requests.packages.urllib3.connectionpool - INFO - Starting new HTTP connection (1): localhost
2018-05-18 09:22:35,851 - AIaas.router.AI_worker_client - ERROR - Predict has failed.. 
Traceback (most recent call last):
  File "/Users/leepand/Downloads/BigRLab_APIs/demoday_fs/web_lab/knn_as_a_service/AIaas/AIaas/router/AI_worker_client.py", line 118, in predict
    prediction_output.result = client.predict(prediction_input.data)
  File "/Users/leepand/Downloads/BigRLab_APIs/demoday_fs/web_lab/knn_as_a_service/AIaas/AIaas/router/common_client.py", line 247, in predict
    return self.post(self.__urls["predict"], json=data)
  File "/Users/leepand/Downloads/BigRLab_APIs/demoday_fs/web_lab/knn_as_a_service/AIaas/AIaas/router/common_client.py", line 106, in post
    r = requests.post(url=url, json=json, params=params, timeout=DD_TIMEOUT)
  File "/Users/leepand/anaconda2/lib/python2.7/site-packages/requests/api.py", line 110, in post
    return request('post', url, data=data, json=json, **kwargs)
  File "/Users/leepand/anaconda2/lib/python2.7/site-packages/requests/api.py", line 56, in request
    return session.request(method=method, url=url, **kwargs)
  File "/Users/leepand/anaconda2/lib/python2.7/site-packages/requests/sessions.py", line 475, in request
    resp = self.send(prep, **send_kwargs)
  File "/Users/leepand/anaconda2/lib/python2.7/site-packages/requests/sessions.py", line 596, in send
    r = adapter.send(request, **kwargs)
  File "/Users/leepand/anaconda2/lib/python2.7/site-packages/requests/adapters.py", line 487, in send
    raise ConnectionError(e, request=request)
ConnectionError: HTTPConnectionPool(host='localhost', port=9001): Max retries exceeded with url: /predict (Caused by NewConnectionError('<requests.packages.urllib3.connection.HTTPConnection object at 0x109660b50>: Failed to establish a new connection: [Errno 61] Connection refused',))
2018-05-18 09:22:35,854 - AIaas.router.AI_worker_client - ERROR - Predict has failed.. 
Traceback (most recent call last):
  File "/Users/leepand/Downloads/BigRLab_APIs/demoday_fs/web_lab/knn_as_a_service/AIaas/AIaas/router/AI_worker_client.py", line 118, in predict
    prediction_output.result = client.predict(prediction_input.data)
  File "/Users/leepand/Downloads/BigRLab_APIs/demoday_fs/web_lab/knn_as_a_service/AIaas/AIaas/router/common_client.py", line 247, in predict
    return self.post(self.__urls["predict"], json=data)
  File "/Users/leepand/Downloads/BigRLab_APIs/demoday_fs/web_lab/knn_as_a_service/AIaas/AIaas/router/common_client.py", line 106, in post
    r = requests.post(url=url, json=json, params=params, timeout=DD_TIMEOUT)
  File "/Users/leepand/anaconda2/lib/python2.7/site-packages/requests/api.py", line 110, in post
    return request('post', url, data=data, json=json, **kwargs)
  File "/Users/leepand/anaconda2/lib/python2.7/site-packages/requests/api.py", line 56, in request
    return session.request(method=method, url=url, **kwargs)
  File "/Users/leepand/anaconda2/lib/python2.7/site-packages/requests/sessions.py", line 475, in request
    resp = self.send(prep, **send_kwargs)
  File "/Users/leepand/anaconda2/lib/python2.7/site-packages/requests/sessions.py", line 596, in send
    r = adapter.send(request, **kwargs)
  File "/Users/leepand/anaconda2/lib/python2.7/site-packages/requests/adapters.py", line 487, in send
    raise ConnectionError(e, request=request)
ConnectionError: HTTPConnectionPool(host='localhost', port=9001): Max retries exceeded with url: /predict (Caused by NewConnectionError('<requests.packages.urllib3.connection.HTTPConnection object at 0x109660b50>: Failed to establish a new connection: [Errno 61] Connection refused',))
2018-05-18 10:14:17,595 - router.router_app - INFO - Starting Router...
2018-05-18 10:14:17,604 - AIaas.router.AI_worker_client - INFO - load balancer inited...
2018-05-18 10:14:17,605 - AIaas.router.AI_worker_client - INFO - AIWorkerClient Inited...
2018-05-18 10:14:17,606 - AIaas.router.predict - INFO - Predict Inited...
2018-05-18 10:14:46,092 - AIaas.router.AI_worker_client - INFO - AI predict has been called..
2018-05-18 10:14:48,636 - AIaas.router.AI_worker_client - INFO - AI predict has been called..
2018-05-18 10:14:50,104 - AIaas.router.AI_worker_client - INFO - AI predict has been called..
2018-05-18 10:14:51,483 - AIaas.router.AI_worker_client - INFO - AI predict has been called..
2018-05-18 10:15:05,118 - AIaas.router.AI_worker_client - INFO - AI predict has been called..
2018-05-18 10:15:09,007 - AIaas.router.AI_worker_client - INFO - AI predict has been called..
2018-05-18 10:21:45,411 - router.router_app - INFO - Starting Router...
2018-05-18 10:21:45,420 - AIaas.router.AI_worker_client - INFO - load balancer inited...
2018-05-18 10:21:45,421 - AIaas.router.AI_worker_client - INFO - AIWorkerClient Inited...
2018-05-18 10:21:45,421 - AIaas.router.predict - INFO - Predict Inited...
2018-05-18 10:22:01,236 - AIaas.router.AI_worker_client - INFO - AI predict has been called..
2018-05-18 10:22:03,121 - AIaas.router.AI_worker_client - INFO - AI predict has been called..
2018-05-18 10:34:37,922 - router.router_app - INFO - Starting Router...
2018-05-18 10:34:37,931 - AIaas.router.AI_worker_client - INFO - load balancer inited...
2018-05-18 10:34:37,931 - AIaas.router.AI_worker_client - INFO - AIWorkerClient Inited...
2018-05-18 10:34:37,932 - AIaas.router.predict - INFO - Predict Inited...
2018-05-18 10:34:53,124 - AIaas.router.AI_worker_client - INFO - AI predict has been called..
2018-05-18 10:34:53,140 - requests.packages.urllib3.connectionpool - INFO - Starting new HTTP connection (1): localhost
2018-05-18 10:34:53,161 - AIaas.router.AI_worker_client - ERROR - Predict has failed.. 
Traceback (most recent call last):
  File "/Users/leepand/anaconda2/lib/python2.7/site-packages/gunicorn/workers/sync.py", line 68, in run_for_one
    self.accept(listener)
  File "/Users/leepand/anaconda2/lib/python2.7/site-packages/gunicorn/workers/sync.py", line 27, in accept
    client, addr = listener.accept()
  File "/Users/leepand/anaconda2/lib/python2.7/socket.py", line 206, in accept
    sock, addr = self._sock.accept()
error: [Errno 35] Resource temporarily unavailable
2018-05-18 10:35:49,735 - router.router_app - INFO - Starting Router...
2018-05-18 10:35:49,744 - AIaas.router.AI_worker_client - INFO - load balancer inited...
2018-05-18 10:35:49,744 - AIaas.router.AI_worker_client - INFO - AIWorkerClient Inited...
2018-05-18 10:35:49,745 - AIaas.router.predict - INFO - Predict Inited...
2018-05-18 10:36:05,803 - AIaas.router.AI_worker_client - INFO - AI predict has been called..
2018-05-18 10:36:05,817 - requests.packages.urllib3.connectionpool - INFO - Starting new HTTP connection (1): localhost
2018-05-18 10:36:05,839 - AIaas.router.AI_worker_client - ERROR - Predict has failed.. 
Traceback (most recent call last):
  File "/Users/leepand/anaconda2/lib/python2.7/site-packages/gunicorn/workers/sync.py", line 68, in run_for_one
    self.accept(listener)
  File "/Users/leepand/anaconda2/lib/python2.7/site-packages/gunicorn/workers/sync.py", line 27, in accept
    client, addr = listener.accept()
  File "/Users/leepand/anaconda2/lib/python2.7/socket.py", line 206, in accept
    sock, addr = self._sock.accept()
error: [Errno 35] Resource temporarily unavailable
2018-05-18 10:36:26,047 - AIaas.router.AI_worker_client - INFO - AI predict has been called..
2018-05-18 10:36:26,051 - requests.packages.urllib3.connectionpool - INFO - Starting new HTTP connection (1): localhost
2018-05-18 10:36:26,056 - AIaas.router.AI_worker_client - ERROR - Predict has failed.. 
Traceback (most recent call last):
  File "/Users/leepand/anaconda2/lib/python2.7/site-packages/gunicorn/workers/sync.py", line 68, in run_for_one
    self.accept(listener)
  File "/Users/leepand/anaconda2/lib/python2.7/site-packages/gunicorn/workers/sync.py", line 27, in accept
    client, addr = listener.accept()
  File "/Users/leepand/anaconda2/lib/python2.7/socket.py", line 206, in accept
    sock, addr = self._sock.accept()
error: [Errno 35] Resource temporarily unavailable
2018-05-18 10:36:38,195 - AIaas.router.AI_worker_client - INFO - AI predict has been called..
2018-05-18 10:36:38,199 - requests.packages.urllib3.connectionpool - INFO - Starting new HTTP connection (1): localhost
2018-05-18 10:36:38,205 - AIaas.router.AI_worker_client - ERROR - Predict has failed.. 
Traceback (most recent call last):
  File "/Users/leepand/anaconda2/lib/python2.7/site-packages/gunicorn/workers/sync.py", line 68, in run_for_one
    self.accept(listener)
  File "/Users/leepand/anaconda2/lib/python2.7/site-packages/gunicorn/workers/sync.py", line 27, in accept
    client, addr = listener.accept()
  File "/Users/leepand/anaconda2/lib/python2.7/socket.py", line 206, in accept
    sock, addr = self._sock.accept()
error: [Errno 35] Resource temporarily unavailable
2018-05-18 10:56:01,566 - router.router_app - INFO - Starting Router...
2018-05-18 10:56:01,576 - AIaas.router.AI_worker_client - INFO - load balancer inited...
2018-05-18 10:56:01,577 - AIaas.router.AI_worker_client - INFO - AIWorkerClient Inited...
2018-05-18 10:56:01,577 - AIaas.router.predict - INFO - Predict Inited...
